Workbook

Sheet 1-Ogrenci
A1: SOMA MESLEKI VE TEKNIK ANADOLU LISESI - MAKINE TEKNOLOJISI ALANI
A2: 12. SINIF STAJ OGRENCI LISTESI - 2024/2025 OGRETIM YILI
A4: MAKINE BAKIM ONARIM (MBO) - A Subesi | G4: BILGISAYARLI MAKINE IMALATI (BMI) - B Subesi
A5: No | B5: Ogr.No | C5: Adi Soyadi | D5: Not Ortalamasi | E5: Oncelik Sirasi | G5: No | H5: Ogr.No | I5: Adi Soyadi | J5: Not Ortalamasi | K5: Oncelik Sirasi
A6: 1 | B6: 1008 | C6: ZAFER SARI | D6: 74.82 | E6: =IFERROR(RANK(D6,D$6:D$37,0),"") -> 7 | G6: 1 | H6: 22102 | I6: RAMAZAN DOGANER | J6: 60.79 | K6: =IFERROR(RANK(J6,J$6:J$37,0),"") -> 14
A7: 2 | B7: 23014 | C7: RAMAZAN OVEK | D7: 78.88 | E7: =IFERROR(RANK(D7,D$6:D$37,0),"") -> 1 | G7: 2 | K7: =IFERROR(RANK(J7,J$6:J$37,0),"")
A8: 3 | B8: 23015 | C8: ISMAIL SIVRI | D8: 77.56 | E8: =IFERROR(RANK(D8,D$6:D$37,0),"") -> 3 | G8: 3 | H8: 22117 | I8: HUSEYIN ANIL KOC | J8: 62.67 | K8: =IFERROR(RANK(J8,J$6:J$37,0),"") -> 13
A9: 4 | B9: 23034 | C9: ALI YILMAZ | D9: 70.33 | E9: =IFERROR(RANK(D9,D$6:D$37,0),"") -> 13 | G9: 4 | H9: 23007 | I9: TALHA OMER YAGMUR | J9: 66.24 | K9: =IFERROR(RANK(J9,J$6:J$37,0),"") -> 10
A10: 5 | B10: 23046 | C10: TUNAHAN TEKER | D10: 71.6 | E10: =IFERROR(RANK(D10,D$6:D$37,0),"") -> 10 | G10: 5 | H10: 23010 | I10: EMIRHAN YASLAM | J10: 79.08 | K10: =IFERROR(RANK(J10,J$6:J$37,0),"") -> 2
A11: 6 | B11: 23050 | C11: YASAR ARDA CAL | D11: 78.75 | E11: =IFERROR(RANK(D11,D$6:D$37,0),"") -> 2 | G11: 6 | H11: 23021 | I11: YIGIT AFACAN | J11: 73.2 | K11: =IFERROR(RANK(J11,J$6:J$37,0),"") -> 5
A12: 7 | B12: 23060 | C12: MEHMET KAZIM UZUN | D12: 69.15 | E12: =IFERROR(RANK(D12,D$6:D$37,0),"") -> 14 | G12: 7 | H12: 23026 | I12: YAGIZ SENHAN | J12: 71.22 | K12: =IFERROR(RANK(J12,J$6:J$37,0),"") -> 7
A13: 8 | B13: 23068 | C13: SADETTIN AKSU | D13: 70.57 | E13: =IFERROR(RANK(D13,D$6:D$37,0),"") -> 12 | G13: 8 | H13: 23053 | I13: MERT BERAT VARLI | J13: 69.26 | K13: =IFERROR(RANK(J13,J$6:J$37,0),"") -> 8
A14: 9 | B14: 23077 | C14: CENGIZHAN GEZGIN | D14: 72.01 | E14: =IFERROR(RANK(D14,D$6:D$37,0),"") -> 8 | G14: 9 | H14: 23054 | I14: SAMET YALIN | J14: 73.36 | K14: =IFERROR(RANK(J14,J$6:J$37,0),"") -> 4
A15: 10 | B15: 23081 | C15: BATIKAN ALEMDAR TASPINAR | D15: 66.67 | E15: =IFERROR(RANK(D15,D$6:D$37,0),"") -> 18 | G15: 10 | H15: 23058 | I15: MEHMET CAN CELEBI | J15: 73.08 | K15: =IFERROR(RANK(J15,J$6:J$37,0),"") -> 6
A16: 11 | B16: 23087 | C16: YUSUF EFE CAL | D16: 77 | E16: =IFERROR(RANK(D16,D$6:D$37,0),"") -> 4 | G16: 11 | H16: 23085 | I16: MUHAMMET TOPRAK | J16: 68.41 | K16: =IFERROR(RANK(J16,J$6:J$37,0),"") -> 9
A17: 12 | B17: 23100 | C17: MERT KOCABIYIK | D17: 75.15 | E17: =IFERROR(RANK(D17,D$6:D$37,0),"") -> 5 | G17: 12 | H17: 23093 | I17: FAHRI CAN ILGAZ | J17: 62.81 | K17: =IFERROR(RANK(J17,J$6:J$37,0),"") -> 12
A18: 13 | B18: 23102 | C18: HUSEYIN YEKTA SENLIK | D18: 68.54 | E18: =IFERROR(RANK(D18,D$6:D$37,0),"") -> 16 | G18: 13 | H18: 23105 | I18: EFE ESREF OZDILKURAL | J18: 79.98 | K18: =IFERROR(RANK(J18,J$6:J$37,0),"") -> 1
A19: 14 | B19: 23104 | C19: ALI HAN CELIK | D19: 71.48 | E19: =IFERROR(RANK(D19,D$6:D$37,0),"") -> 11 | G19: 14 | H19: 23109 | I19: EREN OLUM | J19: 65.89 | K19: =IFERROR(RANK(J19,J$6:J$37,0),"") -> 11
A20: 15 | B20: 23107 | C20: HASAN MERT ANAC | D20: 71.79 | E20: =IFERROR(RANK(D20,D$6:D$37,0),"") -> 9 | G20: 15 | H20: 23249 | I20: EGE GENC | J20: 77.01 | K20: =IFERROR(RANK(J20,J$6:J$37,0),"") -> 3
A21: 16 | B21: 23110 | C21: SULEYMAN COBAN | D21: 63.71 | E21: =IFERROR(RANK(D21,D$6:D$37,0),"") -> 20 | G21: 16 | K21: =IFERROR(RANK(J21,J$6:J$37,0),"")
A22: 17 | B22: 23112 | C22: EMIRHAN ERTURK | D22: 63.45 | E22: =IFERROR(RANK(D22,D$6:D$37,0),"") -> 21 | G22: 17 | K22: =IFERROR(RANK(J22,J$6:J$37,0),"")
A23: 18 | B23: 23113 | C23: MUHAMMET EMIN KILIC | D23: 68.9 | E23: =IFERROR(RANK(D23,D$6:D$37,0),"") -> 15 | G23: 18 | K23: =IFERROR(RANK(J23,J$6:J$37,0),"")
A24: 19 | B24: 23117 | C24: SALIH AGCIK | D24: 64.53 | E24: =IFERROR(RANK(D24,D$6:D$37,0),"") -> 19 | G24: 19 | K24: =IFERROR(RANK(J24,J$6:J$37,0),"")
A25: 20 | B25: 23238 | C25: ARDA YILMAZ | D25: 67.9 | E25: =IFERROR(RANK(D25,D$6:D$37,0),"") -> 17 | G25: 20 | K25: =IFERROR(RANK(J25,J$6:J$37,0),"")
A26: 21 | B26: 23245 | C26: AHMET CEMIL YILDIZ | D26: 75.05 | E26: =IFERROR(RANK(D26,D$6:D$37,0),"") -> 6 | G26: 21 | K26: =IFERROR(RANK(J26,J$6:J$37,0),"")
A27: 22 | E27: =IFERROR(RANK(D27,D$6:D$37,0),"") | G27: 22 | K27: =IFERROR(RANK(J27,J$6:J$37,0),"")
A28: 23 | E28: =IFERROR(RANK(D28,D$6:D$37,0),"") | G28: 23 | K28: =IFERROR(RANK(J28,J$6:J$37,0),"")
A29: 24 | E29: =IFERROR(RANK(D29,D$6:D$37,0),"") | G29: 24 | K29: =IFERROR(RANK(J29,J$6:J$37,0),"")
A30: 25 | E30: =IFERROR(RANK(D30,D$6:D$37,0),"") | G30: 25 | K30: =IFERROR(RANK(J30,J$6:J$37,0),"")
A31: 26 | E31: =IFERROR(RANK(D31,D$6:D$37,0),"") | G31: 26 | K31: =IFERROR(RANK(J31,J$6:J$37,0),"")
A32: 27 | E32: =IFERROR(RANK(D32,D$6:D$37,0),"") | G32: 27 | K32: =IFERROR(RANK(J32,J$6:J$37,0),"")
A33: 28 | E33: =IFERROR(RANK(D33,D$6:D$37,0),"") | G33: 28 | K33: =IFERROR(RANK(J33,J$6:J$37,0),"")
A34: 29 | E34: =IFERROR(RANK(D34,D$6:D$37,0),"") | G34: 29 | K34: =IFERROR(RANK(J34,J$6:J$37,0),"")
A35: 30 | E35: =IFERROR(RANK(D35,D$6:D$37,0),"") | G35: 30 | K35: =IFERROR(RANK(J35,J$6:J$37,0),"")
A36: 31 | E36: =IFERROR(RANK(D36,D$6:D$37,0),"") | G36: 31 | K36: =IFERROR(RANK(J36,J$6:J$37,0),"")
A37: 32 | E37: =IFERROR(RANK(D37,D$6:D$37,0),"") | G37: 32 | K37: =IFERROR(RANK(J37,J$6:J$37,0),"")
A38: MBO - Sinif Not Ortalamasi | D38: =IFERROR(AVERAGEIF(D6:D37,">0"),"Veri Girilmedi") -> 71.325714 | G38: BMI - Sinif Not Ortalamasi | J38: =IFERROR(AVERAGEIF(J6:J37,">0"),"Veri Girilmedi") -> 70.214286
A40: NOT: Gri hücreler bos birakilmistir. Yeni ogrenci eklendiginde: Ogr.No ve Adi Soyadi yazin, Not Ortalamasini girin. Sistem otomatik guncellenir.

Sheet 2-Tercih
A1: SOMA MESLEKI VE TEKNIK ANADOLU LISESI - STAJ YERI TERCIH FORMU
A2: 12. Sinif | 2024/2025 | Her ogrenci 10 tercih yapabilir | Gitmek istemediginiz isletmeleri son sutuna yaziniz.
A4: MAKINE BAKIM ONARIM (MBO) - A Subesi
A5: No | B5: Ogr.No | C5: Adi Soyadi | D5: Not Ort. | E5: 1. Tercih | F5: 2. Tercih | G5: 3. Tercih | H5: 4. Tercih | I5: 5. Tercih | J5: 6. Tercih | K5: 7. Tercih | L5: 8. Tercih | M5: 9. Tercih | N5: 10. Tercih | O5: GITMEK ISTEMEDIGIM ISLETMELER (virgülle)
A6: 1 | B6: 1008 | C6: ZAFER SARI | D6: ='1-Ogrenci'!D6 -> 74.82 | E6: TKI EGE LINYITLERI ISLETMESI MUDURLUGU | F6: ARIKSAN METAL | G6: HIDRO-GEN ENERJI | H6: ZIRVE MAKINA | I6: ZINBA MAKINA SANAYI | J6: DEFAS MADENCILIK SAN. VE TIC. A.S. (DEMIR EXPORT)
A7: 2 | B7: 23014 | C7: RAMAZAN OVEK | D7: ='1-Ogrenci'!D7 -> 78.88 | E7: TKI EGE LINYITLERI ISLETMESI MUDURLUGU | F7: IMBAT MADENCILIK | G7: DEFAS MADENCILIK SAN. VE TIC. A.S. (DEMIR EXPORT) | H7: HIDRO-GEN ENERJI | I7: ZIRVE MAKINA
A8: 3 | B8: 23015 | C8: ISMAIL SIVRI | D8: ='1-Ogrenci'!D8 -> 77.56 | E8: UYSAL TORNA (MUHAMMET UYSAL) | F8: TKI EGE LINYITLERI ISLETMESI MUDURLUGU | G8: DEFAS MADENCILIK SAN. VE TIC. A.S. (DEMIR EXPORT) | H8: IMBAT MADENCILIK
A9: 4 | B9: 23034 | C9: ALI YILMAZ | D9: ='1-Ogrenci'!D9 -> 70.33 | E9: TKI EGE LINYITLERI ISLETMESI MUDURLUGU | F9: HIDRO-GEN ENERJI | G9: IMBAT MADENCILIK | H9: DEFAS MADENCILIK SAN. VE TIC. A.S. (DEMIR EXPORT) | I9: ARIKSAN METAL | J9: E SINERJI MUHENDISLIK
A10: 5 | B10: 23046 | C10: TUNAHAN TEKER | D10: ='1-Ogrenci'!D10 -> 71.6 | E10: HIDRO-GEN ENERJI | F10: TKI EGE LINYITLERI ISLETMESI MUDURLUGU | G10: DEFAS MADENCILIK SAN. VE TIC. A.S. (DEMIR EXPORT) | H10: IMBAT MADENCILIK | I10: MODERANS METAL YAPI
A11: 6 | B11: 23050 | C11: YASAR ARDA CAL | D11: ='1-Ogrenci'!D11 -> 78.75 | E11: ARIKSAN METAL | F11: TKI EGE LINYITLERI ISLETMESI MUDURLUGU
A12: 7 | B12: 23060 | C12: MEHMET KAZIM UZUN | D12: ='1-Ogrenci'!D12 -> 69.15 | E12: DEFAS MADENCILIK SAN. VE TIC. A.S. (DEMIR EXPORT) | F12: TKI EGE LINYITLERI ISLETMESI MUDURLUGU | G12: IMBAT MADENCILIK | H12: HIDRO-GEN ENERJI | I12: ARIKSAN METAL
A13: 8 | B13: 23068 | C13: SADETTIN AKSU | D13: ='1-Ogrenci'!D13 -> 70.57 | E13: TKI EGE LINYITLERI ISLETMESI MUDURLUGU | F13: DEFAS MADENCILIK SAN. VE TIC. A.S. (DEMIR EXPORT) | G13: HIDRO-GEN ENERJI | H13: IMBAT MADENCILIK | I13: ARIKSAN METAL
A14: 9 | B14: 23077 | C14: CENGIZHAN GEZGIN | D14: ='1-Ogrenci'!D14 -> 72.01 | E14: HIDRO-GEN ENERJI | F14: TKI EGE LINYITLERI ISLETMESI MUDURLUGU | G14: DEFAS MADENCILIK SAN. VE TIC. A.S. (DEMIR EXPORT) | H14: IMBAT MADENCILIK | I14: MODERANS METAL YAPI
A15: 10 | B15: 23081 | C15: BATIKAN ALEMDAR TASPINAR | D15: ='1-Ogrenci'!D15 -> 66.67 | E15: DEFAS MADENCILIK SAN. VE TIC. A.S. (DEMIR EXPORT) | F15: TKI EGE LINYITLERI ISLETMESI MUDURLUGU
A16: 11 | B16: 23087 | C16: YUSUF EFE CAL | D16: ='1-Ogrenci'!D16 -> 77 | E16: ARIKSAN METAL | F16: TKI EGE LINYITLERI ISLETMESI MUDURLUGU
A17: 12 | B17: 23100 | C17: MERT KOCABIYIK | D17: ='1-Ogrenci'!D17 -> 75.15 | E17: TKI EGE LINYITLERI ISLETMESI MUDURLUGU | F17: DEFAS MADENCILIK SAN. VE TIC. A.S. (DEMIR EXPORT) | G17: IMBAT MADENCILIK | H17: HIDRO-GEN ENERJI
A18: 13 | B18: 23102 | C18: HUSEYIN YEKTA SENLIK | D18: ='1-Ogrenci'!D18 -> 68.54 | E18: TKI EGE LINYITLERI ISLETMESI MUDURLUGU | F18: BULUT METAL | G18: ZINBA MAKINA SANAYI | H18: ARIKSAN METAL | I18: MODERANS METAL YAPI | J18: ZIRVE MAKINA | K18: DEFAS MADENCILIK SAN. VE TIC. A.S. (DEMIR EXPORT) | L18: HIDRO-GEN ENERJI | M18: IMBAT MADENCILIK | N18: E SINERJI MUHENDISLIK
A19: 14 | B19: 23104 | C19: ALI HAN CELIK | D19: ='1-Ogrenci'!D19 -> 71.48 | E19: TKI EGE LINYITLERI ISLETMESI MUDURLUGU | F19: HIDRO-GEN ENERJI | G19: ARIKSAN METAL | H19: BULUT METAL | I19: ZIRVE MAKINA | J19: ZINBA MAKINA SANAYI | K19: E SINERJI MUHENDISLIK
A20: 15 | B20: 23107 | C20: HASAN MERT ANAC | D20: ='1-Ogrenci'!D20 -> 71.79 | E20: TKI EGE LINYITLERI ISLETMESI MUDURLUGU | F20: DEFAS MADENCILIK SAN. VE TIC. A.S. (DEMIR EXPORT) | G20: ARIKSAN METAL | H20: ZINBA MAKINA SANAYI | I20: ZIRVE MAKINA
A21: 16 | B21: 23110 | C21: SULEYMAN COBAN | D21: ='1-Ogrenci'!D21 -> 63.71 | E21: ZIRVE MAKINA | F21: ARIKSAN METAL | G21: ZINBA MAKINA SANAYI | H21: BULUT METAL
A22: 17 | B22: 23112 | C22: EMIRHAN ERTURK | D22: ='1-Ogrenci'!D22 -> 63.45 | E22: TKI EGE LINYITLERI ISLETMESI MUDURLUGU | F22: DEFAS MADENCILIK SAN. VE TIC. A.S. (DEMIR EXPORT) | G22: IMBAT MADENCILIK | H22: ARIKSAN METAL | I22: BULUT METAL | J22: HIDRO-GEN ENERJI
A23: 18 | B23: 23113 | C23: MUHAMMET EMIN KILIC | D23: ='1-Ogrenci'!D23 -> 68.9 | E23: TKI EGE LINYITLERI ISLETMESI MUDURLUGU | F23: DEFAS MADENCILIK SAN. VE TIC. A.S. (DEMIR EXPORT) | G23: IMBAT MADENCILIK | H23: ARIKSAN METAL | I23: MODERANS METAL YAPI | J23: BULUT METAL | K23: ZIRVE MAKINA | L23: ZINBA MAKINA SANAYI | M23: HIDRO-GEN ENERJI | N23: E SINERJI MUHENDISLIK
A24: 19 | B24: 23117 | C24: SALIH AGCIK | D24: ='1-Ogrenci'!D24 -> 64.53 | E24: IMBAT MADENCILIK | F24: DEFAS MADENCILIK SAN. VE TIC. A.S. (DEMIR EXPORT) | G24: ZINBA MAKINA SANAYI | H24: HIDRO-GEN ENERJI | I24: ZIRVE MAKINA | J24: ARIKSAN METAL | K24: BULUT METAL | L24: TKI EGE LINYITLERI ISLETMESI MUDURLUGU
A25: 20 | B25: 23238 | C25: ARDA YILMAZ | D25: ='1-Ogrenci'!D25 -> 67.9 | E25: ARIKSAN METAL
A26: 21 | B26: 23245 | C26: AHMET CEMIL YILDIZ | D26: ='1-Ogrenci'!D26 -> 75.05 | E26: TKI EGE LINYITLERI ISLETMESI MUDURLUGU | F26: DEFAS MADENCILIK SAN. VE TIC. A.S. (DEMIR EXPORT) | G26: HIDRO-GEN ENERJI | H26: ARIKSAN METAL | I26: BULUT METAL | J26: ZIRVE MAKINA
A27: 22 | D27: ='1-Ogrenci'!D27 -> 0
A28: 23 | D28: ='1-Ogrenci'!D28 -> 0
A29: 24 | D29: ='1-Ogrenci'!D29 -> 0
A30: 25 | D30: ='1-Ogrenci'!D30 -> 0
A31: 26 | D31: ='1-Ogrenci'!D31 -> 0
A32: 27 | D32: ='1-Ogrenci'!D32 -> 0
A33: 28 | D33: ='1-Ogrenci'!D33 -> 0
A34: 29 | D34: ='1-Ogrenci'!D34 -> 0
A35: 30 | D35: ='1-Ogrenci'!D35 -> 0
A36: 31 | D36: ='1-Ogrenci'!D36 -> 0
A37: 32 | D37: ='1-Ogrenci'!D37 -> 0
A39: BILGISAYARLI MAKINE IMALATI (BMI) - B Subesi
A40: No | B40: Ogr.No | C40: Adi Soyadi | D40: Not Ort. | E40: 1. Tercih | F40: 2. Tercih | G40: 3. Tercih | H40: 4. Tercih | I40: 5. Tercih | J40: 6. Tercih | K40: 7. Tercih | L40: 8. Tercih | M40: 9. Tercih | N40: 10. Tercih | O40: GITMEK ISTEMEDIGIM ISLETMELER (virgülle)
A41: 1 | B41: 22102 | C41: RAMAZAN DOGANER | D41: ='1-Ogrenci'!J6 -> 60.79 | E41: TKI EGE LINYITLERI ISLETMESI MUDURLUGU | F41: DEFAS MADENCILIK SAN. VE TIC. A.S. (DEMIR EXPORT) | G41: ZIRVE MAKINA | H41: HIDRO-GEN ENERJI | I41: IMBAT MADENCILIK | J41: E SINERJI MUHENDISLIK | K41: ZINBA MAKINA SANAYI | L41: ARIKSAN METAL | M41: BULUT METAL | N41: MODERANS METAL YAPI
A42: 2
...

Sheet 3-Isletme
A1: STAJ YERI ISLETME LISTESI VE KONTENJAN TABLOSU
A2: Soma Mesleki ve Teknik Anadolu Lisesi | Makine Teknolojisi Alani | 2024/2025
A3: SARI = Kontenjan girisi | TURUNCU = Isletme talep ogrencisi | Bos satirlara yeni isletme eklenebilir (maks 20)
A4: No | B4: Isletme Adi | C4: MBO Kontenjan | D4: BMI Kontenjan | E4: Toplam Kontenjan | F4: Uygun Dal | G4: ISLETME TALEP OGRENCI (virgülle ayir) | H4: Talep Gereksesi
A5: 1 | B5: TKI EGE LINYITLERI ISLETMESI MUDURLUGU | C5: 5 | D5: 5 | E5: =IFERROR(IF(C5+D5=0,"",C5+D5),"") -> 10 | F5: MBO + BMI
A6: 2 | B6: DEFAS MADENCILIK SAN. VE TIC. A.S. (DEMIR EXPORT) | C6: 3 | D6: 2 | E6: =IFERROR(IF(C6+D6=0,"",C6+D6),"") -> 5 | F6: MBO + BMI | G6: BATIKAN ALEMDAR TASPINAR,MEHMET KAZIM UZUN | H6: ÇALIŞAN YAKINI
A7: 3 | B7: IMBAT MADENCILIK | C7: 2 | D7: 2 | E7: =IFERROR(IF(C7+D7=0,"",C7+D7),"") -> 4 | F7: MBO + BMI | G7: SALIH AGCIK,ALI HAN CELIK ,MERT BERAT VARLI,FAHRI CAN ILGAZ | H7: ÇALIŞAN YAKINI
A8: 4 | B8: E SINERJI MUHENDISLIK | C8: 0 | D8: 0 | E8: =IFERROR(IF(C8+D8=0,"",C8+D8),"") | F8: MBO + BMI
A9: 5 | B9: MODERANS METAL YAPI | C9: 0 | D9: 0 | E9: =IFERROR(IF(C9+D9=0,"",C9+D9),"") | F9: MBO + BMI
A10: 6 | B10: HIDRO-GEN ENERJI | C10: 2 | D10: 2 | E10: =IFERROR(IF(C10+D10=0,"",C10+D10),"") -> 4 | F10: MBO + BMI | G10: TUNAHAN TEKER,EREN OLUM | H10: ÇALIŞAN YAKINI
A11: 7 | B11: ARIKSAN METAL | C11: 3 | D11: 2 | E11: =IFERROR(IF(C11+D11=0,"",C11+D11),"") -> 5 | F11: MBO + BMI | G11: ARDA YILMAZ,YASAR ARDA CAL,YUSUF EFE CAL | H11: ÇALIŞAN YAKINI
A12: 8 | B12: BULUT METAL | C12: 1 | D12: 0 | E12: =IFERROR(IF(C12+D12=0,"",C12+D12),"") -> 1 | F12: MBO + BMI
A13: 9 | B13: ZINBA MAKINA SANAYI | C13: 1 | D13: 1 | E13: =IFERROR(IF(C13+D13=0,"",C13+D13),"") -> 2 | F13: MBO + BMI
A14: 10 | B14: ZIRVE MAKINA | C14: 1 | D14: 0 | E14: =IFERROR(IF(C14+D14=0,"",C14+D14),"") -> 1 | F14: MBO + BMI
A15: 11 | B15: NAZLI TORNA (HÜSEYİN NAZLI) | C15: 1 | D15: 0 | E15: =IFERROR(IF(C15+D15=0,"",C15+D15),"") -> 1 | F15: MBO + BMI | G15: HUSEYIN YEKTA SENLIK | H15: ÇALIŞAN YAKINI
A16: 12 | B16: ÜRÜN TAŞLAMA (AYCAN ÜRÜN) | C16: 1 | D16: 0 | E16: =IFERROR(IF(C16+D16=0,"",C16+D16),"") -> 1 | F16: MBO + BMI | G16: EMIRHAN ERTURK | H16: ÇALIŞAN YAKINI
A17: 13 | B17: UYSAL TORNA (MUHAMMET UYSAL) | C17: 1 | D17: 0 | E17: =IFERROR(IF(C17+D17=0,"",C17+D17),"") -> 1 | F17: MBO + BMI | G17: ISMAIL SIVRI | H17: ÇALIŞAN YAKINI
A18: 14 | C18: 0 | D18: 0 | E18: =IFERROR(IF(C18+D18=0,"",C18+D18),"") | F18: MBO + BMI
A19: 15 | C19: 0 | D19: 0 | E19: =IFERROR(IF(C19+D19=0,"",C19+D19),"") | F19: MBO + BMI
A20: 16 | C20: 0 | D20: 0 | E20: =IFERROR(IF(C20+D20=0,"",C20+D20),"") | F20: MBO + BMI
A21: 17 | C21: 0 | D21: 0 | E21: =IFERROR(IF(C21+D21=0,"",C21+D21),"") | F21: MBO + BMI
A22: 18 | C22: 0 | D22: 0 | E22: =IFERROR(IF(C22+D22=0,"",C22+D22),"") | F22: MBO + BMI
A23: 19 | C23: 0 | D23: 0 | E23: =IFERROR(IF(C23+D23=0,"",C23+D23),"") | F23: MBO + BMI
A24: 20 | C24: 0 | D24: 0 | E24: =IFERROR(IF(C24+D24=0,"",C24+D24),"") | F24: MBO + BMI
A25: GENEL TOPLAM KONTENJAN | C25: =SUM(C5:C24) -> 21 | D25: =SUM(D5:D24) -> 14 | E25: =SUM(E5:E24) -> 35
A27: Yeni isletme: Bos satira isletme adini ve kontenjanlarini yazin (maks 20). Isletme silmek icin satiri temizleyin.

Sheet 4-Sonuc
A1: SOMA MESLEKI VE TEKNIK ANADOLU LISESI - STAJ YERLESTIRME SONUCLARI
A2: 12. Sinif | 2024/2025 | Mudur: Ahmet Acar | Alan Sefi: ____________________
A3: YESIL=1.T | MAVI=2.T | SARI=3.T | TURUNCU=4.T | KIRMIZI=5.T | MOR=6.T | ACIK MAVI=7.T | AMBER=8.T | KOYU YESIL=9.T | PEMBE=10.T | GRI=Otomatik | BORDO=Zorunlu | AMBER=Isletme Talebi
A5: MAKINE BAKIM ONARIM (MBO) - YERLESTIRME SONUCLARI
A6: Sira | B6: Ogr.No | C6: Adi Soyadi | D6: Dal | E6: Not Ort. | F6: 1.T | G6: 2.T | H6: 3.T | I6: 4.T | J6: 5.T | K6: 6.T | L6: 7.T | M6: 8.T | N6: 9.T | O6: 10.T | P6: YERLESTIRILEN ISLETME | Q6: Tercih Sirasi | R6: DURUM
A7: =IF('1-Ogrenci'!C6<>"",1,"") -> 1 | B7: =IF('1-Ogrenci'!C6<>"",'1-Ogrenci'!B6,"") -> 1008 | C7: =IF('1-Ogrenci'!C6<>"",'1-Ogrenci'!C6,"") -> ZAFER SARI | D7: =IF('1-Ogrenci'!C6<>"","MBO","") -> MBO | E7: ='1-Ogrenci'!D6 -> 74.82 | F7: ='2-Tercih'!E7 -> TKI EGE LINYITLERI ISLETMESI MUDURLUGU | G7: ='2-Tercih'!F7 -> IMBAT MADENCILIK | H7: ='2-Tercih'!G7 -> DEFAS MADENCILIK SAN. VE TIC. A.S. (DEMIR EXPORT) | I7: ='2-Tercih'!H7 -> HIDRO-GEN ENERJI | J7: ='2-Tercih'!I7 -> ZIRVE MAKINA | K7: ='2-Tercih'!J7 -> 0 | L7: ='2-Tercih'!K7 -> 0 | M7: ='2-Tercih'!L7 -> 0 | ... O7: ='2-Tercih'!N7 -> 0 | P7: TKI EGE LINYITLERI ISLETMESI MUDURLUGU | Q7: 1. Tercih | R7: YERLESTI
A8: =IF('1-Ogrenci'!C7<>"",2,"") -> 2 | B8: =IF('1-Ogrenci'!C7<>"",'1-Ogrenci'!B7,"") -> 23014 | C8: =IF('1-Ogrenci'!C7<>"",'1-Ogrenci'!C7,"") -> RAMAZAN OVEK | D8: =IF('1-Ogrenci'!C7<>"","MBO","") -> MBO | E8: ='1-Ogrenci'!D7 -> 78.88 | F8: ='2-Tercih'!E8 -> UYSAL TORNA (MUHAMMET UYSAL) | G8: ='2-Tercih'!F8 -> TKI EGE LINYITLERI ISLETMESI MUDURLUGU | H8: ='2-Tercih'!G8 -> DEFAS MADENCILIK SAN. VE TIC. A.S. (DEMIR EXPORT) | I8: ='2-Tercih'!H8 -> IMBAT MADENCILIK | J8: ='2-Tercih'!I8 -> 0 | K8: ='2-Tercih'!J8 -> 0 | L8: ='2-Tercih'!K8 -> 0 | M8: ='2-Tercih'!L8 -> 0 | ... O8: ='2-Tercih'!N8 -> 0 | P8: TKI EGE LINYITLERI ISLETMESI MUDURLUGU | Q8: 1. Tercih | R8: YERLESTI
A9: =IF('1-Ogrenci'!C8<>"",3,"") -> 3 | B9: =IF('1-Ogrenci'!C8<>"",'1-Ogrenci'!B8,"") -> 23015 | C9: =IF('1-Ogrenci'!C8<>"",'1-Ogrenci'!C8,"") -> ISMAIL SIVRI | D9: =IF('1-Ogrenci'!C8<>"","MBO","") -> MBO | E9: ='1-Ogrenci'!D8 -> 77.56 | F9: ='2-Tercih'!E9 -> TKI EGE LINYITLERI ISLETMESI MUDURLUGU | G9: ='2-Tercih'!F9 -> HIDRO-GEN ENERJI | H9: ='2-Tercih'!G9 -> IMBAT MADENCILIK | I9: ='2-Tercih'!H9 -> DEFAS MADENCILIK SAN. VE TIC. A.S. (DEMIR EXPORT) | J9: ='2-Tercih'!I9 -> ARIKSAN METAL | K9: ='2-Tercih'!J9 -> E SINERJI MUHENDISLIK | L9: ='2-Tercih'!K9 -> 0 | M9: ='2-Tercih'!L9 -> 0 | ... O9: ='2-Tercih'!N9 -> 0 | P9: UYSAL TORNA (MUHAMMET UYSAL) | Q9: Isletme Talebi | R9: ISLETME TALEBI
A10: =IF('1-Ogrenci'!C9<>"",4,"") -> 4 | B10: =IF('1-Ogrenci'!C9<>"",'1-Ogrenci'!B9,"") -> 23034 | C10: =IF('1-Ogrenci'!C9<>"",'1-Ogrenci'!C9,"") -> ALI YILMAZ | D10: =IF('1-Ogrenci'!C9<>"","MBO","") -> MBO | E10: ='1-Ogrenci'!D9 -> 70.33 | F10: ='2-Tercih'!E10 -> HIDRO-GEN ENERJI | G10: ='2-Tercih'!F10 -> TKI EGE LINYITLERI ISLETMESI MUDURLUGU | H10: ='2-Tercih'!G10 -> DEFAS MADENCILIK SAN. VE TIC. A.S. (DEMIR EXPORT) | I10: ='2-Tercih'!H10 -> IMBAT MADENCILIK | J10: ='2-Tercih'!I10 -> MODERANS METAL YAPI | K10: ='2-Tercih'!J10 -> 0 | L10: ='2-Tercih'!K10 -> 0 | M10: ='2-Tercih'!L10 -> 0 | ... O10: ='2-Tercih'!N10 -> 0 | P10: DEFAS MADENCILIK SAN. VE TIC. A.S. (DEMIR EXPORT) | Q10: 4. Tercih | R10: YERLESTI
A11: =IF('1-Ogrenci'!C10<>"",5,"") -> 5 | B11: =IF('1-Ogrenci'!C10<>"",'1-Ogrenci'!B10,"") -> 23046 | C11: =IF('1-Ogrenci'!C10<>"",'1-Ogrenci'!C10,"") -> TUNAHAN TEKER | D11: =IF('1-Ogrenci'!C10<>"","MBO","") -> MBO | E11: ='1-Ogrenci'!D10 -> 71.6 | F11: ='2-Tercih'!E11 -> ARIKSAN METAL | G11: ='2-Tercih'!F11 -> TKI EGE LINYITLERI ISLETMESI MUDURLUGU | H11: ='2-Tercih'!G11 -> 0 | I11: ='2-Tercih'!H11 -> 0 | J11: ='2-Tercih'!I11 -> 0 | K11: ='2-Tercih'!J11 -> 0 | L11: ='2-Tercih'!K11 -> 0 | M11: ='2-Tercih'!L11 -> 0 | ... O11: ='2-Tercih'!N11 -> 0 | P11: HIDRO-GEN ENERJI | Q11: Isletme Talebi | R11: ISLETME TALEBI
A12: =IF('1-Ogrenci'!C11<>"",6,"") -> 6 | B12: =IF('1-Ogrenci'!C11<>"",'1-Ogrenci'!B11,"") -> 23050 | C12: =IF('1-Ogrenci'!C11<>"",'1-Ogrenci'!C11,"") -> YASAR ARDA CAL | D12: =IF('1-Ogrenci'!C11<>"","MBO","") -> MBO | E12: ='1-Ogrenci'!D11 -> 78.75 | F12: ='2-Tercih'!E12 -> DEFAS MADENCILIK SAN. VE TIC. A.S. (DEMIR EXPORT) | G12: ='2-Tercih'!F12 -> TKI EGE LINYITLERI ISLETMESI MUDURLUGU | H12: ='2-Tercih'!G12 -> IMBAT MADENCILIK | I12: ='2-Tercih'!H12 -> HIDRO-GEN ENERJI | J12: ='2-Tercih'!I12 -> ARIKSAN METAL | K12: ='2-Tercih'!J12 -> 0 | L12: ='2-Tercih'!K12 -> 0 | M12: ='2-Tercih'!L12 -> 0 | ... O12: ='2-Tercih'!N12 -> 0 | P12: ARIKSAN METAL | Q12: Isletme Talebi | R12: ISLETME TALEBI
A13: =IF('1-Ogrenci'!C12<>"",7,"") -> 7 | B13: =IF('1-Ogrenci'!C12<>"",'1-Ogrenci'!B12,"") -> 23060 | C13: =IF('1-Ogrenci'!C12<>"",'1-Ogrenci'!C12,"") -> MEHMET KAZIM UZUN | D13: =IF('1-Ogrenci'!C12<>"","MBO","") -> MBO | E13: ='1-Ogrenci'!D12 -> 69.15 | F13: ='2-Tercih'!E13 -> TKI EGE LINYITLERI ISLETMESI MUDURLUGU | G13: ='2-Tercih'!F13 -> DEFAS MADENCILIK SAN. VE TIC. A.S. (DEMIR EXPORT) | H13: ='2-Tercih'!G13 -> HIDRO-GEN ENERJI | I13: ='2-Tercih'!H13 -> IMBAT MADENCILIK | J13: ='2-Tercih'!I13 -> ARIKSAN METAL | K13: ='2-Tercih'!J13 -> 0 | L13: ='2-Tercih'!K13 -> 0 | M13: ='2-Tercih'!L13 -> 0 | ... O13: ='2-Tercih'!N13 -> 0 | P13: DEFAS MADENCILIK SAN. VE TIC. A.S. (DEMIR EXPORT) | Q13: Isletme Talebi | R13: ISLETME TALEBI
A14: =IF('1-Ogrenci'!C13<>"",8,"") -> 8 | B14: =IF('1-Ogrenci'!C13<>"",'1-Ogrenci'!B13,"") -> 23068 | C14: =IF('1-Ogrenci'!C13<>"",'1-Ogrenci'!C13,"") -> SADETTIN AKSU | D14: =IF('1-Ogrenci'!C13<>"","MBO","") -> MBO | E14: ='1-Ogrenci'!D13 -> 70.57 | F14: ='2-Tercih'!E14 -> HIDRO-GEN ENERJI | G14: ='2-Tercih'!F14 -> TKI EGE LINYITLERI ISLETMESI MUDURLUGU | H14: ='2-Tercih'!G14 -> DEFAS MADENCILIK SAN. VE TIC. A.S. (DEMIR EXPORT) | I14: ='2-Tercih'!H14 -> IMBAT MADENCILIK | J14: ='2-Tercih'!I14 -> MODERANS METAL YAPI | K14: ='2-Tercih'!J14 -> 0 | L14: ='2-Tercih'!K14 -> 0 | M14: ='2-Tercih'!L14 -> 0 | ... O14: ='2-Tercih'!N14 -> 0 | P14: ZINBA MAKINA SANAYI | Q14: Otomatik | R14: OTOMATIK
A15: =IF('1-Ogrenci'!C14<>"",9,"") -> 9 | B15: =IF('1-Ogrenci'!C14<>"",'1-Ogrenci'!B14,"") -> 23077 | C15: =IF('1-Ogrenci'!C14<>"",'1-Ogrenci'!C14,"") -> CENGIZHAN GEZGIN | D15: =IF('1-Ogrenci'!C14<>"","MBO","") -> MBO | E15: ='1-Ogrenci'!D14 -> 72.01 | F15: ='2-Tercih'!E15 -> DEFAS MADENCILIK SAN. VE TIC. A.S. (DEMIR EXPORT) | G15: ='2-Tercih'!F15 -> TKI EGE LINYITLERI ISLETMESI MUDURLUGU | H15: ='2-Tercih'!G15 -> 0 | I15: ='2-Tercih'!H15 -> 0 | J15: ='2-Tercih'!I15 -> 0 | K15: ='2-Tercih'!J15 -> 0 | L15: ='2-Tercih'!K15 -> 0 | M15: ='2-Tercih'!L15 -> 0 | ... O15: ='2-Tercih'!N15 -> 0 | P15: HIDRO-GEN ENERJI | Q15: 1. Tercih | R15: YERLESTI
A16: =IF('1-Ogrenci'!C15<>"",10,"") -> 10 | B16: =IF('1-Ogrenci'!C15<>"",'1-Ogrenci'!B15,"") -> 23081 | C16: =IF('1-Ogrenci'!C15<>"",'1-Ogrenci'!C15,"") -> BATIKAN ALEMDAR TASPINAR | D16: =IF('1-Ogrenci'!C15<>"","MBO","") -> MBO | E16: ='1-Ogrenci'!D15 -> 66.67 | F16: ='2-Tercih'!E16 -> ARIKSAN METAL | G16: ='2-Tercih'!F16 -> TKI EGE LINYITLERI ISLETMESI MUDURLUGU | H16: ='2-Tercih'!G16 -> 0 | I16: ='2-Tercih'!H16 -> 0 | J16: ='2-Tercih'!I16 -> 0 | K16: ='2-Tercih'!J16 -> 0 | L16: ='2-Tercih'!K16 -> 0 | M16: ='2-Tercih'!L16 -> 0 | ... O16: ='2-Tercih'!N16 -> 0 | P16: DEFAS MADENCILIK SAN. VE TIC. A.S. (DEMIR EXPORT) | Q16: Isletme Talebi | R16: ISLETME TALEBI
A17: =IF('1-Ogrenci'!C16<>"",11,"") -> 11 | B17: =IF('1-Ogrenci'!C16<>"",'1-Ogrenci'!B16,"") -> 23087 | C17: =IF('1-Ogrenci'!C16<>"",'1-Ogrenci'!C16,"") -> YUSUF EFE CAL | D17: =IF('1-Ogrenci'!C16<>"","MBO","") -> MBO | E17: ='1-Ogrenci'!D16 -> 77 | F17: ='2-Tercih'!E17 -> TKI EGE LINYITLERI ISLETMESI MUDURLUGU | G17: ='2-Tercih'!F17 -> DEFAS MADENCILIK SAN. VE TIC. A.S. (DEMIR EXPORT) | H17: ='2-Tercih'!G17 -> IMBAT MADENCILIK | I17: ='2-Tercih'!H17 -> HIDRO-GEN ENERJI | J17: ='2-Tercih'!I17 -> 0 | K17: ='2-Tercih'!J17 -> 0 | L17: ='2-Tercih'!K17 -> 0 | M17: ='2-Tercih'!L17 -> 0 | ... O17: ='2-Tercih'!N17 -> 0 | P17: ARIKSAN METAL | Q17: Isletme Talebi | R17: ISLETME TALEBI
A18: =IF('1-Ogrenci'!C17<>"",12,"") -> 12 | B18: =IF('1-Ogrenci'!C17<>"",'1-Ogrenci'!B17,"") -> 23100 | C18: =IF('1-Ogrenci'!C17<>"",'1-Ogrenci'!C17,"") -> MERT KOCABIYIK | D18: =IF('1-Ogrenci'!C17<>"","MBO","") -> MBO | E18: ='1-Ogrenci'!D17 -> 75.15 | F18: ='2-Tercih'!E18 -> TKI EGE LINYITLERI ISLETMESI MUDURLUGU | G18: ='2-Tercih'!F18 -> BULUT METAL | H18: ='2-Tercih'!G18 -> ZINBA MAKINA SANAYI | I18: ='2-Tercih'!H18 -> ARIKSAN METAL | J18: ='2-Tercih'!I18 -> MODERANS METAL YAPI | K18: ='2-Tercih'!J18 -> ZIRVE MAKINA | L18: ='2-Tercih'!K18 -> DEFAS MADENCILIK SAN. VE TIC. A.S. (DEMIR EXPORT) | M18: ='2-Tercih'!L18 -> HIDRO-GEN ENERJI | ... O18: ='2-Tercih'!N18 -> E SINERJI MUHENDISLIK | P18: TKI EGE LINYITLERI ISLETMESI MUDURLUGU | Q18: 1. Tercih | R18: YERLESTI
A19: =IF('1-Ogrenci'!C18<>"",13,"") -> 13 | B19: =IF('1-Ogrenci'!C18<>"",'1-Ogrenci'!B18,"") -> 23102 | C19: =IF('1-Ogrenci'!C18<>"",'1-Ogrenci'!C18,"") -> HUSEYIN YEKTA SENLIK | D19: =IF('1-Ogrenci'!C18<>"","MBO","") -> MBO | E19: ='1-Ogrenci'!D18 -> 68.54 | F19: ='2-Tercih'!E19 -> TKI EGE LINYITLERI ISLETMESI MUDURLUGU | G19: ='2-Tercih'!F19 -> HIDRO-GEN ENERJI | H19: ='2-Tercih'!G19 -> ARIKSAN METAL | I19: ='2-Tercih'!H19 -> BULUT METAL | J19: ='2-Tercih'!I19 -> ZIRVE MAKINA | K19: ='2-Tercih'!J19 -> ZINBA MAKINA SANAYI | L19: ='2-Tercih'!K19 -> E SINERJI MUHENDISLIK | M19: ='2-Tercih'!L19 -> 0 | ... O19: ='2-Tercih'!N19 -> 0 | P19: NAZLI TORNA (HÜSEYİN NAZLI) | Q19: Isletme Talebi | R19: ISLETME TALEBI
A20: =IF('1-Ogrenci'!C19<>"",14,"") -> 14 | B20: =IF('1-Ogrenci'!C19<>"",'1-Ogrenci'!B19,"") -> 23104 | C20: =IF('1-Ogrenci'!C19<>"",'1-Ogrenci'!C19,"") -> ALI HAN CELIK | D20: =IF('1-Ogrenci'!C19<>"","MBO","") -> MBO | E20: ='1-Ogrenci'!D19 -> 71.48 | F20: ='2-Tercih'!E20 -> TKI EGE LINYITLERI ISLETMESI MUDURLUGU | G20: ='2-Tercih'!F20 -> DEFAS MADENCILIK SAN. VE TIC. A.S. (DEMIR EXPORT) | H20: ='2-Tercih'!G20 -> ARIKSAN METAL | I20: ='2-Tercih'!H20 -> ZINBA MAKINA SANAYI | J20: ='2-Tercih'!I20 -> ZIRVE MAKINA | K20: ='2-Tercih'!J20 -> 0 | L20: ='2-Tercih'!K20 -> 0 | M20: ='2-Tercih'!L20 -> 0 | ... O20: ='2-Tercih'!N20 -> 0 | P20: IMBAT MADENCILIK | Q20: Isletme Talebi | R20: ISLETME TALEBI
A21: =IF('1-Ogrenci'!C20<>"",15,"") -> 15 | B21: =IF('1-Ogrenci'!C20<>"",'1-Ogrenci'!B20,"") -> 23107 | C21: =IF('1-Ogrenci'!C20<>"",'1-Ogrenci'!C20,"") -> HASAN MERT ANAC | D21: =IF('1-Ogrenci'!C20<>"","MBO","") -> MBO | E21: ='1-Ogrenci'!D20 -> 71.79 | F21: ='2-Tercih'!E21 -> ZIRVE MAKINA | G21: ='2-Tercih'!F21 -> ARIKSAN METAL | H21: ='2-Tercih'!G21 -> ZINBA MAKINA SANAYI | I21: ='2-Tercih'!H21 -> BULUT METAL | J21: ='2-Tercih'!I21 -> 0 | K21: ='2-Tercih'!J21 -> 0 | L21: ='2-Tercih'!K21 -> 0 | M21: ='2-Tercih'!L21 -> 0 | ... O21: ='2-Tercih'!N21 -> 0 | P21: TKI EGE LINYITLERI ISLETMESI MUDURLUGU | Q21: 1. Tercih | R21: YERLESTI
A22: =IF('1-Ogrenci'!C21<>"",16,"") -> 16 | B22: =IF('1-Ogrenci'!C21<>"",'1-Ogrenci'!B21,"") -> 23110 | C22: =IF('1-Ogrenci'!C21<>"",'1-Ogrenci'!C21,"") -> SULEYMAN COBAN | D22: =IF('1-Ogrenci'!C21<>"","MBO","") -> MBO | E22: ='1-Ogrenci'!D21 -> 63.71 | F22: ='2-Tercih'!E22 -> TKI EGE LINYITLERI ISLETMESI MUDURLUGU | G22: ='2-Tercih'!F22 -> DEFAS MADENCILIK SAN. VE TIC. A.S. (DEMIR EXPORT) | H22: ='2-Tercih'!G22 -> IMBAT MADENCILIK | I22: ='2-Tercih'!H22 -> ARIKSAN METAL | J22: ='2-Tercih'!I22 -> BULUT METAL | K22: ='2-Tercih'!J22 -> HIDRO-GEN ENERJI | L22: ='2-Tercih'!K22 -> 0 | M22: ='2-Tercih'!L22 -> 0 | ... O22: ='2-Tercih'!N22 -> 0 | P22: ZIRVE MAKINA | Q22: 1. Tercih | R22: YERLESTI
A23: =IF('1-Ogrenci'!C22<>"",17,"") -> 17 | B23: =IF('1-Ogrenci'!C22<>"",'1-Ogrenci'!B22,"") -> 23112 | C23: =IF('1-Ogrenci'!C22<>"",'1-Ogrenci'!C22,"") -> EMIRHAN ERTURK | D23: =IF('1-Ogrenci'!C22<>"","MBO","") -> MBO | E23: ='1-Ogrenci'!D22 -> 63.45 | F23: ='2-Tercih'!E23 -> TKI EGE LINYITLERI ISLETMESI MUDURLUGU | G23: ='2-Tercih'!F23 -> DEFAS MADENCILIK SAN. VE TIC. A.S. (DEMIR EXPORT) | H23: ='2-Tercih'!G23 -> IMBAT MADENCILIK | I23: ='2-Tercih'!H23 -> ARIKSAN METAL | J23: ='2-Tercih'!I23 -> MODERANS METAL YAPI | K23: ='2-Tercih'!J23 -> BULUT METAL | L23: ='2-Tercih'!K23 -> ZIRVE MAKINA | M23: ='2-Tercih'!L23 -> ZINBA MAKINA SANAYI | ... O23: ='2-Tercih'!N23 -> E SINERJI MUHENDISLIK | P23: ÜRÜN TAŞLAMA (AYCAN ÜRÜN) | Q23: Isletme Talebi | R23: ISLETME TALEBI
A24: =IF('1-Ogrenci'!C23<>"",18,"") -> 18 | B24: =IF('1-Ogrenci'!C23<>"",'1-Ogrenci'!B23,"") -> 23113 | C24: =IF('1-Ogrenci'!C23<>"",'1-Ogrenci'!C23,"") -> MUHAMMET EMIN KILIC | D24: =IF('1-Ogrenci'!C23<>"","MBO","") -> MBO | E24: ='1-Ogrenci'!D23 -> 68.9 | F24: ='2-Tercih'!E24 -> IMBAT MADENCILIK | G24: ='2-Tercih'!F24 -> DEFAS MADENCILIK SAN. VE TIC. A.S. (DEMIR EXPORT) | H24: ='2-Tercih'!G24 -> ZINBA MAKINA SANAYI | I24: ='2-Tercih'!H24 -> HIDRO-GEN ENERJI | J24: ='2-Tercih'!I24 -> ZIRVE MAKINA | K24: ='2-Tercih'!J24 -> ARIKSAN METAL | L24: ='2-Tercih'!K24 -> BULUT METAL | M24: ='2-Tercih'!L24 -> TKI EGE LINYITLERI ISLETMESI MUDURLUGU | ... O24: ='2-Tercih'!N24 -> 0 | P24: BULUT METAL | Q24: 6. Tercih | R24: YERLESTI
A25: =IF('1-Ogrenci'!C24<>"",19,"") -> 19 | B25: =IF('1-Ogrenci'!C24<>"",'1-Ogrenci'!B24,"") -> 23117 | C25: =IF('1-Ogrenci'!C24<>"",'1-Ogrenci'!C24,"") -> SALIH AGCIK | D25: =IF('1-Ogrenci'!C24<>"","MBO","") -> MBO | E25: ='1-Ogrenci'!D24 -> 64.53 | F25: ='2-Tercih'!E25 -> ARIKSAN METAL | G25: ='2-Tercih'!F25 -> 0 | H25: ='2-Tercih'!G25 -> 0 | I25: ='2-Tercih'!H25 -> 0 | J25: ='2-Tercih'!I25 -> 0 | K25: ='2-Tercih'!J25 -> 0 | L25: ='2-Tercih'!K25 -> 0 | M25: ='2-Tercih'!L25 -> 0 | ... O25: ='2-Tercih'!N25 -> 0 | P25: IMBAT MADENCILIK | Q25: Isletme Talebi | R25: ISLETME TALEBI
A26: =IF('1-Ogrenci'!C25<>"",20,"") -> 20 | B26: =IF('1-Ogrenci'!C25<>"",'1-Ogrenci'!B25,"") -> 23238 | C26: =IF('1-Ogrenci'!C25<>"",'1-Ogrenci'!C25,"") -> ARDA YILMAZ | D26: =IF('1-Ogrenci'!C25<>"","MBO","") -> MBO | E26: ='1-Ogrenci'!D25 -> 67.9 | F26: ='2-Tercih'!E26 -> TKI EGE LINYITLERI ISLETMESI MUDURLUGU | G26: ='2-Tercih'!F26 -> DEFAS MADENCILIK SAN. VE TIC. A.S. (DEMIR EXPORT) | H26: ='2-Tercih'!G26 -> HIDRO-GEN ENERJI | I26: ='2-Tercih'!H26 -> ARIKSAN METAL | J26: ='2-Tercih'!I26 -> BULUT METAL | K26: ='2-Tercih'!J26 -> ZIRVE MAKINA | L26: ='2-Tercih'!K26 -> 0 | M26: ='2-Tercih'!L26 -> 0 | ... O26: ='2-Tercih'!N26 -> 0 | P26: ARIKSAN METAL | Q26: Isletme Talebi | R26: ISLETME TALEBI
A27: =IF('1-Ogrenci'!C26<>"",21,"") -> 21 | B27: =IF('1-Ogrenci'!C26<>"",'1-Ogrenci'!B26,"") -> 23245 | C27: =IF('1-Ogrenci'!C26<>"",'1-Ogrenci'!C26,"") -> AHMET CEMIL YILDIZ | D27: =IF('1-Ogrenci'!C26<>"","MBO","") -> MBO | E27: ='1-Ogrenci'!D26 -> 75.05 | F27: ='2-Tercih'!E27 -> 0 | G27: ='2-Tercih'!F27 -> 0 | H27: ='2-Tercih'!G27 -> 0 | I27: ='2-Tercih'!H27 -> 0 | J27: ='2-Tercih'!I27 -> 0 | K27: ='2-Tercih'!J27 -> 0 | L27: ='2-Tercih'!K27 -> 0 | M27: ='2-Tercih'!L27 -> 0 | ... O27: ='2-Tercih'!N27 -> 0 | P27: TKI EGE LINYITLERI ISLETMESI MUDURLUGU | Q27: 1. Tercih | R27: YERLESTI
A28: =IF('1-Ogrenci'!C27<>"",22,"") | B28: =IF('1-Ogrenci'!C27<>"",'1-Ogrenci'!B27,"") | C28: =IF('1-Ogrenci'!C27<>"",'1-Ogrenci'!C27,"") | D28: =IF('1-Ogrenci'!C27<>"","MBO","")
A29: =IF('1-Ogrenci'!C28<>"",23,"") | B29: =IF('1-Ogrenci'!C28<>"",'1-Ogrenci'!B28,"") | C29: =IF('1-Ogrenci'!C28<>"",'1-Ogrenci'!C28,"") | D29: =IF('1-Ogrenci'!C28<>"","MBO","")
A30: =IF('1-Ogrenci'!C29<>"",24,"") | B30: =IF('1-Ogrenci'!C29<>"",'1-Ogrenci'!B29,"") | C30: =IF('1-Ogrenci'!C29<>"",'1-Ogrenci'!C29,"") | D30: =IF('1-Ogrenci'!C29<>"","MBO","")
A31: =IF('1-Ogrenci'!C30<>"",25,"") | B31: =IF('1-Ogrenci'!C30<>"",'1-Ogrenci'!B30,"") | C31: =IF('1-Ogrenci'!C30<>"",'1-Ogrenci'!C30,"") | D31: =IF('1-Ogrenci'!C30<>"","MBO","")
A32: =IF('1-Ogrenci'!C31<>"",26,"") | B32: =IF('1-Ogrenci'!C31<>"",'1-Ogrenci'!B31,"") | C32: =IF('1-Ogrenci'!C31<>"",'1-Ogrenci'!C31,"") | D32: =IF('1-Ogrenci'!C31<>"","MBO","")
A33: =IF('1-Ogrenci'!C32<>"",27,"") | B33: =IF('1-Ogrenci'!C32<>"",'1-Ogrenci'!B32,"") | C33: =IF('1-Ogrenci'!C32<>"",'1-Ogrenci'!C32,"") | D33: =IF('1-Ogrenci'!C32<>"","MBO","")
A34: =IF('1-Ogrenci'!C33<>"",28,"") | B34: =IF('1-Ogrenci'!C33<>"",'1-Ogrenci'!B33,"") | C34: =IF('1-Ogrenci'!C33<>"",'1-Ogrenci'!C33,"") | D34: =IF('1-Ogrenci'!C33<>"","MBO","")
A35: =IF('1-Ogrenci'!C34<>"",29,"") | B35: =IF('1-Ogrenci'!C34<>"",'1-Ogrenci'!B34,"") | C35: =IF('1-Ogrenci'!C34<>"",'1-Ogrenci'!C34,"") | D35: =IF('1-Ogrenci'!C34<>"","MBO","")
A36: =IF('1-Ogrenci'!C35<>"",30,"") | B36: =IF('1-Ogrenci'!C35<>"",'1-Ogrenci'!B35,"") | C36: =IF('1-Ogrenci'!C35<>"",'1-Ogrenci'!C35,"") | D36: =IF('1-Ogrenci'!C35<>"","MBO","")
A37: =IF('1-Ogrenci'!C36<>"",31,"") | B37: =IF('1-Ogrenci'!C36<>"",'1-Ogrenci'!B36,"") | C37: =IF('1-Ogrenci'!C36<>"",'1-Ogrenci'!C36,"") | D37: =IF('1-Ogrenci'!C36<>"","MBO","")
A38: =IF('1-Ogrenci'!C37<>"",32,"") | B38: =IF('1-Ogrenci'!C37<>"",'1-Ogrenci'!B37,"") | C38: =IF('1-Ogrenci'!C37<>"",'1-Ogrenci'!C37,"") | D38: =IF('1-Ogrenci'!C37<>"","MBO","")
A40: BILGISAYARLI MAKINE IMALATI (BMI) - YERLESTIRME SONUCLARI
A41: Sira | B41: Ogr.No | C41: Adi Soyadi | D41: Dal | E41: Not Ort. | F41: 1.T | G41: 2.T | H41: 3.T | I41: 4.T | J41: 5.T | K41: 6.T | L41: 7.T | M41: 8.T | N41: 9.T | O41: 10.T | P41: YERLESTIRILEN ISLETME | Q41: Tercih Sirasi | R41: DURUM
A42: =IF('1-Ogrenci'!I6<>"",1,"") -> 1 | B42: =IF('1-Ogrenci'!I6<>"",'1-Ogrenci'!H6,"") -> 22102 | C42: =IF('1-Ogrenci'!I6<>"",'1-Ogrenci'!I6,"") -> RAMAZAN DOGANER | D42: =IF('1-Ogrenci'!I6<>"","BMI","") -> BMI | E42: ='1-Ogrenci'!J6 -> 60.79 | F42: ='2-Tercih'!E41 -> TKI EGE LINYITLERI ISLETMESI MUDURLUGU | G42: ='2-Tercih'!F41 -> DEFAS MADENCILIK SAN. VE TIC. A.S. (DEMIR EXPORT) | H42: ='2-Tercih'!G41 -> ZIRVE MAKINA | I42: ='2-Tercih'!H41 -> HIDRO-GEN ENERJI | J42: ='2-Tercih'!I41 -> IMBAT MADENCILIK | K42: ='2-Tercih'!J41 -> E SINERJI MUHENDISLIK | L42: ='2-Tercih'!K41 -> ZINBA MAKINA SANAYI | M42: ='2-Tercih'!L41 -> ARIKSAN METAL | ... O42: ='2-Tercih'!N41 -> MODERANS METAL YAPI | P42: ZINBA MAKINA SANAYI | Q42: 7. Tercih | R42: YERLESTI
...
