Workbook

Sheet TAKVİM
A1: TAKVİM — Öğretim yılını seçin; tüm ders sayfalarındaki tarihler otomatik hesaplanır
A3: OKUL | B3: Soma Mesleki ve Teknik Anadolu Lisesi
A4: ÖĞRETİM YILI SEÇ | B4: 2026-2027
A5: 1.Yarıyıl Başlangıcı (elle değiştirilebilir) | B5: =DATE(VALUE(LEFT($B$4,4)),9,14)-(WEEKDAY(DATE(VALUE(LEFT($B$4,4)),9,14),2)-1) -> 46279
A6: Not: Ramazan/Kurban Bayramı otomatik hesaplanamaz; resmî tatil haftalarının konumu (Ara Tatil/Yarıyıl Tatili) örnek 2026-2027 takvimine göre sabit varsayılmıştır.
A8: 37 HAFTALIK ÇALIŞMA TAKVİMİ (Pazartesi tarihleri)
A9: Hafta No | B9: Pazartesi Tarihi | C9: Tarih Aralığı (görsel) | D9: Tatil mi? | E9: Tatil Adı
A10: 1 | B10: =($B$5+(1-1)*7) -> 46279 | C10: =IF(MONTH(($B$5+(1-1)*7))=MONTH((($B$5+(1-1)*7)+4)),TEXT(DAY(($B$5+(1-1)*7)),"00")&"-"&TEXT(DAY((($B$5+(1-1)*7)+4)),"00")&" "&CHOOSE(MONTH(($B$5+(1-1)*7)),"Ocak","Şubat","Mart","Nisan","Mayıs","Haziran","Temmuz","Ağustos","Eylül","Ekim","Kasım","Aralık"),TEXT(DAY(($B$5+(1-1)*7)),"00")&" "&CHOOSE(MONTH(($B$5+(1-1)*7)),"Ocak","Şubat","Mart","Nisan","Mayıs","Haziran","Temmuz","Ağustos","Eylül","Ekim","Kasım","Aralık")&" - "&TEXT(DAY((($B$5+(1-1)*7)+4)),"00")&" "&CHOOSE(MONTH((($B$5+(1-1)*7)+4)),"Ocak","Şubat","Mart","Nisan","Mayıs","Haziran","Temmuz","Ağustos","Eylül","Ekim","Kasım","Aralık")) -> 14-18 Eylül | D10: HAYIR
A11: 2 | B11: =($B$5+(2-1)*7) -> 46286 | C11: =IF(MONTH(($B$5+(2-1)*7))=MONTH((($B$5+(2-1)*7)+4)),TEXT(DAY(($B$5+(2-1)*7)),"00")&"-"&TEXT(DAY((($B$5+(2-1)*7)+4)),"00")&" "&CHOOSE(MONTH(($B$5+(2-1)*7)),"Ocak","Şubat","Mart","Nisan","Mayıs","Haziran","Temmuz","Ağustos","Eylül","Ekim","Kasım","Aralık"),TEXT(DAY(($B$5+(2-1)*7)),"00")&" "&CHOOSE(MONTH(($B$5+(2-1)*7)),"Ocak","Şubat","Mart","Nisan","Mayıs","Haziran","Temmuz","Ağustos","Eylül","Ekim","Kasım","Aralık")&" - "&TEXT(DAY((($B$5+(2-1)*7)+4)),"00")&" "&CHOOSE(MONTH((($B$5+(2-1)*7)+4)),"Ocak","Şubat","Mart","Nisan","Mayıs","Haziran","Temmuz","Ağustos","Eylül","Ekim","Kasım","Aralık")) -> 21-25 Eylül | D11: HAYIR
A12: 3 | B12: =($B$5+(3-1)*7) -> 46293 | C12: =IF(MONTH(($B$5+(3-1)*7))=MONTH((($B$5+(3-1)*7)+4)),TEXT(DAY(($B$5+(3-1)*7)),"00")&"-"&TEXT(DAY((($B$5+(3-1)*7)+4)),"00")&" "&CHOOSE(MONTH(($B$5+(3-1)*7)),"Ocak","Şubat","Mart","Nisan","Mayıs","Haziran","Temmuz","Ağustos","Eylül","Ekim","Kasım","Aralık"),TEXT(DAY(($B$5+(3-1)*7)),"00")&" "&CHOOSE(MONTH(($B$5+(3-1)*7)),"Ocak","Şubat","Mart","Nisan","Mayıs","Haziran","Temmuz","Ağustos","Eylül","Ekim","Kasım","Aralık")&" - "&TEXT(DAY((($B$5+(3-1)*7)+4)),"00")&" "&CHOOSE(MONTH((($B$5+(3-1)*7)+4)),"Ocak","Şubat","Mart","Nisan","Mayıs","Haziran","Temmuz","Ağustos","Eylül","Ekim","Kasım","Aralık")) -> 28 Eylül - 02 Ekim | D12: HAYIR
A13: 4 | B13: =($B$5+(4-1)*7) -> 46300 | C13: =IF(MONTH(($B$5+(4-1)*7))=MONTH((($B$5+(4-1)*7)+4)),TEXT(DAY(($B$5+(4-1)*7)),"00")&"-"&TEXT(DAY((($B$5+(4-1)*7)+4)),"00")&" "&CHOOSE(MONTH(($B$5+(4-1)*7)),"Ocak","Şubat","Mart","Nisan","Mayıs","Haziran","Temmuz","Ağustos","Eylül","Ekim","Kasım","Aralık"),TEXT(DAY(($B$5+(4-1)*7)),"00")&" "&CHOOSE(MONTH(($B$5+(4-1)*7)),"Ocak","Şubat","Mart","Nisan","Mayıs","Haziran","Temmuz","Ağustos","Eylül","Ekim","Kasım","Aralık")&" - "&TEXT(DAY((($B$5+(4-1)*7)+4)),"00")&" "&CHOOSE(MONTH((($B$5+(4-1)*7)+4)),"Ocak","Şubat","Mart","Nisan","Mayıs","Haziran","Temmuz","Ağustos","Eylül","Ekim","Kasım","Aralık")) -> 05-09 Ekim | D13: HAYIR
A14: 5 | B14: =($B$5+(5-1)*7) -> 46307 | C14: =IF(MONTH(($B$5+(5-1)*7))=MONTH((($B$5+(5-1)*7)+4)),TEXT(DAY(($B$5+(5-1)*7)),"00")&"-"&TEXT(DAY((($B$5+(5-1)*7)+4)),"00")&" "&CHOOSE(MONTH(($B$5+(5-1)*7)),"Ocak","Şubat","Mart","Nisan","Mayıs","Haziran","Temmuz","Ağustos","Eylül","Ekim","Kasım","Aralık"),TEXT(DAY(($B$5+(5-1)*7)),"00")&" "&CHOOSE(MONTH(($B$5+(5-1)*7)),"Ocak","Şubat","Mart","Nisan","Mayıs","Haziran","Temmuz","Ağustos","Eylül","Ekim","Kasım","Aralık")&" - "&TEXT(DAY((($B$5+(5-1)*7)+4)),"00")&" "&CHOOSE(MONTH((($B$5+(5-1)*7)+4)),"Ocak","Şubat","Mart","Nisan","Mayıs","Haziran","Temmuz","Ağustos","Eylül","Ekim","Kasım","Aralık")) -> 12-16 Ekim | D14: HAYIR
A15: 6 | B15: =($B$5+(6-1)*7) -> 46314 | C15: =IF(MONTH(($B$5+(6-1)*7))=MONTH((($B$5+(6-1)*7)+4)),TEXT(DAY(($B$5+(6-1)*7)),"00")&"-"&TEXT(DAY((($B$5+(6-1)*7)+4)),"00")&" "&CHOOSE(MONTH(($B$5+(6-1)*7)),"Ocak","Şubat","Mart","Nisan","Mayıs","Haziran","Temmuz","Ağustos","Eylül","Ekim","Kasım","Aralık"),TEXT(DAY(($B$5+(6-1)*7)),"00")&" "&CHOOSE(MONTH(($B$5+(6-1)*7)),"Ocak","Şubat","Mart","Nisan","Mayıs","Haziran","Temmuz","Ağustos","Eylül","Ekim","Kasım","Aralık")&" - "&TEXT(DAY((($B$5+(6-1)*7)+4)),"00")&" "&CHOOSE(MONTH((($B$5+(6-1)*7)+4)),"Ocak","Şubat","Mart","Nisan","Mayıs","Haziran","Temmuz","Ağustos","Eylül","Ekim","Kasım","Aralık")) -> 19-23 Ekim | D15: HAYIR
A16: 7 | B16: =($B$5+(7-1)*7) -> 46321 | C16: =IF(MONTH(($B$5+(7-1)*7))=MONTH((($B$5+(7-1)*7)+4)),TEXT(DAY(($B$5+(7-1)*7)),"00")&"-"&TEXT(DAY((($B$5+(7-1)*7)+4)),"00")&" "&CHOOSE(MONTH(($B$5+(7-1)*7)),"Ocak","Şubat","Mart","Nisan","Mayıs","Haziran","Temmuz","Ağustos","Eylül","Ekim","Kasım","Aralık"),TEXT(DAY(($B$5+(7-1)*7)),"00")&" "&CHOOSE(MONTH(($B$5+(7-1)*7)),"Ocak","Şubat","Mart","Nisan","Mayıs","Haziran","Temmuz","Ağustos","Eylül","Ekim","Kasım","Aralık")&" - "&TEXT(DAY((($B$5+(7-1)*7)+4)),"00")&" "&CHOOSE(MONTH((($B$5+(7-1)*7)+4)),"Ocak","Şubat","Mart","Nisan","Mayıs","Haziran","Temmuz","Ağustos","Eylül","Ekim","Kasım","Aralık")) -> 26-30 Ekim | D16: HAYIR
A17: 8 | B17: =($B$5+(8-1)*7) -> 46328 | C17: =IF(MONTH(($B$5+(8-1)*7))=MONTH((($B$5+(8-1)*7)+4)),TEXT(DAY(($B$5+(8-1)*7)),"00")&"-"&TEXT(DAY((($B$5+(8-1)*7)+4)),"00")&" "&CHOOSE(MONTH(($B$5+(8-1)*7)),"Ocak","Şubat","Mart","Nisan","Mayıs","Haziran","Temmuz","Ağustos","Eylül","Ekim","Kasım","Aralık"),TEXT(DAY(($B$5+(8-1)*7)),"00")&" "&CHOOSE(MONTH(($B$5+(8-1)*7)),"Ocak","Şubat","Mart","Nisan","Mayıs","Haziran","Temmuz","Ağustos","Eylül","Ekim","Kasım","Aralık")&" - "&TEXT(DAY((($B$5+(8-1)*7)+4)),"00")&" "&CHOOSE(MONTH((($B$5+(8-1)*7)+4)),"Ocak","Şubat","Mart","Nisan","Mayıs","Haziran","Temmuz","Ağustos","Eylül","Ekim","Kasım","Aralık")) -> 02-06 Kasım | D17: HAYIR
A18: 9 | B18: =($B$5+(9-1)*7) -> 46335 | C18: =IF(MONTH(($B$5+(9-1)*7))=MONTH((($B$5+(9-1)*7)+4)),TEXT(DAY(($B$5+(9-1)*7)),"00")&"-"&TEXT(DAY((($B$5+(9-1)*7)+4)),"00")&" "&CHOOSE(MONTH(($B$5+(9-1)*7)),"Ocak","Şubat","Mart","Nisan","Mayıs","Haziran","Temmuz","Ağustos","Eylül","Ekim","Kasım","Aralık"),TEXT(DAY(($B$5+(9-1)*7)),"00")&" "&CHOOSE(MONTH(($B$5+(9-1)*7)),"Ocak","Şubat","Mart","Nisan","Mayıs","Haziran","Temmuz","Ağustos","Eylül","Ekim","Kasım","Aralık")&" - "&TEXT(DAY((($B$5+(9-1)*7)+4)),"00")&" "&CHOOSE(MONTH((($B$5+(9-1)*7)+4)),"Ocak","Şubat","Mart","Nisan","Mayıs","Haziran","Temmuz","Ağustos","Eylül","Ekim","Kasım","Aralık")) -> 09-13 Kasım | D18: HAYIR
A19: 10 | B19: =($B$5+(10-1)*7) -> 46342 | C19: =IF(MONTH(($B$5+(10-1)*7))=MONTH((($B$5+(10-1)*7)+4)),TEXT(DAY(($B$5+(10-1)*7)),"00")&"-"&TEXT(DAY((($B$5+(10-1)*7)+4)),"00")&" "&CHOOSE(MONTH(($B$5+(10-1)*7)),"Ocak","Şubat","Mart","Nisan","Mayıs","Haziran","Temmuz","Ağustos","Eylül","Ekim","Kasım","Aralık"),TEXT(DAY(($B$5+(10-1)*7)),"00")&" "&CHOOSE(MONTH(($B$5+(10-1)*7)),"Ocak","Şubat","Mart","Nisan","Mayıs","Haziran","Temmuz","Ağustos","Eylül","Ekim","Kasım","Aralık")&" - "&TEXT(DAY((($B$5+(10-1)*7)+4)),"00")&" "&CHOOSE(MONTH((($B$5+(10-1)*7)+4)),"Ocak","Şubat","Mart","Nisan","Mayıs","Haziran","Temmuz","Ağustos","Eylül","Ekim","Kasım","Aralık")) -> 16-20 Kasım | D19: EVET | E19: 1.DÖNEM ARA TATİL
A20: 11 | B20: =($B$5+(11-1)*7) -> 46349 | C20: =IF(MONTH(($B$5+(11-1)*7))=MONTH((($B$5+(11-1)*7)+4)),TEXT(DAY(($B$5+(11-1)*7)),"00")&"-"&TEXT(DAY((($B$5+(11-1)*7)+4)),"00")&" "&CHOOSE(MONTH(($B$5+(11-1)*7)),"Ocak","Şubat","Mart","Nisan","Mayıs","Haziran","Temmuz","Ağustos","Eylül","Ekim","Kasım","Aralık"),TEXT(DAY(($B$5+(11-1)*7)),"00")&" "&CHOOSE(MONTH(($B$5+(11-1)*7)),"Ocak","Şubat","Mart","Nisan","Mayıs","Haziran","Temmuz","Ağustos","Eylül","Ekim","Kasım","Aralık")&" - "&TEXT(DAY((($B$5+(11-1)*7)+4)),"00")&" "&CHOOSE(MONTH((($B$5+(11-1)*7)+4)),"Ocak","Şubat","Mart","Nisan","Mayıs","Haziran","Temmuz","Ağustos","Eylül","Ekim","Kasım","Aralık")) -> 23-27 Kasım | D20: HAYIR
A21: 12 | B21: =($B$5+(12-1)*7) -> 46356 | C21: =IF(MONTH(($B$5+(12-1)*7))=MONTH((($B$5+(12-1)*7)+4)),TEXT(DAY(($B$5+(12-1)*7)),"00")&"-"&TEXT(DAY((($B$5+(12-1)*7)+4)),"00")&" "&CHOOSE(MONTH(($B$5+(12-1)*7)),"Ocak","Şubat","Mart","Nisan","Mayıs","Haziran","Temmuz","Ağustos","Eylül","Ekim","Kasım","Aralık"),TEXT(DAY(($B$5+(12-1)*7)),"00")&" "&CHOOSE(MONTH(($B$5+(12-1)*7)),"Ocak","Şubat","Mart","Nisan","Mayıs","Haziran","Temmuz","Ağustos","Eylül","Ekim","Kasım","Aralık")&" - "&TEXT(DAY((($B$5+(12-1)*7)+4)),"00")&" "&CHOOSE(MONTH((($B$5+(12-1)*7)+4)),"Ocak","Şubat","Mart","Nisan","Mayıs","Haziran","Temmuz","Ağustos","Eylül","Ekim","Kasım","Aralık")) -> 30 Kasım - 04 Aralık | D21: HAYIR
A22: 13 | B22: =($B$5+(13-1)*7) -> 46363 | C22: =IF(MONTH(($B$5+(13-1)*7))=MONTH((($B$5+(13-1)*7)+4)),TEXT(DAY(($B$5+(13-1)*7)),"00")&"-"&TEXT(DAY((($B$5+(13-1)*7)+4)),"00")&" "&CHOOSE(MONTH(($B$5+(13-1)*7)),"Ocak","Şubat","Mart","Nisan","Mayıs","Haziran","Temmuz","Ağustos","Eylül","Ekim","Kasım","Aralık"),TEXT(DAY(($B$5+(13-1)*7)),"00")&" "&CHOOSE(MONTH(($B$5+(13-1)*7)),"Ocak","Şubat","Mart","Nisan","Mayıs","Haziran","Temmuz","Ağustos","Eylül","Ekim","Kasım","Aralık")&" - "&TEXT(DAY((($B$5+(13-1)*7)+4)),"00")&" "&CHOOSE(MONTH((($B$5+(13-1)*7)+4)),"Ocak","Şubat","Mart","Nisan","Mayıs","Haziran","Temmuz","Ağustos","Eylül","Ekim","Kasım","Aralık")) -> 07-11 Aralık | D22: HAYIR
A23: 14 | B23: =($B$5+(14-1)*7) -> 46370 | C23: =IF(MONTH(($B$5+(14-1)*7))=MONTH((($B$5+(14-1)*7)+4)),TEXT(DAY(($B$5+(14-1)*7)),"00")&"-"&TEXT(DAY((($B$5+(14-1)*7)+4)),"00")&" "&CHOOSE(MONTH(($B$5+(14-1)*7)),"Ocak","Şubat","Mart","Nisan","Mayıs","Haziran","Temmuz","Ağustos","Eylül","Ekim","Kasım","Aralık"),TEXT(DAY(($B$5+(14-1)*7)),"00")&" "&CHOOSE(MONTH(($B$5+(14-1)*7)),"Ocak","Şubat","Mart","Nisan","Mayıs","Haziran","Temmuz","Ağustos","Eylül","Ekim","Kasım","Aralık")&" - "&TEXT(DAY((($B$5+(14-1)*7)+4)),"00")&" "&CHOOSE(MONTH((($B$5+(14-1)*7)+4)),"Ocak","Şubat","Mart","Nisan","Mayıs","Haziran","Temmuz","Ağustos","Eylül","Ekim","Kasım","Aralık")) -> 14-18 Aralık | D23: HAYIR
A24: 15 | B24: =($B$5+(15-1)*7) -> 46377 | C24: =IF(MONTH(($B$5+(15-1)*7))=MONTH((($B$5+(15-1)*7)+4)),TEXT(DAY(($B$5+(15-1)*7)),"00")&"-"&TEXT(DAY((($B$5+(15-1)*7)+4)),"00")&" "&CHOOSE(MONTH(($B$5+(15-1)*7)),"Ocak","Şubat","Mart","Nisan","Mayıs","Haziran","Temmuz","Ağustos","Eylül","Ekim","Kasım","Aralık"),TEXT(DAY(($B$5+(15-1)*7)),"00")&" "&CHOOSE(MONTH(($B$5+(15-1)*7)),"Ocak","Şubat","Mart","Nisan","Mayıs","Haziran","Temmuz","Ağustos","Eylül","Ekim","Kasım","Aralık")&" - "&TEXT(DAY((($B$5+(15-1)*7)+4)),"00")&" "&CHOOSE(MONTH((($B$5+(15-1)*7)+4)),"Ocak","Şubat","Mart","Nisan","Mayıs","Haziran","Temmuz","Ağustos","Eylül","Ekim","Kasım","Aralık")) -> 21-25 Aralık | D24: HAYIR
A25: 16 | B25: =($B$5+(16-1)*7) -> 46384 | C25: =IF(MONTH(($B$5+(16-1)*7))=MONTH((($B$5+(16-1)*7)+4)),TEXT(DAY(($B$5+(16-1)*7)),"00")&"-"&TEXT(DAY((($B$5+(16-1)*7)+4)),"00")&" "&CHOOSE(MONTH(($B$5+(16-1)*7)),"Ocak","Şubat","Mart","Nisan","Mayıs","Haziran","Temmuz","Ağustos","Eylül","Ekim","Kasım","Aralık"),TEXT(DAY(($B$5+(16-1)*7)),"00")&" "&CHOOSE(MONTH(($B$5+(16-1)*7)),"Ocak","Şubat","Mart","Nisan","Mayıs","Haziran","Temmuz","Ağustos","Eylül","Ekim","Kasım","Aralık")&" - "&TEXT(DAY((($B$5+(16-1)*7)+4)),"00")&" "&CHOOSE(MONTH((($B$5+(16-1)*7)+4)),"Ocak","Şubat","Mart","Nisan","Mayıs","Haziran","Temmuz","Ağustos","Eylül","Ekim","Kasım","Aralık")) -> 28 Aralık - 01 Ocak | D25: HAYIR
A26: 17 | B26: =($B$5+(17-1)*7) -> 46391 | C26: =IF(MONTH(($B$5+(17-1)*7))=MONTH((($B$5+(17-1)*7)+4)),TEXT(DAY(($B$5+(17-1)*7)),"00")&"-"&TEXT(DAY((($B$5+(17-1)*7)+4)),"00")&" "&CHOOSE(MONTH(($B$5+(17-1)*7)),"Ocak","Şubat","Mart","Nisan","Mayıs","Haziran","Temmuz","Ağustos","Eylül","Ekim","Kasım","Aralık"),TEXT(DAY(($B$5+(17-1)*7)),"00")&" "&CHOOSE(MONTH(($B$5+(17-1)*7)),"Ocak","Şubat","Mart","Nisan","Mayıs","Haziran","Temmuz","Ağustos","Eylül","Ekim","Kasım","Aralık")&" - "&TEXT(DAY((($B$5+(17-1)*7)+4)),"00")&" "&CHOOSE(MONTH((($B$5+(17-1)*7)+4)),"Ocak","Şubat","Mart","Nisan","Mayıs","Haziran","Temmuz","Ağustos","Eylül","Ekim","Kasım","Aralık")) -> 04-08 Ocak | D26: HAYIR
A27: 18 | B27: =($B$5+(18-1)*7) -> 46398 | C27: =IF(MONTH(($B$5+(18-1)*7))=MONTH((($B$5+(18-1)*7)+4)),TEXT(DAY(($B$5+(18-1)*7)),"00")&"-"&TEXT(DAY((($B$5+(18-1)*7)+4)),"00")&" "&CHOOSE(MONTH(($B$5+(18-1)*7)),"Ocak","Şubat","Mart","Nisan","Mayıs","Haziran","Temmuz","Ağustos","Eylül","Ekim","Kasım","Aralık"),TEXT(DAY(($B$5+(18-1)*7)),"00")&" "&CHOOSE(MONTH(($B$5+(18-1)*7)),"Ocak","Şubat","Mart","Nisan","Mayıs","Haziran","Temmuz","Ağustos","Eylül","Ekim","Kasım","Aralık")&" - "&TEXT(DAY((($B$5+(18-1)*7)+4)),"00")&" "&CHOOSE(MONTH((($B$5+(18-1)*7)+4)),"Ocak","Şubat","Mart","Nisan","Mayıs","Haziran","Temmuz","Ağustos","Eylül","Ekim","Kasım","Aralık")) -> 11-15 Ocak | D27: HAYIR
A28: 19 | B28: =($B$5+(19-1)*7) -> 46405 | C28: =IF(MONTH(($B$5+(19-1)*7))=MONTH((($B$5+(19-1)*7)+4)),TEXT(DAY(($B$5+(19-1)*7)),"00")&"-"&TEXT(DAY((($B$5+(19-1)*7)+4)),"00")&" "&CHOOSE(MONTH(($B$5+(19-1)*7)),"Ocak","Şubat","Mart","Nisan","Mayıs","Haziran","Temmuz","Ağustos","Eylül","Ekim","Kasım","Aralık"),TEXT(DAY(($B$5+(19-1)*7)),"00")&" "&CHOOSE(MONTH(($B$5+(19-1)*7)),"Ocak","Şubat","Mart","Nisan","Mayıs","Haziran","Temmuz","Ağustos","Eylül","Ekim","Kasım","Aralık")&" - "&TEXT(DAY((($B$5+(19-1)*7)+4)),"00")&" "&CHOOSE(MONTH((($B$5+(19-1)*7)+4)),"Ocak","Şubat","Mart","Nisan","Mayıs","Haziran","Temmuz","Ağustos","Eylül","Ekim","Kasım","Aralık")) -> 18-22 Ocak | D28: HAYIR
A29: 20 | B29: =($B$5+(20-1)*7) -> 46412 | C29: =IF(MONTH(($B$5+(20-1)*7))=MONTH((($B$5+(20-1)*7)+4)),TEXT(DAY(($B$5+(20-1)*7)),"00")&"-"&TEXT(DAY((($B$5+(20-1)*7)+4)),"00")&" "&CHOOSE(MONTH(($B$5+(20-1)*7)),"Ocak","Şubat","Mart","Nisan","Mayıs","Haziran","Temmuz","Ağustos","Eylül","Ekim","Kasım","Aralık"),TEXT(DAY(($B$5+(20-1)*7)),"00")&" "&CHOOSE(MONTH(($B$5+(20-1)*7)),"Ocak","Şubat","Mart","Nisan","Mayıs","Haziran","Temmuz","Ağustos","Eylül","Ekim","Kasım","Aralık")&" - "&TEXT(DAY((($B$5+(20-1)*7)+4)),"00")&" "&CHOOSE(MONTH((($B$5+(20-1)*7)+4)),"Ocak","Şubat","Mart","Nisan","Mayıs","Haziran","Temmuz","Ağustos","Eylül","Ekim","Kasım","Aralık")) -> 25-29 Ocak | D29: EVET | E29: YARI YIL TATİLİ
A30: 21 | B30: =($B$5+(21-1)*7+7) -> 46426 | C30: =IF(MONTH(($B$5+(21-1)*7+7))=MONTH((($B$5+(21-1)*7+7)+4)),TEXT(DAY(($B$5+(21-1)*7+7)),"00")&"-"&TEXT(DAY((($B$5+(21-1)*7+7)+4)),"00")&" "&CHOOSE(MONTH(($B$5+(21-1)*7+7)),"Ocak","Şubat","Mart","Nisan","Mayıs","Haziran","Temmuz","Ağustos","Eylül","Ekim","Kasım","Aralık"),TEXT(DAY(($B$5+(21-1)*7+7)),"00")&" "&CHOOSE(MONTH(($B$5+(21-1)*7+7)),"Ocak","Şubat","Mart","Nisan","Mayıs","Haziran","Temmuz","Ağustos","Eylül","Ekim","Kasım","Aralık")&" - "&TEXT(DAY((($B$5+(21-1)*7+7)+4)),"00")&" "&CHOOSE(MONTH((($B$5+(21-1)*7+7)+4)),"Ocak","Şubat","Mart","Nisan","Mayıs","Haziran","Temmuz","Ağustos","Eylül","Ekim","Kasım","Aralık")) -> 08-12 Şubat | D30: HAYIR
A31: 22 | B31: =($B$5+(22-1)*7+7) -> 46433 | C31: =IF(MONTH(($B$5+(22-1)*7+7))=MONTH((($B$5+(22-1)*7+7)+4)),TEXT(DAY(($B$5+(22-1)*7+7)),"00")&"-"&TEXT(DAY((($B$5+(22-1)*7+7)+4)),"00")&" "&CHOOSE(MONTH(($B$5+(22-1)*7+7)),"Ocak","Şubat","Mart","Nisan","Mayıs","Haziran","Temmuz","Ağustos","Eylül","Ekim","Kasım","Aralık"),TEXT(DAY(($B$5+(22-1)*7+7)),"00")&" "&CHOOSE(MONTH(($B$5+(22-1)*7+7)),"Ocak","Şubat","Mart","Nisan","Mayıs","Haziran","Temmuz","Ağustos","Eylül","Ekim","Kasım","Aralık")&" - "&TEXT(DAY((($B$5+(22-1)*7+7)+4)),"00")&" "&CHOOSE(MONTH((($B$5+(22-1)*7+7)+4)),"Ocak","Şubat","Mart","Nisan","Mayıs","Haziran","Temmuz","Ağustos","Eylül","Ekim","Kasım","Aralık")) -> 15-19 Şubat | D31: HAYIR
A32: 23 | B32: =($B$5+(23-1)*7+7) -> 46440 | C32: =IF(MONTH(($B$5+(23-1)*7+7))=MONTH((($B$5+(23-1)*7+7)+4)),TEXT(DAY(($B$5+(23-1)*7+7)),"00")&"-"&TEXT(DAY((($B$5+(23-1)*7+7)+4)),"00")&" "&CHOOSE(MONTH(($B$5+(23-1)*7+7)),"Ocak","Şubat","Mart","Nisan","Mayıs","Haziran","Temmuz","Ağustos","Eylül","Ekim","Kasım","Aralık"),TEXT(DAY(($B$5+(23-1)*7+7)),"00")&" "&CHOOSE(MONTH(($B$5+(23-1)*7+7)),"Ocak","Şubat","Mart","Nisan","Mayıs","Haziran","Temmuz","Ağustos","Eylül","Ekim","Kasım","Aralık")&" - "&TEXT(DAY((($B$5+(23-1)*7+7)+4)),"00")&" "&CHOOSE(MONTH((($B$5+(23-1)*7+7)+4)),"Ocak","Şubat","Mart","Nisan","Mayıs","Haziran","Temmuz","Ağustos","Eylül","Ekim","Kasım","Aralık")) -> 22-26 Şubat | D32: HAYIR
A33: 24 | B33: =($B$5+(24-1)*7+7) -> 46447 | C33: =IF(MONTH(($B$5+(24-1)*7+7))=MONTH((($B$5+(24-1)*7+7)+4)),TEXT(DAY(($B$5+(24-1)*7+7)),"00")&"-"&TEXT(DAY((($B$5+(24-1)*7+7)+4)),"00")&" "&CHOOSE(MONTH(($B$5+(24-1)*7+7)),"Ocak","Şubat","Mart","Nisan","Mayıs","Haziran","Temmuz","Ağustos","Eylül","Ekim","Kasım","Aralık"),TEXT(DAY(($B$5+(24-1)*7+7)),"00")&" "&CHOOSE(MONTH(($B$5+(24-1)*7+7)),"Ocak","Şubat","Mart","Nisan","Mayıs","Haziran","Temmuz","Ağustos","Eylül","Ekim","Kasım","Aralık")&" - "&TEXT(DAY((($B$5+(24-1)*7+7)+4)),"00")&" "&CHOOSE(MONTH((($B$5+(24-1)*7+7)+4)),"Ocak","Şubat","Mart","Nisan","Mayıs","Haziran","Temmuz","Ağustos","Eylül","Ekim","Kasım","Aralık")) -> 01-05 Mart | D33: HAYIR
A34: 25 | B34: =($B$5+(25-1)*7+7) -> 46454 | C34: =IF(MONTH(($B$5+(25-1)*7+7))=MONTH((($B$5+(25-1)*7+7)+4)),TEXT(DAY(($B$5+(25-1)*7+7)),"00")&"-"&TEXT(DAY((($B$5+(25-1)*7+7)+4)),"00")&" "&CHOOSE(MONTH(($B$5+(25-1)*7+7)),"Ocak","Şubat","Mart","Nisan","Mayıs","Haziran","Temmuz","Ağustos","Eylül","Ekim","Kasım","Aralık"),TEXT(DAY(($B$5+(25-1)*7+7)),"00")&" "&CHOOSE(MONTH(($B$5+(25-1)*7+7)),"Ocak","Şubat","Mart","Nisan","Mayıs","Haziran","Temmuz","Ağustos","Eylül","Ekim","Kasım","Aralık")&" - "&TEXT(DAY((($B$5+(25-1)*7+7)+4)),"00")&" "&CHOOSE(MONTH((($B$5+(25-1)*7+7)+4)),"Ocak","Şubat","Mart","Nisan","Mayıs","Haziran","Temmuz","Ağustos","Eylül","Ekim","Kasım","Aralık")) -> 08-12 Mart | D34: EVET | E34: 2. DÖNEM ARA TATİL
A35: 26 | B35: =($B$5+(26-1)*7+7) -> 46461 | C35: =IF(MONTH(($B$5+(26-1)*7+7))=MONTH((($B$5+(26-1)*7+7)+4)),TEXT(DAY(($B$5+(26-1)*7+7)),"00")&"-"&TEXT(DAY((($B$5+(26-1)*7+7)+4)),"00")&" "&CHOOSE(MONTH(($B$5+(26-1)*7+7)),"Ocak","Şubat","Mart","Nisan","Mayıs","Haziran","Temmuz","Ağustos","Eylül","Ekim","Kasım","Aralık"),TEXT(DAY(($B$5+(26-1)*7+7)),"00")&" "&CHOOSE(MONTH(($B$5+(26-1)*7+7)),"Ocak","Şubat","Mart","Nisan","Mayıs","Haziran","Temmuz","Ağustos","Eylül","Ekim","Kasım","Aralık")&" - "&TEXT(DAY((($B$5+(26-1)*7+7)+4)),"00")&" "&CHOOSE(MONTH((($B$5+(26-1)*7+7)+4)),"Ocak","Şubat","Mart","Nisan","Mayıs","Haziran","Temmuz","Ağustos","Eylül","Ekim","Kasım","Aralık")) -> 15-19 Mart | D35: HAYIR
A36: 27 | B36: =($B$5+(27-1)*7+7) -> 46468 | C36: =IF(MONTH(($B$5+(27-1)*7+7))=MONTH((($B$5+(27-1)*7+7)+4)),TEXT(DAY(($B$5+(27-1)*7+7)),"00")&"-"&TEXT(DAY((($B$5+(27-1)*7+7)+4)),"00")&" "&CHOOSE(MONTH(($B$5+(27-1)*7+7)),"Ocak","Şubat","Mart","Nisan","Mayıs","Haziran","Temmuz","Ağustos","Eylül","Ekim","Kasım","Aralık"),TEXT(DAY(($B$5+(27-1)*7+7)),"00")&" "&CHOOSE(MONTH(($B$5+(27-1)*7+7)),"Ocak","Şubat","Mart","Nisan","Mayıs","Haziran","Temmuz","Ağustos","Eylül","Ekim","Kasım","Aralık")&" - "&TEXT(DAY((($B$5+(27-1)*7+7)+4)),"00")&" "&CHOOSE(MONTH((($B$5+(27-1)*7+7)+4)),"Ocak","Şubat","Mart","Nisan","Mayıs","Haziran","Temmuz","Ağustos","Eylül","Ekim","Kasım","Aralık")) -> 22-26 Mart | D36: HAYIR
A37: 28 | B37: =($B$5+(28-1)*7+7) -> 46475 | C37: =IF(MONTH(($B$5+(28-1)*7+7))=MONTH((($B$5+(28-1)*7+7)+4)),TEXT(DAY(($B$5+(28-1)*7+7)),"00")&"-"&TEXT(DAY((($B$5+(28-1)*7+7)+4)),"00")&" "&CHOOSE(MONTH(($B$5+(28-1)*7+7)),"Ocak","Şubat","Mart","Nisan","Mayıs","Haziran","Temmuz","Ağustos","Eylül","Ekim","Kasım","Aralık"),TEXT(DAY(($B$5+(28-1)*7+7)),"00")&" "&CHOOSE(MONTH(($B$5+(28-1)*7+7)),"Ocak","Şubat","Mart","Nisan","Mayıs","Haziran","Temmuz","Ağustos","Eylül","Ekim","Kasım","Aralık")&" - "&TEXT(DAY((($B$5+(28-1)*7+7)+4)),"00")&" "&CHOOSE(MONTH((($B$5+(28-1)*7+7)+4)),"Ocak","Şubat","Mart","Nisan","Mayıs","Haziran","Temmuz","Ağustos","Eylül","Ekim","Kasım","Aralık")) -> 29 Mart - 02 Nisan | D37: HAYIR
A38: 29 | B38: =($B$5+(29-1)*7+7) -> 46482 | C38: =IF(MONTH(($B$5+(29-1)*7+7))=MONTH((($B$5+(29-1)*7+7)+4)),TEXT(DAY(($B$5+(29-1)*7+7)),"00")&"-"&TEXT(DAY((($B$5+(29-1)*7+7)+4)),"00")&" "&CHOOSE(MONTH(($B$5+(29-1)*7+7)),"Ocak","Şubat","Mart","Nisan","Mayıs","Haziran","Temmuz","Ağustos","Eylül","Ekim","Kasım","Aralık"),TEXT(DAY(($B$5+(29-1)*7+7)),"00")&" "&CHOOSE(MONTH(($B$5+(29-1)*7+7)),"Ocak","Şubat","Mart","Nisan","Mayıs","Haziran","Temmuz","Ağustos","Eylül","Ekim","Kasım","Aralık")&" - "&TEXT(DAY((($B$5+(29-1)*7+7)+4)),"00")&" "&CHOOSE(MONTH((($B$5+(29-1)*7+7)+4)),"Ocak","Şubat","Mart","Nisan","Mayıs","Haziran","Temmuz","Ağustos","Eylül","Ekim","Kasım","Aralık")) -> 05-09 Nisan | D38: HAYIR
A39: 30 | B39: =($B$5+(30-1)*7+7) -> 46489 | C39: =IF(MONTH(($B$5+(30-1)*7+7))=MONTH((($B$5+(30-1)*7+7)+4)),TEXT(DAY(($B$5+(30-1)*7+7)),"00")&"-"&TEXT(DAY((($B$5+(30-1)*7+7)+4)),"00")&" "&CHOOSE(MONTH(($B$5+(30-1)*7+7)),"Ocak","Şubat","Mart","Nisan","Mayıs","Haziran","Temmuz","Ağustos","Eylül","Ekim","Kasım","Aralık"),TEXT(DAY(($B$5+(30-1)*7+7)),"00")&" "&CHOOSE(MONTH(($B$5+(30-1)*7+7)),"Ocak","Şubat","Mart","Nisan","Mayıs","Haziran","Temmuz","Ağustos","Eylül","Ekim","Kasım","Aralık")&" - "&TEXT(DAY((($B$5+(30-1)*7+7)+4)),"00")&" "&CHOOSE(MONTH((($B$5+(30-1)*7+7)+4)),"Ocak","Şubat","Mart","Nisan","Mayıs","Haziran","Temmuz","Ağustos","Eylül","Ekim","Kasım","Aralık")) -> 12-16 Nisan | D39: HAYIR
A40: 31 | B40: =($B$5+(31-1)*7+7) -> 46496 | C40: =IF(MONTH(($B$5+(31-1)*7+7))=MONTH((($B$5+(31-1)*7+7)+4)),TEXT(DAY(($B$5+(31-1)*7+7)),"00")&"-"&TEXT(DAY((($B$5+(31-1)*7+7)+4)),"00")&" "&CHOOSE(MONTH(($B$5+(31-1)*7+7)),"Ocak","Şubat","Mart","Nisan","Mayıs","Haziran","Temmuz","Ağustos","Eylül","Ekim","Kasım","Aralık"),TEXT(DAY(($B$5+(31-1)*7+7)),"00")&" "&CHOOSE(MONTH(($B$5+(31-1)*7+7)),"Ocak","Şubat","Mart","Nisan","Mayıs","Haziran","Temmuz","Ağustos","Eylül","Ekim","Kasım","Aralık")&" - "&TEXT(DAY((($B$5+(31-1)*7+7)+4)),"00")&" "&CHOOSE(MONTH((($B$5+(31-1)*7+7)+4)),"Ocak","Şubat","Mart","Nisan","Mayıs","Haziran","Temmuz","Ağustos","Eylül","Ekim","Kasım","Aralık")) -> 19-23 Nisan | D40: HAYIR
A41: 32 | B41: =($B$5+(32-1)*7+7) -> 46503 | C41: =IF(MONTH(($B$5+(32-1)*7+7))=MONTH((($B$5+(32-1)*7+7)+4)),TEXT(DAY(($B$5+(32-1)*7+7)),"00")&"-"&TEXT(DAY((($B$5+(32-1)*7+7)+4)),"00")&" "&CHOOSE(MONTH(($B$5+(32-1)*7+7)),"Ocak","Şubat","Mart","Nisan","Mayıs","Haziran","Temmuz","Ağustos","Eylül","Ekim","Kasım","Aralık"),TEXT(DAY(($B$5+(32-1)*7+7)),"00")&" "&CHOOSE(MONTH(($B$5+(32-1)*7+7)),"Ocak","Şubat","Mart","Nisan","Mayıs","Haziran","Temmuz","Ağustos","Eylül","Ekim","Kasım","Aralık")&" - "&TEXT(DAY((($B$5+(32-1)*7+7)+4)),"00")&" "&CHOOSE(MONTH((($B$5+(32-1)*7+7)+4)),"Ocak","Şubat","Mart","Nisan","Mayıs","Haziran","Temmuz","Ağustos","Eylül","Ekim","Kasım","Aralık")) -> 26-30 Nisan | D41: HAYIR
A42: 33 | B42: =($B$5+(33-1)*7+7) -> 46510 | C42: =IF(MONTH(($B$5+(33-1)*7+7))=MONTH((($B$5+(33-1)*7+7)+4)),TEXT(DAY(($B$5+(33-1)*7+7)),"00")&"-"&TEXT(DAY((($B$5+(33-1)*7+7)+4)),"00")&" "&CHOOSE(MONTH(($B$5+(33-1)*7+7)),"Ocak","Şubat","Mart","Nisan","Mayıs","Haziran","Temmuz","Ağustos","Eylül","Ekim","Kasım","Aralık"),TEXT(DAY(($B$5+(33-1)*7+7)),"00")&" "&CHOOSE(MONTH(($B$5+(33-1)*7+7)),"Ocak","Şubat","Mart","Nisan","Mayıs","Haziran","Temmuz","Ağustos","Eylül","Ekim","Kasım","Aralık")&" - "&TEXT(DAY((($B$5+(33-1)*7+7)+4)),"00")&" "&CHOOSE(MONTH((($B$5+(33-1)*7+7)+4)),"Ocak","Şubat","Mart","Nisan","Mayıs","Haziran","Temmuz","Ağustos","Eylül","Ekim","Kasım","Aralık")) -> 03-07 Mayıs | D42: HAYIR
...

Sheet TEMEL İMALAT İŞLEM 9A
C1: GÜNLÜK DERS PLANI
A3: DERS | B3: TEMEL İMALAT İŞLEMLERİ | F3: ALAN/DAL | G3: Makine ve Tasarım Teknolojisi Alanı
A4: SINIF | B4: AMP 9A | F4: DERS SAATİ | G4: 6 SAAT
A5: ÖĞRETMEN | B5: Ali Osman KOÇ | F5: DERS GÜNÜ SEÇ | G5: Cuma
A7: TARİH | B7: KONU | C7: KAZANIM | D7: GİRİŞ | E7: GELİŞME | F7: SONUÇ | G7: YÖNTEM VE TEKNİKLER | H7: ARAÇ VE GEREÇLER | I7: ÖLÇME-DEĞERLENDİRME
A8: =TAKVİM!$B$10+(MATCH($G$5,{"Pazartesi","Salı","Çarşamba","Perşembe","Cuma"},0)-1) -> 46283 | B8: EL İŞLEMLERİ - 1. Atölyede İş Güvenliği Tedbirleri | C8: 1. Atölyede iş güvenliği tedbirlerini alır. • Atölyede uyması gereken kurallar açıklanır. • Tezgâhlardan meydana gelebilecek iş kazaları açıklanır. • Çalışma sırasında meydana gelebilecek iş kazalarına karşı tedbirleri açıklanır. • İş güvenliği ve emniyet kuralları açıklanır. | D8: Öğretim yılının ilk dersi olduğu için önceki bir konu tekrarı yapılmaz; bunun yerine öğrencilerle kısa bir tanışma yapılır ve atölyeye ilk kez giren öğrencilerin dikkati, atölyedeki tezgâh ve makinelerin taşıdığı riskler üzerine çekilir. | E8: Öğrenciler atölyede gezdirilerek her tezgâh/bölüm tek tek tanıtılır; iş güvenliği uyarı levhaları ve tehlikeli bölgeler (hareketli aksam, elektrik panosu) gösterilir. Öğrencilere kişisel koruyucu donanım (gözlük, eldiven, iş önlüğü) dağıtılarak doğru kullanımı uygulamalı gösterilir. | F8: Öğrencilerden atölye kurallarını kendi cümleleriyle özetlemeleri istenir; kısa bir sözlü doğru-yanlış değerlendirmesiyle pekiştirme yapılır ve gelecek hafta atölye temizlik-düzeni ile KKD konusunun devam edeceği belirtilir. | G8: Gösteri, Soru-Cevap, Programlı Öğretim, Bireyselleştirilmiş Öğretim, Temrin Çalışmaları | H8: Temel İmalat Atölyesi, torna tezgahları, freze tezgahları, matkap tezgahları, kesici takımlar, akıllı tahta
A9: =TAKVİM!$B$11+(MATCH($G$5,{"Pazartesi","Salı","Çarşamba","Perşembe","Cuma"},0)-1) -> 46290 | B9: 1. Atölyede İş Güvenliği Tedbirleri | C9: 1. Atölyede iş güvenliği tedbirlerini alır. • Atölye temizlik ve düzeni açıklanır. • Yapılan işe uygun iş elbiseleri ve kişisel koruyucu donanımları hazırlatılır. • Yanıcı ve parlayıcı malzemelerin güvenli bir şekilde tutulması sağlanır. | D9: Geçen hafta işlenen genel iş güvenliği kuralları 2-3 soruyla kısaca hatırlatılır; bu hafta atölye temizliği, düzeni ve kişisel koruyucu donanımların ayrıntılarına odaklanılacağı söylenir. | E9: Atölyedeki yağ, talaş ve yanıcı-parlayıcı malzeme depolama alanları gösterilir; düzenli çalışma alanı oluşturma prensibi anlatılır. Öğrencilere iş elbisesi ve KKD giydirme uygulaması yaptırılır, yangın söndürme tüpünün yeri ve acil çıkış gösterilir. | F9: Öğrencilerden kendi tezgâh çevrelerini düzenlemeleri istenir, gözlemle kısa geri bildirim verilir. | G9: Gösteri, Soru-Cevap, Programlı Öğretim, Bireyselleştirilmiş Öğretim, Temrin Çalışmaları | H9: Temel İmalat Atölyesi, torna tezgahları, freze tezgahları, matkap tezgahları, kesici takımlar, akıllı tahta
A10: =TAKVİM!$B$12+(MATCH($G$5,{"Pazartesi","Salı","Çarşamba","Perşembe","Cuma"},0)-1) -> 46297 | B10: 2. Düzlem Yüzey Eğeleme | C10: 2. Verilen resme uygun olarak düzlem yüzey eğeleme yapar. • Eğe çeşitleri sıralanır. • İşi parçasını bağlama yöntemleri açıklanır. • Düzlem yüzey kontrol aletleri sıralanır. • Öğrencilerin doğru pozisyonda olmaları sağlanır. | D10: Eğeleme sırasında da güvenlik kurallarının geçerli olduğu (örn. dönen parça yokken eldiven takılabileceği) hatırlatılır; sınıfa düz, yarım yuvarlak, üçgen ve yassı eğe örnekleri getirilerek tanıtılır. | E10: Öğretmen önce mengeneye iş parçası bağlama işlemini, ardından doğru duruş ve eğe tutuşunu (iki elle, vücut açısıyla) gösterir; mihengir ile düzlem kontrolü örneklenir. Her öğrenci sırayla kendi iş parçasını mengeneye bağlar. | F10: Bir öğrencinin bağlama ve duruşu sınıfa örnek olarak gösterilir, görülen hatalar birlikte düzeltilir. | G10: Gösteri, Soru-Cevap, Programlı Öğretim, Bireyselleştirilmiş Öğretim, Temrin Çalışmaları | H10: Temel İmalat Atölyesi, torna tezgahları, freze tezgahları, matkap tezgahları, kesici takımlar, akıllı tahta
A11: =TAKVİM!$B$13+(MATCH($G$5,{"Pazartesi","Salı","Çarşamba","Perşembe","Cuma"},0)-1) -> 46304 | B11: 2. Düzlem Yüzey Eğeleme | C11: 2. Verilen resme uygun olarak düzlem yüzey eğeleme yapar. • Eğe çeşitleri sıralanır. • İşi parçasını bağlama yöntemleri açıklanır. • Düzlem yüzey kontrol aletleri sıralanır. • Öğrencilerin doğru pozisyonda olmaları sağlanır. | D11: Geçen hafta öğrenilen doğru duruş ve bağlama tekniği kısaca hatırlatılır; bu hafta gerçek parça üzerinde eğeleme uygulamasına geçileceği söylenir. | E11: Her öğrenciye standart bir çelik parça dağıtılır; düzlem yüzey eğeleme uygulaması öğretmen gözetiminde tek tek yaptırılır, mihengir ile ara kontroller yapılır, yanlış eğe açısı anında düzeltilir. | F11: Tamamlanan parçalar mihengirle kontrol edilip düzlük derecesine göre kısa sözlü geri bildirim verilir. | G11: Gösteri, Soru-Cevap, Programlı Öğretim, Bireyselleştirilmiş Öğretim, Temrin Çalışmaları | H11: Temel İmalat Atölyesi, torna tezgahları, freze tezgahları, matkap tezgahları, kesici takımlar, akıllı tahta
A12: =TAKVİM!$B$14+(MATCH($G$5,{"Pazartesi","Salı","Çarşamba","Perşembe","Cuma"},0)-1) -> 46311 | B12: 3. Markalama Yapma | C12: 3. Markalama ekipmanları ile verilen resme uygun olarak iş parçasını markalar. • Markalamanın amacı üzerinde durulur. • Markalama yöntemleri üzerinde durulur. | D12: Eğelemeden önce parça üzerine sınırların nasıl işaretleneceği sorulur; markalama kalemi, pergel, gönye ve nokta vurma çekici sınıfa getirilerek tanıtılır. | E12: Markalama boyası sürme, çizim aletleriyle imalat resmine göre çizgi çekme, pergelle daire/yay çizme ve nokta vurma çekiciyle işaretleri sabitleme adım adım gösterilir; öğrenciler kendi parçalarında markalama uygulaması yapar. | F12: Markalanan parçalar örnek resimle karşılaştırılır, ölçü sapmaları varsa birlikte incelenir. | G12: Gösteri, Soru-Cevap, Programlı Öğretim, Bireyselleştirilmiş Öğretim, Temrin Çalışmaları | H12: Temel İmalat Atölyesi, torna tezgahları, freze tezgahları, matkap tezgahları, kesici takımlar, akıllı tahta
A13: =TAKVİM!$B$15+(MATCH($G$5,{"Pazartesi","Salı","Çarşamba","Perşembe","Cuma"},0)-1) -> 46318 | B13: 4. Profil Yüzey Eğeleme | C13: 4. Verilen resme uygun olarak profil yüzey eğeleme işlemleri yapar. • Profil yüzey eğeleme yöntemlerini açıklanır. • Yüzey kontrol aletleri tanımlanır. • İç ve dış yüzey eğeleme yaptırılır. • Delik ve kanal eğeleme yaptırılır. • Eğe ile pah kırma işlemi yaptırılır. | D13: Geçen haftaki markalama çizgilerinin bu hafta profil eğeleme sınırlarını belirlediği hatırlatılır; profil kontrolünde kullanılacak radyus ve açı mastarları gösterilir. | E13: İç ve dış profil yüzeylerin eğelenmesi, delik/kanal içi eğeleme ve pah kırma teknikleri sırasıyla gösterilir; öğrenciler markaladıkları parça üzerinde profil eğeleme uygulaması yapar. | F13: Profil mastarıyla kontrol edilip uygunluk değerlendirilir; eksik kalan öğrencilere gelecek hafta tamamlama süresi verileceği söylenir. | G13: Gösteri, Soru-Cevap, Programlı Öğretim, Bireyselleştirilmiş Öğretim, Temrin Çalışmaları | H13: Temel İmalat Atölyesi, torna tezgahları, freze tezgahları, matkap tezgahları, kesici takımlar, akıllı tahta
A14: =TAKVİM!$B$16+(MATCH($G$5,{"Pazartesi","Salı","Çarşamba","Perşembe","Cuma"},0)-1) -> 46325 | B14: 4. Profil Yüzey Eğeleme | C14: 4. Verilen resme uygun olarak profil yüzey eğeleme işlemleri yapar. • Profil yüzey eğeleme yöntemlerini açıklanır. • Yüzey kontrol aletleri tanımlanır. • İç ve dış yüzey eğeleme yaptırılır. • Delik ve kanal eğeleme yaptırılır. • Eğe ile pah kırma işlemi yaptırılır. 29 EKİM Cumhuriyet Bayramı | D14: 29 Ekim Cumhuriyet Bayramı nedeniyle kısa bir haftaya girildiği hatırlatılır; geçen haftaki profil eğeleme uygulamasına kaldığı yerden devam edileceği belirtilir. | E14: Yarım kalan profil eğeleme parçaları öğrencilere tamamlattırılır; hatalı yüzeyler için ince eğe ile son pas verme tekniği gösterilir. | F14: Tamamlanan parçalar teslim alınıp genel bir değerlendirme yapılır. | G14: Gösteri, Soru-Cevap, Programlı Öğretim, Bireyselleştirilmiş Öğretim, Temrin Çalışmaları | H14: Temel İmalat Atölyesi, torna tezgahları, freze tezgahları, matkap tezgahları, kesici takımlar, akıllı tahta
A15: =TAKVİM!$B$17+(MATCH($G$5,{"Pazartesi","Salı","Çarşamba","Perşembe","Cuma"},0)-1) -> 46332 | B15: 5. Kesme İşlemleri Yapma | C15: 5. Verilen resme uygun olarak kesme işlemlerini yapar. • Testere ile kesmeyi tarif edilir. • Testere ile kesme yaparken kazalardan korunma açıklanır. • Keski ile kesme açıklanır. • Keski çeşitleri sıralanır. • Keski ile kesmede dikkat edilecek hususlar açıklanır. | D15: Eğelemeden önce büyük parçadan fazlalığın nasıl kesilerek uzaklaştırıldığı sorulur; el testeresi ve keski örnekleri sınıfa getirilir. | E15: El testeresiyle düz kesme, keskiyle yontma/kesme teknikleri gösterilir; kesme sırasında el ve göz güvenliği özellikle vurgulanır. Öğrenciler öğretmen gözetiminde kesme uygulaması yapar. | F15: Kesilen parçaların düzgünlüğü ölçüyle kontrol edilir. | G15: Gösteri, Soru-Cevap, Programlı Öğretim, Bireyselleştirilmiş Öğretim, Temrin Çalışmaları | H15: Temel İmalat Atölyesi, torna tezgahları, freze tezgahları, matkap tezgahları, kesici takımlar, akıllı tahta
A16: =TAKVİM!$B$18+(MATCH($G$5,{"Pazartesi","Salı","Çarşamba","Perşembe","Cuma"},0)-1) -> 46339 | B16: 5. Kesme İşlemleri Yapma | C16: 5. Verilen resme uygun olarak kesme işlemlerini yapar. • Testere lamasını testere koluna doğru olarak bağlatılır. • Güvenlik tedbirlerine dikkat ederek testere ile değişik kalınlık ve profildeki parçalar kestirilir. • Düz keski ile keskileme yaptırılır. • Kanal keskisi ile çeşitli kanallar açtırılır. • El makası ile saç kesme yaptırılır. • Kol makasları ile kesme yaptırılır. 10 KASIM Atatürk'ü Anma Günü ve Atatürk Haftası | D16: 10 Kasım Atatürk'ü Anma Günü nedeniyle kısa bir anma yapıldıktan sonra derse geçilir; geçen haftaki temel kesme tekniği hatırlatılır. | E16: Testere lamasının doğru yönde bağlanması gösterilir; yuvarlak, kare ve lama profildeki parçaların kesimi uygulanır. Ardından düz keski ve kanal keskisiyle keskileme, el makası ve kol makasıyla sac kesme teknikleri sırayla gösterilip yaptırılır. | F16: Farklı kesme yöntemleriyle elde edilen örnekler karşılaştırılarak hangi yöntemin hangi malzeme/şekil için uygun olduğu sınıfça tartışılır. | G16: Gösteri, Soru-Cevap, Programlı Öğretim, Bireyselleştirilmiş Öğretim, Temrin Çalışmaları | H16: Temel İmalat Atölyesi, torna tezgahları, freze tezgahları, matkap tezgahları, kesici takımlar, akıllı tahta
A17: =TAKVİM!$C$19 -> 16-20 Kasım | B17: 1.DÖNEM ARA TATİL
A18: =TAKVİM!$B$20+(MATCH($G$5,{"Pazartesi","Salı","Çarşamba","Perşembe","Cuma"},0)-1) -> 46353 | B18: MALZEME - 1. Malzeme Seçme | C18: 1. İşin özelliklerine göre uygun malzeme seçer. • Malzeme ve özellikleri açıklanır. • Metal ve metal alaşımlı malzemeler (Çelik, Alüminyum ve alaşımları, bakır ve alaşımları, dökme demir) üzerinde durulur. • Metal olmayan malzemeler (Plastik ve kompozit malzemeler) üzerinde durulur. | D18: Ara tatil dönüşü kısa bir 'atölye kurallarını hatırlıyor musunuz' sorusuyla derse ısınma yapılır; bu hafta yeni ünite olan malzeme bilgisine geçileceği söylenir. Sınıfa çelik, alüminyum, bakır, dökme demir ve plastik numuneler getirilir. | E18: Numuneler elden ele dolaştırılarak renk, ağırlık ve manyetiklik gibi ayırt edici özellikler gösterilir; metal ve metal olmayan malzemeler tahtada karşılaştırmalı tablo hâlinde sınıflandırılır. | F18: Öğrencilerden ellerindeki numuneyi tanımlamaları istenerek kısa bir tanıma uygulaması yapılır. | G18: Gösteri, Soru-Cevap, Programlı Öğretim, Bireyselleştirilmiş Öğretim, Temrin Çalışmaları | H18: Temel İmalat Atölyesi, torna tezgahları, freze tezgahları, matkap tezgahları, kesici takımlar, akıllı tahta
A19: =TAKVİM!$B$21+(MATCH($G$5,{"Pazartesi","Salı","Çarşamba","Perşembe","Cuma"},0)-1) -> 46360 | B19: 1. Malzeme Seçme | C19: 1. İşin özelliklerine göre uygun malzeme seçer. • İşe göre malzeme seçtirilir. • Çelik standart katalogları kullandırılır. • Çelik standartlarına göre malzeme seçtirilir. | D19: Geçen haftaki numunelerden çeliğin farklı türleri olduğu hatırlatılır; sınıfa standart çelik kataloğu getirilir. | E19: Çelik standart kataloğundan örnek okuma yapılır; verilen bir iş parçası için uygun çelik türünü kataloğdan seçme uygulaması grup çalışmasıyla yaptırılır. | F19: Gruplar seçtikleri malzemeyi gerekçeleriyle kısaca sınıfa sunar. | G19: Gösteri, Soru-Cevap, Programlı Öğretim, Bireyselleştirilmiş Öğretim, Temrin Çalışmaları | H19: Temel İmalat Atölyesi, torna tezgahları, freze tezgahları, matkap tezgahları, kesici takımlar, akıllı tahta
A20: =TAKVİM!$B$22+(MATCH($G$5,{"Pazartesi","Salı","Çarşamba","Perşembe","Cuma"},0)-1) -> 46367 | B20: 2. Malzemeyi Test Etme | C20: 2. Malzemeyi test eder. • Malzeme muayene yöntemleri açıklanır. • Sertlik ölçme tanımlanır. • Sertlik ölçme yöntemleri örneklerle açıklanır. • Malzeme muayene yöntemleri uygulanır. • Sertlik ölçme yöntemleriyle test yaptırılır. | D20: Aynı görünümdeki iki metalin sertliğinin farklı olabileceği sorusuyla dikkat çekilir; sertlik ölçümünde kullanılan araçlar (eğe testi, varsa sertlik ölçüm cihazı) tanıtılır. | E20: Malzeme muayene ve sertlik ölçme yöntemleri (eğe testi, çentik testi, cihazla ölçüm) sırayla gösterilir; farklı malzeme numuneleri üzerinde öğrencilerle birlikte test uygulaması yapılır. | F20: Elde edilen sertlik sonuçları bir tabloya işlenip birlikte yorumlanır. | G20: Gösteri, Soru-Cevap, Programlı Öğretim, Bireyselleştirilmiş Öğretim, Temrin Çalışmaları | H20: Temel İmalat Atölyesi, torna tezgahları, freze tezgahları, matkap tezgahları, kesici takımlar, akıllı tahta
A21: =TAKVİM!$B$23+(MATCH($G$5,{"Pazartesi","Salı","Çarşamba","Perşembe","Cuma"},0)-1) -> 46374 | B21: DELME VE VİDA İŞLEMLERİ - 1. Matkap Bileme | C21: 1. Bileme açılarına uygun olarak matkap ucunu biler. • Zımpara tezgâhlarının özellikleri açıklanır. • Zımpara tezgâhlarında çalışırken kullanılan koruyucu aletleri sıralanır. • Matkap bilemede dikkat edilecek kuralları açıklanır. • Zımpara taşı dayama tablasını kontrol eder ve ayar yaptırılır. • Güvenlik kurallarına dikkat ederek matkap ucunu, taşa doğru açılı tutarak biletilir. • Bilenen matkabın kontrolünü yaptırılır. • Bilemede soğutma sıvısı kullandırılır. | D21: Delik delmeden önce matkap ucunun neden keskin olması gerektiği sorulur; körelmiş ve keskin matkap uçları karşılaştırmalı olarak gösterilir. | E21: Zımpara tezgâhının güvenli kullanımı ile matkap bileme açısı ve tekniği öğretmen tarafından gösterilir; öğrenciler nezaret altında kendi matkap uçlarını biler, soğutma sıvısı kullanımı özellikle vurgulanır. | F21: Bilenen matkap uçları gözle/büyüteçle kontrol edilip simetriklik açısından değerlendirilir. | G21: Gösteri, Soru-Cevap, Programlı Öğretim, Bireyselleştirilmiş Öğretim, Temrin Çalışmaları | H21: Temel İmalat Atölyesi, torna tezgahları, freze tezgahları, matkap tezgahları, kesici takımlar, akıllı tahta
A22: =TAKVİM!$B$24+(MATCH($G$5,{"Pazartesi","Salı","Çarşamba","Perşembe","Cuma"},0)-1) -> 46381 | B22: 2. Delik Delme | C22: 2. Matkap tezgâhında verilen resme uygun olarak delik deler. • Matkap tezgâhları ve matkap çeşitleri açıklanır. • Matkap bilemede dikkat edilecek hususlar açıklanır. • Matkap tezgâhında soğutma sıvısı kullanarak çeşitli delik delme işlemleri yaptırılır. • Matkap tezgâhında havşa açtırılır. | D22: Geçen hafta bilenen matkap uçlarının bu hafta kullanılacağı hatırlatılır; matkap tezgâhının kısımları gösterilir. | E22: Matkap tezgâhında iş parçası bağlama, soğutma sıvısı kullanarak delik delme ve havşa açma işlemleri adım adım gösterilip öğrencilere uygulatılır. | F22: Delinen deliklerin ölçüsü kumpasla kontrol edilir. | G22: Gösteri, Soru-Cevap, Programlı Öğretim, Bireyselleştirilmiş Öğretim, Temrin Çalışmaları | H22: Temel İmalat Atölyesi, torna tezgahları, freze tezgahları, matkap tezgahları, kesici takımlar, akıllı tahta
A23: =TAKVİM!$B$25+(MATCH($G$5,{"Pazartesi","Salı","Çarşamba","Perşembe","Cuma"},0)-1) -> 46388 | B23: 2. Delik Delme | C23: 2. Matkap tezgâhında verilen resme uygun olarak delik deler. • Matkap tezgâhında soğutma sıvısı kullanarak çeşitli delik delme işlemleri yaptırılır. • Matkap tezgâhında havşa açtırılır. | D23: Yılın son haftası öncesinde bu döneme kadar delinen parçalar kısaca gözden geçirilir; bu hafta farklı çaplarda delik delme uygulamasına devam edileceği belirtilir. | E23: Farklı matkap çapları ile kademeli delik delme ve havşa açma uygulaması tekrarlanarak pekiştirilir. | F23: Dönem içi delik delme becerileri genel olarak değerlendirilip eksik kalan noktalar not edilir. | G23: Gösteri, Soru-Cevap, Programlı Öğretim, Bireyselleştirilmiş Öğretim, Temrin Çalışmaları | H23: Temel İmalat Atölyesi, torna tezgahları, freze tezgahları, matkap tezgahları, kesici takımlar, akıllı tahta
A24: =TAKVİM!$B$26+(MATCH($G$5,{"Pazartesi","Salı","Çarşamba","Perşembe","Cuma"},0)-1) -> 46395 | B24: 3. Rayba Çekme | C24: 3. Verilen resme uygun olarak raybalama yapar. • Rayba çeşitlerini sıralanır. • Raybalama da işlem sırasını açıklanır. • Güvenlik kurallarına dikkat ederek raybalama işlemleri yaptırır. | D24: Delinen bir deliğin bazen tam ölçüde ya da pürüzsüz olmayabileceği örneğiyle raybalamanın gerekliliği anlatılır; rayba örnekleri gösterilir. | E24: Rayba çeşitleri tanıtılır; delik ölçüsü kontrolü, yağlama ve düşük devirle çekme adımlarından oluşan raybalama işlem sırası gösterilir. Öğrenciler kendi deldikleri delikleri raybalar. | F24: Raybalanan deliklerin yüzey pürüzsüzlüğü ve ölçüsü kumpas/mastar ile kontrol edilir. | G24: Gösteri, Soru-Cevap, Programlı Öğretim, Bireyselleştirilmiş Öğretim, Temrin Çalışmaları | H24: Temel İmalat Atölyesi, torna tezgahları, freze tezgahları, matkap tezgahları, kesici takımlar, akıllı tahta
A25: =TAKVİM!$B$27+(MATCH($G$5,{"Pazartesi","Salı","Çarşamba","Perşembe","Cuma"},0)-1) -> 46402 | B25: 4. Elle Kılavuz Çekme | C25: 4. Verilen resme uygun olarak elle kılavuz çekme işlemleri yapar. • Vida çeşitleri sıralanır. • Kılavuzlar tanımlanır. • Kılavuzlar kısımlarını açıklanır. • Kılavuz çekmede dikkat edilecek hususlar açıklanır. • Öğrencilerin kılavuz kullanırken kesme yağı kullanmaları sağlanır. | D25: Bir somuna nasıl diş açıldığı sorulur; kılavuz kolu ve kılavuz seti sınıfa getirilerek tanıtılır. | E25: Kılavuzun kısımları tanıtılır; kesme yağı kullanarak dik ve düzgün kılavuz çekme tekniği gösterilir. Öğrenciler kendi deldikleri deliklere kılavuz çeker. | F25: Açılan dişler uygun bir cıvata ile denenerek kontrol edilir. | G25: Gösteri, Soru-Cevap, Programlı Öğretim, Bireyselleştirilmiş Öğretim, Temrin Çalışmaları | H25: Temel İmalat Atölyesi, torna tezgahları, freze tezgahları, matkap tezgahları, kesici takımlar, akıllı tahta
A26: =TAKVİM!$B$28+(MATCH($G$5,{"Pazartesi","Salı","Çarşamba","Perşembe","Cuma"},0)-1) -> 46409 | B26: 5. Elle Pafta Çekme | C26: 5. Verilen resme uygun olarak elle pafta çekme işlemleri yapar. • Paftayı tanımlar, pafta çeşitleri sıralanır. • Pafta çekmede işlem sırası açıklanır. • Paftayı doğru ağızlatır. • Öğrencilerin pafta kullanırken kesme yağı kullanmaları sağlanır. | D26: Kılavuzun iç diş açtığı hatırlatılarak, dış diş (cıvata dişi) açmak için paftanın kullanıldığı anlatılır; pafta seti gösterilir. | E26: Pafta çeşitleri, doğru ağızlama ve kesme yağı kullanarak pafta çekme tekniği gösterilir; öğrenciler silindirik çubuklara pafta çeker. | F26: Açılan dişler somunla denenir; 1. dönem sonu genel bir değerlendirme yapılır. | G26: Gösteri, Soru-Cevap, Programlı Öğretim, Bireyselleştirilmiş Öğretim, Temrin Çalışmaları | H26: Temel İmalat Atölyesi, torna tezgahları, freze tezgahları, matkap tezgahları, kesici takımlar, akıllı tahta
A27: =TAKVİM!$C$29 -> 25-29 Ocak | B27: YARI YIL TATİLİ
A28: =TAKVİM!$B$30+(MATCH($G$5,{"Pazartesi","Salı","Çarşamba","Perşembe","Cuma"},0)-1) -> 46430 | B28: TEMEL TORNALAMA İŞLEMLERİ - 1. Torna Tezgâhlarını Tanıma | C28: 1. Torna Tezgâhlarını tanır. • Torna tezgâhı tanımlanır. • Torna tezgâh çeşitlerini listelenir. • Torna tezgâhlarında iş güvenliği önlemleri örneklerle açıklanır. | D28: 2. dönemin ilk dersi olması nedeniyle 1. dönemde işlenen el aletleriyle imalatın kısa bir özeti yapılır; bu dönem torna tezgâhlarıyla imalatın öğrenileceği söylenir. Öğrenciler atölyedeki torna tezgâhına götürülür. | E28: Torna tezgâhının ana kısımları (ayna, punta, araba, kızak) tek tek gösterilir; tezgâh çeşitleri (üniversal, revolver) örneklerle anlatılır; bağlı kıyafet giymeme ve gözlük takma gibi iş güvenliği kuralları vurgulanır. | F28: Öğrencilerden tezgâh kısımlarını isimlendirmeleri istenerek kısa bir tanıma değerlendirmesi yapılır. | G28: Gösteri, Soru-Cevap, Programlı Öğretim, Bireyselleştirilmiş Öğretim, Temrin Çalışmaları | H28: Temel İmalat Atölyesi, torna tezgahları, freze tezgahları, matkap tezgahları, kesici takımlar, akıllı tahta
A29: =TAKVİM!$B$31+(MATCH($G$5,{"Pazartesi","Salı","Çarşamba","Perşembe","Cuma"},0)-1) -> 46437 | B29: 1. Torna Tezgâhlarını Tanıma | C29: 1. Torna Tezgâhlarını tanır. • Torna tezgâhı tanımlanır. • Torna tezgâh çeşitlerini listelenir. • Torna tezgâhlarında iş güvenliği önlemleri örneklerle açıklanır. | D29: Geçen hafta tanıtılan torna tezgâhı kısımları kısaca hatırlatılır; bu hafta tezgâhın çalıştırılmasına odaklanılacağı söylenir. | E29: Tezgâhın açılıp kapatılması, devir ayarı ve ilerleme kolu kullanımı öğretmen tarafından gösterilir; öğrenciler nezaret altında tezgâhı boşta çalıştırır. | F29: Her öğrencinin tezgâhı güvenli şekilde açıp kapatabildiği gözlemlenerek not edilir. | G29: Gösteri, Soru-Cevap, Programlı Öğretim, Bireyselleştirilmiş Öğretim, Temrin Çalışmaları | H29: Temel İmalat Atölyesi, torna tezgahları, freze tezgahları, matkap tezgahları, kesici takımlar, akıllı tahta
A30: =TAKVİM!$B$32+(MATCH($G$5,{"Pazartesi","Salı","Çarşamba","Perşembe","Cuma"},0)-1) -> 46444 | B30: 2. Kesici Takımları Hazırlamak ve Bağlama | C30: 2. Kesici takımlarını hazırlar ve bağlar. • Torna tezgâhında kullanılacak kesiciler sınıflandırılır. • Torna kesicileri malzemelerine göre sınıflandırılır. • Torna kesicilerini biçimlerine göre listeler, kaleme verilen kesme açıları açıklanır. | D30: Tornalama için 'bıçağın' (kalemin) nasıl olması gerektiği sorulur; alın, yan ve delik kalemi örnekleri sınıfa getirilir. | E30: Kalem malzemeleri (HSS, karbür uçlu) ve kesme açıları tanıtılır; kalemin kalem tutucuya punta ekseninde doğru yükseklikte bağlanması gösterilir. Öğrenciler kalem bağlama uygulaması yapar. | F30: Bağlanan kalemlerin punta eksenine göre doğru yükseklikte olup olmadığı birlikte kontrol edilir. | G30: Gösteri, Soru-Cevap, Programlı Öğretim, Bireyselleştirilmiş Öğretim, Temrin Çalışmaları | H30: Temel İmalat Atölyesi, torna tezgahları, freze tezgahları, matkap tezgahları, kesici takımlar, akıllı tahta
A31: =TAKVİM!$B$33+(MATCH($G$5,{"Pazartesi","Salı","Çarşamba","Perşembe","Cuma"},0)-1) -> 46451 | B31: 2. Kesici Takımları Hazırlamak ve Bağlama | C31: 2. Kesici takımlarını hazırlar ve bağlar. • Torna tezgâhında kullanılacak kesiciler sınıflandırılır. • Torna kesicileri malzemelerine göre sınıflandırılır. • Torna kesicilerini biçimlerine göre listeler, kaleme verilen kesme açıları açıklanır. | D31: Geçen haftaki kalem bağlama tekniği kısaca tekrarlanır; bu hafta farklı kalem tiplerinin hangi işlemde kullanılacağının üzerinde durulacağı belirtilir. | E31: Alın kalemi, yan kalem ve delik kaleminin kullanım yerleri karşılaştırmalı örneklerle gösterilir; öğrenciler farklı kalemleri sırayla bağlayıp sökme uygulaması yapar. | F31: Hangi kalemin hangi işlem için uygun olduğu sınıfça tartışılarak pekiştirilir. | G31: Gösteri, Soru-Cevap, Programlı Öğretim, Bireyselleştirilmiş Öğretim, Temrin Çalışmaları | H31: Temel İmalat Atölyesi, torna tezgahları, freze tezgahları, matkap tezgahları, kesici takımlar, akıllı tahta
A32: =TAKVİM!$C$34 -> 08-12 Mart | B32: 2. DÖNEM ARA TATİL
A33: =TAKVİM!$B$35+(MATCH($G$5,{"Pazartesi","Salı","Çarşamba","Perşembe","Cuma"},0)-1) -> 46465 | B33: 3. İş Parçalarını Bağlama | C33: 3. İş Parçalarını tezgâha bağlar. • İş parçasını tezgâha bağlama çeşitleri tarif edilir. • Bağlama araçları sınıflandırılır. • Komparatör ile iş parçasının salgı kontrolü açıklanır. • Emniyetli bağlama kuralları açıklanır. • Gerektiğinde bağlama aracı söktürülür veya taktırılır. • İş kalıplarını aynaya bağlatılır. | D33: Tatil sonrası kısa bir hatırlatmayla derse başlanır; iş parçasının torna aynasına nasıl bağlandığı sorulur, üç ayaklı ayna gösterilir. | E33: Ayna ayaklarının sıkılması ve komparatörle salgı kontrolü öğretmen tarafından gösterilir; öğrenciler kendi iş parçalarını aynaya bağlayıp salgı kontrolü yapar. | F33: Salgısı en düşük bağlanan parça örnek gösterilerek sınıfça değerlendirilir. | G33: Gösteri, Soru-Cevap, Programlı Öğretim, Bireyselleştirilmiş Öğretim, Temrin Çalışmaları | H33: Temel İmalat Atölyesi, torna tezgahları, freze tezgahları, matkap tezgahları, kesici takımlar, akıllı tahta
A34: =TAKVİM!$B$36+(MATCH($G$5,{"Pazartesi","Salı","Çarşamba","Perşembe","Cuma"},0)-1) -> 46472 | B34: 3. İş Parçalarını Bağlama | C34: 3. İş Parçalarını tezgâha bağlar. • İş parçasını tezgâha bağlama çeşitleri tarif edilir. • Bağlama araçları sınıflandırılır. • Komparatör ile iş parçasının salgı kontrolü açıklanır. • Emniyetli bağlama kuralları açıklanır. | D34: Geçen haftaki salgı kontrolü tekniği hatırlatılır; bu hafta farklı bağlama araçlarının (dört ayaklı ayna, mengene, iş kalıbı) tanıtılacağı söylenir. | E34: Dört ayaklı ayna ile merkezlenmemiş parça bağlama ve emniyetli bağlama kuralları gösterilir; öğrenciler farklı parçaları farklı yöntemlerle bağlama uygulaması yapar. | F34: Bağlama güvenliği açısından her öğrencinin parçası kontrol edilerek geri bildirim verilir. | G34: Gösteri, Soru-Cevap, Programlı Öğretim, Bireyselleştirilmiş Öğretim, Temrin Çalışmaları | H34: Temel İmalat Atölyesi, torna tezgahları, freze tezgahları, matkap tezgahları, kesici takımlar, akıllı tahta
A35: =TAKVİM!$B$37+(MATCH($G$5,{"Pazartesi","Salı","Çarşamba","Perşembe","Cuma"},0)-1) -> 46479 | B35: 4. İş Parçası Üzerinde Tornalama İşlemleri Yapma | C35: 4. İş parçası üzerinde tornalama işlemleri yapar. • Alın tornalama işlemi açıklanır. • Öğrencinin kesiciyi punta ekseninde bağlaması ve devir hesabı yapması sağlanır. • İlerleme hızına dikkat edilerek, alın tornalama işlemi yaptırılır. • Punta deliği açma tanımlanır. • Öğrenciye uygun devirle punta deliği açtırılır. | D35: Aynaya bağlanan parçanın yüzeyinin nasıl düzgünleştirileceği sorulur; bitmiş ve bitmemiş alın yüzeyi karşılaştırmalı olarak gösterilir. | E35: Devir hesabı yapılarak alın tornalama tekniği gösterilir, öğrenciler kendi parçalarında alın tornalama uygulaması yapar; ardından merkezleme matkabıyla punta deliği açma gösterilip uygulatılır. | F35: Tornalanan alın yüzeyi düzlük açısından kontrol edilir. | G35: Gösteri, Soru-Cevap, Programlı Öğretim, Bireyselleştirilmiş Öğretim, Temrin Çalışmaları | H35: Temel İmalat Atölyesi, torna tezgahları, freze tezgahları, matkap tezgahları, kesici takımlar, akıllı tahta
A36: =TAKVİM!$B$38+(MATCH($G$5,{"Pazartesi","Salı","Çarşamba","Perşembe","Cuma"},0)-1) -> 46486 | B36: 4. İş Parçası Üzerinde Tornalama İşlemleri Yapma | C36: 4. İş parçası üzerinde tornalama işlemleri yapar. • Silindirik tornalama işlemini açıklanır. • Uzun parçaları ayna punta arasında yapması gerektiği vurgulanır. • Salgı kontrolü yapılarak, uygun devirle silindirik tornalama işlemi yaptırılır. • Kademeli tornalamayı tanımlanır. • Uygun devir ve ilerleme ile kademeli tornalama yaptırılır. 23 NİSAN Ulusal Egemenlik ve Çocuk Bayramı | D36: 23 Nisan haftasına denk gelen bu haftada, geçen hafta açılan punta deliğinin uzun parça tornalamada kullanılacağı anlatılır; ayna-punta arası bağlama örneği gösterilir. | E36: Salgı kontrolüyle uygun devir seçilerek silindirik tornalama tekniği gösterilir; ardından farklı çaplarda kademe açma esasına dayanan kademeli tornalama uygulaması yaptırılır. | F36: Tornalanan silindirik ve kademeli yüzeyler kumpasla ölçülüp resme uygunluğu kontrol edilir. | G36: Gösteri, Soru-Cevap, Programlı Öğretim, Bireyselleştirilmiş Öğretim, Temrin Çalışmaları | H36: Temel İmalat Atölyesi, torna tezgahları, freze tezgahları, matkap tezgahları, kesici takımlar, akıllı tahta
A37: =TAKVİM!$B$39+(MATCH($G$5,{"Pazartesi","Salı","Çarşamba","Perşembe","Cuma"},0)-1) -> 46493 | B37: 4. İş Parçası Üzerinde Tornalama İşlemleri Yapma | C37: 4. İş parçası üzerinde tornalama işlemleri yapar. • Tornada kanal açma tanımlanır. • Devir hesabı yapılarak, soğutma sıvısı kullandırılır. • Tornada kanal açma işlemi yaptırılır. • Konik tornalama tanımlanır. • Konik hesabı yaptırılır. • Uygun devir ve ilerleme ile konik tornalama yaptırılır. | D37: Bir milin üzerine segman/rulman oturması için kanal gerektiği örneğiyle dikkat çekilir; kanal kalemi gösterilir. | E37: Devir ve soğutma sıvısı kullanılarak kanal açma tekniği gösterilir; ardından üst kızak açısı ayarlama ve konik hesabına dayanan konik tornalama anlatılıp uygulatılır. | F37: Açılan kanal ölçüsü ve konik açısı mastarla kontrol edilir. | G37: Gösteri, Soru-Cevap, Programlı Öğretim, Bireyselleştirilmiş Öğretim, Temrin Çalışmaları | H37: Temel İmalat Atölyesi, torna tezgahları, freze tezgahları, matkap tezgahları, kesici takımlar, akıllı tahta
A38: =TAKVİM!$B$40+(MATCH($G$5,{"Pazartesi","Salı","Çarşamba","Perşembe","Cuma"},0)-1) -> 46500 | B38: 4. İş Parçası Üzerinde Tornalama İşlemleri Yapma | C38: 4. İş parçası üzerinde tornalama işlemleri yapar. • Tırtıl çekme tanımlanır. • Tırtıl çekme işlemi yaptırılır. • Torna tezgâhında kılavuz ve pafta çekme açıklanır. • Torna tezgâhında kılavuz ve pafta çekme işlemi yaptırılır. | D38: Elle kavranacak parçalarda (tornavida sapı gibi) yüzeyin neden pürüzlendirildiği sorulur; tırtıl kalemi gösterilir. | E38: Tırtıl çekme tekniği gösterilip uygulatılır; ardından torna tezgâhında düşük devirle kılavuz ve pafta çekme (elle çekmeden farkı vurgulanarak) gösterilir ve öğrencilere uygulatılır. | F38: Tırtıllı yüzey ve açılan diş kalitesi gözle ve elle kontrol edilir; dönem içi torna becerileri genel olarak değerlendirilir. | G38: Gösteri, Soru-Cevap, Programlı Öğretim, Bireyselleştirilmiş Öğretim, Temrin Çalışmaları | H38: Temel İmalat Atölyesi, torna tezgahları, freze tezgahları, matkap tezgahları, kesici takımlar, akıllı tahta
A39: =TAKVİM!$B$41+(MATCH($G$5,{"Pazartesi","Salı","Çarşamba","Perşembe","Cuma"},0)-1) -> 46507 | B39: TEMEL FREZELEME İŞLEMLERİ - 1. Freze Tezgâhlarını Tanıma | C39: 1. Freze Tezgâhlarını tanır. • Freze Tezgâhlarını tanımlanır. • Freze tezgâhı çeşitlerini sınıflandırır. • Freze tezgâhı kısımları sıralanır. • Freze Tezgâhları çalışma sistemini açıklanır. • Freze tezgâhlarında uyulacak iş güvenliği kuralları sıralanır. | D39: Torna ile silindirik parça işlendiği hatırlatılarak, düz/köşeli yüzeyler için freze tezgâhının kullanılacağı söylenir; öğrenciler freze tezgâhına götürülür. | E39: Freze tezgâhının kısımları (tabla, mil, kafa), çeşitleri (yatay/dikey) ve çalışma sistemi gösterilir; dönen çakıya yaklaşmama ve koruyucu kullanma gibi iş güvenliği kuralları vurgulanır. | F39: Tezgâh kısımları isimlendirme sorularıyla pekiştirilir. | G39: Gösteri, Soru-Cevap, Programlı Öğretim, Bireyselleştirilmiş Öğretim, Temrin Çalışmaları | H39: Temel İmalat Atölyesi, torna tezgahları, freze tezgahları, matkap tezgahları, kesici takımlar, akıllı tahta
A40: =TAKVİM!$B$42+(MATCH($G$5,{"Pazartesi","Salı","Çarşamba","Perşembe","Cuma"},0)-1) -> 46514 | B40: 1. Freze Tezgâhlarını Tanıma | C40: 1. Freze Tezgâhlarını tanır. • Freze tezgâhı panosunu kullandırır. • Freze tezgâhında yapılabilecek işleri tasarlatır. • Freze tezgâhı devir sayısını ayarlatır. • Freze tezgâhı ilerleme hızını ayarlatır. • Freze tezgâhı tablasına mengene bağlatır. • Freze tezgâhına kesiciyi bağlatır. • Freze tezgâhının otomatik ayarlarını yaptırır. • Öğrenci freze tezgâhını çalıştırır. | D40: Geçen hafta tanıtılan freze tezgâhı kısımları hatırlatılır; bu hafta tezgâhın pratik kullanımına geçileceği belirtilir. | E40: Kontrol panosu, devir/ilerleme ayarı, mengene bağlama, kesici bağlama ve otomatik ilerleme ayarları öğretmen tarafından gösterilir; öğrenciler nezaret altında tezgâhı adım adım çalıştırır. | F40: Her öğrencinin tezgâhı güvenli şekilde başlatıp durdurabildiği gözlemlenir. | G40: Gösteri, Soru-Cevap, Programlı Öğretim, Bireyselleştirilmiş Öğretim, Temrin Çalışmaları | H40: Temel İmalat Atölyesi, torna tezgahları, freze tezgahları, matkap tezgahları, kesici takımlar, akıllı tahta
A41: =TAKVİM!$B$43+(MATCH($G$5,{"Pazartesi","Salı","Çarşamba","Perşembe","Cuma"},0)-1) -> 46521 | B41: 2. Kesicileri Bağlama | C41: 2. Kesicileri bağlar. • Freze çakıları biçimlerine göre tanıtılır ve kullanıldığı yerler açıklanır. • Freze çakılarını yapıldığı malzemelere göre sıralanır. • Freze çakılarını tezgâha bağlama tekniklerini açıklanır. • İşe uygun özellikte freze çakısı seçtirilir. • Çakıya uygun bağlama aracını seçtirilir. • Malafa ve başlığı tezgâha bağlatılır. • Dönüş yönünü dikkate alarak frezeyi takım tutucuya bağlatılır. 19 MAYIS Atatürk'ü Anma Gençlik ve Spor Bayramı | D41: 19 Mayıs haftasına denk gelen bu haftada, torna kaleminden farklı olarak frezede 'çakı' kullanıldığı hatırlatılır; parmak, disk ve köşe çakısı örnekleri sınıfa getirilir. | E41: Çakı malzemeleri ve kullanım yerleri anlatılır; malafa ve başlığa çakı bağlama, dönüş yönüne göre takım tutucuya bağlama teknikleri gösterilir. Öğrenciler çakı bağlama uygulaması yapar. | F41: Bağlanan çakının sıkılığı ve dönüş yönü birlikte kontrol edilir. | G41: Gösteri, Soru-Cevap, Programlı Öğretim, Bireyselleştirilmiş Öğretim, Temrin Çalışmaları | H41: Temel İmalat Atölyesi, torna tezgahları, freze tezgahları, matkap tezgahları, kesici takımlar, akıllı tahta
A42: =TAKVİM!$B$44+(MATCH($G$5,{"Pazartesi","Salı","Çarşamba","Perşembe","Cuma"},0)-1) -> 46528 | B42: 2. Kesicileri Bağlama | C42: 2. Kesicileri bağlar. • Freze çakıları biçimlerine göre tanıtılır ve kullanıldığı yerler açıklanır. • Freze çakılarını yapıldığı malzemelere göre sıralanır. • Freze çakılarını tezgâha bağlama tekniklerini açıklanır. | D42: Geçen hafta bağlanan çakı çeşitleri kısaca hatırlatılır; bu hafta farklı çakı-malzeme uyumuna odaklanılacağı belirtilir. | E42: Çelik ve alüminyum gibi farklı iş parçası malzemelerine göre uygun çakı seçimi karşılaştırmalı örneklerle gösterilir; öğrenciler seçim uygulaması yapar. | F42: Seçilen çakı-malzeme eşleşmeleri sınıfça tartışılarak değerlendirilir. | G42: Gösteri, Soru-Cevap, Programlı Öğretim, Bireyselleştirilmiş Öğretim, Temrin Çalışmaları | H42: Temel İmalat Atölyesi, torna tezgahları, freze tezgahları, matkap tezgahları, kesici takımlar, akıllı tahta
...

Sheet MESLEKİ GELİŞİM AT 9A
C1: GÜNLÜK DERS PLANI
A3: DERS | B3: MESLEKİ GELİŞİM ATÖLYESİ | F3: ALAN/DAL | G3: Makine ve Tasarım Teknolojisi Alanı
A4: SINIF | B4: AMP 9A | F4: DERS SAATİ | G4: 2 SAAT
A5: ÖĞRETMEN | B5: Ali Osman KOÇ | F5: DERS GÜNÜ SEÇ | G5: Cuma
A7: TARİH | B7: KONU | C7: KAZANIM | D7: GİRİŞ | E7: GELİŞME | F7: SONUÇ | G7: YÖNTEM VE TEKNİKLER | H7: ARAÇ VE GEREÇLER | I7: ÖLÇME-DEĞERLENDİRME
A8: =TAKVİM!$B$10+(MATCH($G$5,{"Pazartesi","Salı","Çarşamba","Perşembe","Cuma"},0)-1) -> 46283 | B8: MESLEK ETİĞİ VE AHİLİK - 1. Kurallar ve İşlevi | C8: 1. Kuralların gerekliliğini ve işlevini toplumsal fayda açısından tartışır. • Sınıf ortamında sunum yapmalarına yönelik bir etkinlik planlanarak öğrencilerin iletişim engellerini deneyimlemeleri sağlanır. • Öğrencilerin, etkili iletişim için sınıfta uyulması gereken kurallara arkadaşlarıyla birlikte karar vermeleri sağlanır. • Öğrencilerle birlikte oluşturulacak sınıf anlaşmasının görünür ve kalıcı olması için gerekli önlemler alınır. | D8: Öğretim yılının ilk dersi olduğu için önceki bir konu tekrarı yapılmaz; bunun yerine öğrencilere kısaca kendilerini tanıtmaları için söz verilir ve sınıfta neden ortak kurallara ihtiyaç duyulduğu sorusu ile derse başlanır. | E8: Öğrencilerden kısa süreli sunum yapmaları istenerek bir iletişim engeli yaşama deneyimi yaşatılır; ardından bu deneyim üzerinden etkili iletişim için sınıfta uyulması gereken kurallar öğrencilerle birlikte tartışılarak belirlenir ve panoya asılacak bir 'sınıf anlaşması' hazırlanır. | F8: Hazırlanan sınıf anlaşması yüksek sesle okunup tüm öğrencilerin onayı alınır; anlaşmanın sınıfta görünür bir yere asılacağı belirtilir. | G8: Soru-Cevap, Grup Çalışması, Tartışma, Proje Tabanlı Öğrenme, Bireyselleştirilmiş Öğretim | H8: Etkileşimli tahta/projeksiyon, mesleki gelişim dersi tasarım odaklı çalışma defteri, internet, kütüphane
