Workbook

Sheet TAKVİM
A1: ÇALIŞMA TAKVİMİ — Bu sayfadaki tarihleri her yıl güncelleyin; diğer tüm ders sayfaları otomatik güncellenir
A3: OKUL | B3: Soma Mesleki ve Teknik Anadolu Lisesi | D3: ÖĞRETİM YILI SEÇ | E3: 2026-2027
A4: EĞİTİM-ÖĞRETİM YILI | B4: 2026-2027 Eğitim-Öğretim Yılı | D4: 1.Yarıyıl Başlangıcı (elle değiştirilebilir) | E4: =DATE(VALUE(LEFT($E$3,4)),9,14)-(WEEKDAY(DATE(VALUE(LEFT($E$3,4)),9,14),2)-1) -> 46279
D5: Not: Ramazan/Kurban Bayramı otomatik hesaplanamaz, elle güncellenmeli.
A6: SINAV TARİHLERİ
A7: 1.Dönem 1.Sınav Tarihi | B7: 13.11.2026
A8: 1.Dönem 2.Sınav Tarihi | B8: 08.01.2027
A9: 2.Dönem 1.Sınav Tarihi | B9: 19.03.2027
A10: 2.Dönem 2.Sınav Tarihi | B10: 14.05.2027
A12: ÖNEMLİ GÜN VE HAFTALAR
A13: 1.Yarıyıl Başlangıcı | B13: 2026-09-14 00:00:00
A14: 2.Yarıyıl Başlangıcı | B14: 2027-02-08 00:00:00
A15: Cumhuriyet Bayramı | B15: 29.10.2026
A16: 1. Dönem Ara Tatil | B16: 16-20 Kasım
A17: Atatürk'ü Anma Günü ve Atatürk Haftası | B17: 10.11.2026
A18: 23 Nisan Ulusal Egemenlik ve Çocuk Bayramı | B18: 23.04.2027
A19: 2. Dönem Ara Tatil | B19: 08-12 Mart
A20: 19 Mayıs Atatürk'ü Anma Gençlik ve Spor Bayramı | B20: 19.05.2027
A21: Yılbaşı Tatili | B21: 01.01.2027
A22: Ramazan Bayramı | B22: 20.03.2027
A23: Yarıyıl Tatili | B23: 25 OCAK - 05 ŞUBAT 2027
A24: Eğitim-Öğretim Yılının Sonu | B24: 25.06.2027
A27: 37 HAFTALIK DERS TAKVİMİ (tüm ders sayfaları bu tabloyu kullanır)
A28: Hafta No | B28: Tarih Aralığı | C28: Tatil mi? | D28: Tatil/Not Adı
A29: 1 | B29: 14-18 Eylül | C29: HAYIR
A30: 2 | B30: 21-25 Eylül | C30: HAYIR
A31: 3 | B31: 28 Eylül - 02 Ekim | C31: HAYIR
A32: 4 | B32: 05-09 Ekim | C32: HAYIR
A33: 5 | B33: 12-16 Ekim | C33: HAYIR
A34: 6 | B34: 19-23 Ekim | C34: HAYIR
A35: 7 | B35: 26-30 Ekim | C35: HAYIR
A36: 8 | B36: 02-06 Kasım | C36: HAYIR
A37: 9 | B37: 09-13 Kasım | C37: HAYIR
A38: 10 | B38: 16-20 Kasım | C38: EVET | D38: 1.DÖNEM ARA TATİL
A39: 11 | B39: 23-27 Kasım | C39: HAYIR
A40: 12 | B40: 30 Kasım - 04 Aralık | C40: HAYIR
A41: 13 | B41: 07-11 Aralık | C41: HAYIR
A42: 14 | B42: 14-18 Aralık | C42: HAYIR
A43: 15 | B43: 21-25 Aralık | C43: HAYIR
A44: 16 | B44: 28 Aralık - 01 Ocak | C44: HAYIR
...

Sheet TEMEL İMALAT İŞLEM AMP 9A
H1: YILLIK DERS PLANI
A3: EĞİTİM-ÖĞRETİM YILI | G3: =TAKVİM!$B$4 -> 2026-2027 Eğitim-Öğretim Yılı | P3: OKUL | U3: =TAKVİM!$B$3 -> Soma Mesleki ve Teknik Anadolu Lisesi
A4: DERS | G4: : TEMEL İMALAT İŞLEMLERİ | P4: ALAN/DAL | U4: : Makine ve Tasarım Teknolojisi Alanı
A5: DERS SAATİ | G5: : 6 SAAT | P5: SINIF | U5: : AMP 9A
A7: 1.DÖNEM SINAV TARİHLERİ | P7: 2.DÖNEM SINAV TARİHLERİ
A8: 1.Dönem 1.Sınav Tarihi | G8: =TAKVİM!$B$7 -> 13.11.2026 | P8: 2.Dönem 1.Sınav Tarihi | U8: =TAKVİM!$B$9 -> 19.03.2027
A9: 1.Dönem 2.Sınav Tarihi | G9: =TAKVİM!$B$8 -> 08.01.2027 | P9: 2.Dönem 2.Sınav Tarihi | U9: =TAKVİM!$B$10 -> 14.05.2027
A11: 1.DÖNEM ÖNEMLİ GÜN VE HAFTALAR | P11: 2.DÖNEM ÖNEMLİ GÜN VE HAFTALAR
A12: 1.Yarıyıl Başlangıcı | G12: =TAKVİM!$B$13 -> 2026-09-14 00:00:00 | P12: 2.Yarıyıl Başlangıcı | U12: =TAKVİM!$B$14 -> 2027-02-08 00:00:00
A13: Cumhuriyet Bayramı | G13: =TAKVİM!$B$15 -> 29.10.2026 | P13: 2. Dönem Ara Tatil | U13: =TAKVİM!$B$19 -> 08-12 Mart
A14: Atatürk'ü Anma Günü ve Atatürk Haftası | G14: =TAKVİM!$B$17 -> 10.11.2026 | P14: 23 Nisan Ulusal Egemenlik ve Çocuk Bayramı | U14: =TAKVİM!$B$18 -> 23.04.2027
A15: 1. Dönem Ara Tatil | G15: =TAKVİM!$B$16 -> 16-20 Kasım | P15: 19 Mayıs Atatürk'ü Anma Gençlik ve Spor Bayramı | U15: =TAKVİM!$B$20 -> 19.05.2027
A16: Yılbaşı Tatili | G16: =TAKVİM!$B$21 -> 01.01.2027 | P16: Ramazan Bayramı | U16: =TAKVİM!$B$22 -> 20.03.2027
A17: Yarıyıl Tatili | G17: =TAKVİM!$B$23 -> 25 OCAK - 05 ŞUBAT 2027 | P17: Eğitim-Öğretim Yılının Sonu | U17: =TAKVİM!$B$24 -> 25.06.2027
A19: 2026-2027 EĞİTİM-ÖĞRETİM YILI İŞGÜNÜ TAKVİMİ
A20: =TAKVİM!$A$73 -> Günler | B20: =TAKVİM!$B$73 -> Eylül 2026 | H20: =TAKVİM!$H$73 -> Ekim 2026 | N20: =TAKVİM!$N$73 -> Kasım 2026 | T20: =TAKVİM!$T$73 -> Aralık 2026 | Z20: =TAKVİM!$Z$73 -> Ocak 2027
A21: =TAKVİM!$A$74 -> Pazartesi | B21: =TAKVİM!$B$74 | C21: =TAKVİM!$C$74 -> 7 | D21: =TAKVİM!$D$74 -> 14 | E21: =TAKVİM!$E$74 -> 21 | F21: =TAKVİM!$F$74 -> 28 | G21: =TAKVİM!$G$74 | H21: =TAKVİM!$H$74 | I21: =TAKVİM!$I$74 -> 5 | J21: =TAKVİM!$J$74 -> 12 | K21: =TAKVİM!$K$74 -> 19 | L21: =TAKVİM!$L$74 -> 26 | M21: =TAKVİM!$M$74 | N21: =TAKVİM!$N$74 | O21: =TAKVİM!$O$74 -> 2 | P21: =TAKVİM!$P$74 -> 9 | Q21: =TAKVİM!$Q$74 -> 16 | R21: =TAKVİM!$R$74 -> 23 | S21: =TAKVİM!$S$74 -> 30 | T21: =TAKVİM!$T$74 | U21: =TAKVİM!$U$74 -> 7 | V21: =TAKVİM!$V$74 -> 14 | W21: =TAKVİM!$W$74 -> 21 | X21: =TAKVİM!$X$74 -> 28 | Y21: =TAKVİM!$Y$74 | Z21: =TAKVİM!$Z$74 | AA21: =TAKVİM!$AA$74 -> 4 | AB21: =TAKVİM!$AB$74 -> 11 | AC21: =TAKVİM!$AC$74 -> 18 | AD21: =TAKVİM!$AD$74 -> 25 | AE21: =TAKVİM!$AE$74
A22: =TAKVİM!$A$75 -> Salı | B22: =TAKVİM!$B$75 -> 1 | C22: =TAKVİM!$C$75 -> 8 | D22: =TAKVİM!$D$75 -> 15 | E22: =TAKVİM!$E$75 -> 22 | F22: =TAKVİM!$F$75 -> 29 | G22: =TAKVİM!$G$75 | H22: =TAKVİM!$H$75 | I22: =TAKVİM!$I$75 -> 6 | J22: =TAKVİM!$J$75 -> 13 | K22: =TAKVİM!$K$75 -> 20 | L22: =TAKVİM!$L$75 -> 27 | M22: =TAKVİM!$M$75 | N22: =TAKVİM!$N$75 | O22: =TAKVİM!$O$75 -> 3 | P22: =TAKVİM!$P$75 -> 10 | Q22: =TAKVİM!$Q$75 -> 17 | R22: =TAKVİM!$R$75 -> 24 | S22: =TAKVİM!$S$75 | T22: =TAKVİM!$T$75 -> 1 | U22: =TAKVİM!$U$75 -> 8 | V22: =TAKVİM!$V$75 -> 15 | W22: =TAKVİM!$W$75 -> 22 | X22: =TAKVİM!$X$75 -> 29 | Y22: =TAKVİM!$Y$75 | Z22: =TAKVİM!$Z$75 | AA22: =TAKVİM!$AA$75 -> 5 | AB22: =TAKVİM!$AB$75 -> 12 | AC22: =TAKVİM!$AC$75 -> 19 | AD22: =TAKVİM!$AD$75 -> 26 | AE22: =TAKVİM!$AE$75
A23: =TAKVİM!$A$76 -> Çarşamba | B23: =TAKVİM!$B$76 -> 2 | C23: =TAKVİM!$C$76 -> 9 | D23: =TAKVİM!$D$76 -> 16 | E23: =TAKVİM!$E$76 -> 23 | F23: =TAKVİM!$F$76 -> 30 | G23: =TAKVİM!$G$76 | H23: =TAKVİM!$H$76 | I23: =TAKVİM!$I$76 -> 7 | J23: =TAKVİM!$J$76 -> 14 | K23: =TAKVİM!$K$76 -> 21 | L23: =TAKVİM!$L$76 -> 28 | M23: =TAKVİM!$M$76 | N23: =TAKVİM!$N$76 | O23: =TAKVİM!$O$76 -> 4 | P23: =TAKVİM!$P$76 -> 11 | Q23: =TAKVİM!$Q$76 -> 18 | R23: =TAKVİM!$R$76 -> 25 | S23: =TAKVİM!$S$76 | T23: =TAKVİM!$T$76 -> 2 | U23: =TAKVİM!$U$76 -> 9 | V23: =TAKVİM!$V$76 -> 16 | W23: =TAKVİM!$W$76 -> 23 | X23: =TAKVİM!$X$76 -> 30 | Y23: =TAKVİM!$Y$76 | Z23: =TAKVİM!$Z$76 | AA23: =TAKVİM!$AA$76 -> 6 | AB23: =TAKVİM!$AB$76 -> 13 | AC23: =TAKVİM!$AC$76 -> 20 | AD23: =TAKVİM!$AD$76 -> 27 | AE23: =TAKVİM!$AE$76
A24: =TAKVİM!$A$77 -> Perşembe | B24: =TAKVİM!$B$77 -> 3 | C24: =TAKVİM!$C$77 -> 10 | D24: =TAKVİM!$D$77 -> 17 | E24: =TAKVİM!$E$77 -> 24 | F24: =TAKVİM!$F$77 | G24: =TAKVİM!$G$77 | H24: =TAKVİM!$H$77 -> 1 | I24: =TAKVİM!$I$77 -> 8 | J24: =TAKVİM!$J$77 -> 15 | K24: =TAKVİM!$K$77 -> 22 | L24: =TAKVİM!$L$77 -> 29 | M24: =TAKVİM!$M$77 | N24: =TAKVİM!$N$77 | O24: =TAKVİM!$O$77 -> 5 | P24: =TAKVİM!$P$77 -> 12 | Q24: =TAKVİM!$Q$77 -> 19 | R24: =TAKVİM!$R$77 -> 26 | S24: =TAKVİM!$S$77 | T24: =TAKVİM!$T$77 -> 3 | U24: =TAKVİM!$U$77 -> 10 | V24: =TAKVİM!$V$77 -> 17 | W24: =TAKVİM!$W$77 -> 24 | X24: =TAKVİM!$X$77 -> 31 | Y24: =TAKVİM!$Y$77 | Z24: =TAKVİM!$Z$77 | AA24: =TAKVİM!$AA$77 -> 7 | AB24: =TAKVİM!$AB$77 -> 14 | AC24: =TAKVİM!$AC$77 -> 21 | AD24: =TAKVİM!$AD$77 -> 28 | AE24: =TAKVİM!$AE$77
A25: =TAKVİM!$A$78 -> Cuma | B25: =TAKVİM!$B$78 -> 4 | C25: =TAKVİM!$C$78 -> 11 | D25: =TAKVİM!$D$78 -> 18 | E25: =TAKVİM!$E$78 -> 25 | F25: =TAKVİM!$F$78 | G25: =TAKVİM!$G$78 | H25: =TAKVİM!$H$78 -> 2 | I25: =TAKVİM!$I$78 -> 9 | J25: =TAKVİM!$J$78 -> 16 | K25: =TAKVİM!$K$78 -> 23 | L25: =TAKVİM!$L$78 -> 30 | M25: =TAKVİM!$M$78 | N25: =TAKVİM!$N$78 | O25: =TAKVİM!$O$78 -> 6 | P25: =TAKVİM!$P$78 -> 13 | Q25: =TAKVİM!$Q$78 -> 20 | R25: =TAKVİM!$R$78 -> 27 | S25: =TAKVİM!$S$78 | T25: =TAKVİM!$T$78 -> 4 | U25: =TAKVİM!$U$78 -> 11 | V25: =TAKVİM!$V$78 -> 18 | W25: =TAKVİM!$W$78 -> 25 | X25: =TAKVİM!$X$78 | Y25: =TAKVİM!$Y$78 | Z25: =TAKVİM!$Z$78 -> 1 | AA25: =TAKVİM!$AA$78 -> 8 | AB25: =TAKVİM!$AB$78 -> 15 | AC25: =TAKVİM!$AC$78 -> 22 | AD25: =TAKVİM!$AD$78 -> 29 | AE25: =TAKVİM!$AE$78
A26: =TAKVİM!$A$79 -> Cumartesi | B26: =TAKVİM!$B$79 -> 5 | C26: =TAKVİM!$C$79 -> 12 | D26: =TAKVİM!$D$79 -> 19 | E26: =TAKVİM!$E$79 -> 26 | F26: =TAKVİM!$F$79 | G26: =TAKVİM!$G$79 | H26: =TAKVİM!$H$79 -> 3 | I26: =TAKVİM!$I$79 -> 10 | J26: =TAKVİM!$J$79 -> 17 | K26: =TAKVİM!$K$79 -> 24 | L26: =TAKVİM!$L$79 -> 31 | M26: =TAKVİM!$M$79 | N26: =TAKVİM!$N$79 | O26: =TAKVİM!$O$79 -> 7 | P26: =TAKVİM!$P$79 -> 14 | Q26: =TAKVİM!$Q$79 -> 21 | R26: =TAKVİM!$R$79 -> 28 | S26: =TAKVİM!$S$79 | T26: =TAKVİM!$T$79 -> 5 | U26: =TAKVİM!$U$79 -> 12 | V26: =TAKVİM!$V$79 -> 19 | W26: =TAKVİM!$W$79 -> 26 | X26: =TAKVİM!$X$79 | Y26: =TAKVİM!$Y$79 | Z26: =TAKVİM!$Z$79 -> 2 | AA26: =TAKVİM!$AA$79 -> 9 | AB26: =TAKVİM!$AB$79 -> 16 | AC26: =TAKVİM!$AC$79 -> 23 | AD26: =TAKVİM!$AD$79 -> 30 | AE26: =TAKVİM!$AE$79
A27: =TAKVİM!$A$80 -> Pazar | B27: =TAKVİM!$B$80 -> 6 | C27: =TAKVİM!$C$80 -> 13 | D27: =TAKVİM!$D$80 -> 20 | E27: =TAKVİM!$E$80 -> 27 | F27: =TAKVİM!$F$80 | G27: =TAKVİM!$G$80 | H27: =TAKVİM!$H$80 -> 4 | I27: =TAKVİM!$I$80 -> 11 | J27: =TAKVİM!$J$80 -> 18 | K27: =TAKVİM!$K$80 -> 25 | L27: =TAKVİM!$L$80 | M27: =TAKVİM!$M$80 | N27: =TAKVİM!$N$80 -> 1 | O27: =TAKVİM!$O$80 -> 8 | P27: =TAKVİM!$P$80 -> 15 | Q27: =TAKVİM!$Q$80 -> 22 | R27: =TAKVİM!$R$80 -> 29 | S27: =TAKVİM!$S$80 | T27: =TAKVİM!$T$80 -> 6 | U27: =TAKVİM!$U$80 -> 13 | V27: =TAKVİM!$V$80 -> 20 | W27: =TAKVİM!$W$80 -> 27 | X27: =TAKVİM!$X$80 | Y27: =TAKVİM!$Y$80 | Z27: =TAKVİM!$Z$80 -> 3 | AA27: =TAKVİM!$AA$80 -> 10 | AB27: =TAKVİM!$AB$80 -> 17 | AC27: =TAKVİM!$AC$80 -> 24 | AD27: =TAKVİM!$AD$80 -> 31 | AE27: =TAKVİM!$AE$80
A28: =TAKVİM!$A$81 -> Günler | B28: =TAKVİM!$B$81 -> Şubat 2027 | H28: =TAKVİM!$H$81 -> Mart 2027 | N28: =TAKVİM!$N$81 -> Nisan 2027 | T28: =TAKVİM!$T$81 -> Mayıs 2027 | Z28: =TAKVİM!$Z$81 -> Haziran 2027
A29: =TAKVİM!$A$82 -> Pazartesi | B29: =TAKVİM!$B$82 -> 1 | C29: =TAKVİM!$C$82 -> 8 | D29: =TAKVİM!$D$82 -> 15 | E29: =TAKVİM!$E$82 -> 22 | F29: =TAKVİM!$F$82 | G29: =TAKVİM!$G$82 | H29: =TAKVİM!$H$82 -> 1 | I29: =TAKVİM!$I$82 -> 8 | J29: =TAKVİM!$J$82 -> 15 | K29: =TAKVİM!$K$82 -> 22 | L29: =TAKVİM!$L$82 -> 29 | M29: =TAKVİM!$M$82 | N29: =TAKVİM!$N$82 | O29: =TAKVİM!$O$82 -> 5 | P29: =TAKVİM!$P$82 -> 12 | Q29: =TAKVİM!$Q$82 -> 19 | R29: =TAKVİM!$R$82 -> 26 | S29: =TAKVİM!$S$82 | T29: =TAKVİM!$T$82 | U29: =TAKVİM!$U$82 -> 3 | V29: =TAKVİM!$V$82 -> 10 | W29: =TAKVİM!$W$82 -> 17 | X29: =TAKVİM!$X$82 -> 24 | Y29: =TAKVİM!$Y$82 -> 31 | Z29: =TAKVİM!$Z$82 | AA29: =TAKVİM!$AA$82 -> 7 | AB29: =TAKVİM!$AB$82 -> 14 | AC29: =TAKVİM!$AC$82 -> 21 | AD29: =TAKVİM!$AD$82 -> 28 | AE29: =TAKVİM!$AE$82
A30: =TAKVİM!$A$83 -> Salı | B30: =TAKVİM!$B$83 -> 2 | C30: =TAKVİM!$C$83 -> 9 | D30: =TAKVİM!$D$83 -> 16 | E30: =TAKVİM!$E$83 -> 23 | F30: =TAKVİM!$F$83 | G30: =TAKVİM!$G$83 | H30: =TAKVİM!$H$83 -> 2 | I30: =TAKVİM!$I$83 -> 9 | J30: =TAKVİM!$J$83 -> 16 | K30: =TAKVİM!$K$83 -> 23 | L30: =TAKVİM!$L$83 -> 30 | M30: =TAKVİM!$M$83 | N30: =TAKVİM!$N$83 | O30: =TAKVİM!$O$83 -> 6 | P30: =TAKVİM!$P$83 -> 13 | Q30: =TAKVİM!$Q$83 -> 20 | R30: =TAKVİM!$R$83 -> 27 | S30: =TAKVİM!$S$83 | T30: =TAKVİM!$T$83 | U30: =TAKVİM!$U$83 -> 4 | V30: =TAKVİM!$V$83 -> 11 | W30: =TAKVİM!$W$83 -> 18 | X30: =TAKVİM!$X$83 -> 25 | Y30: =TAKVİM!$Y$83 | Z30: =TAKVİM!$Z$83 -> 1 | AA30: =TAKVİM!$AA$83 -> 8 | AB30: =TAKVİM!$AB$83 -> 15 | AC30: =TAKVİM!$AC$83 -> 22 | AD30: =TAKVİM!$AD$83 -> 29 | AE30: =TAKVİM!$AE$83
A31: =TAKVİM!$A$84 -> Çarşamba | B31: =TAKVİM!$B$84 -> 3 | C31: =TAKVİM!$C$84 -> 10 | D31: =TAKVİM!$D$84 -> 17 | E31: =TAKVİM!$E$84 -> 24 | F31: =TAKVİM!$F$84 | G31: =TAKVİM!$G$84 | H31: =TAKVİM!$H$84 -> 3 | I31: =TAKVİM!$I$84 -> 10 | J31: =TAKVİM!$J$84 -> 17 | K31: =TAKVİM!$K$84 -> 24 | L31: =TAKVİM!$L$84 -> 31 | M31: =TAKVİM!$M$84 | N31: =TAKVİM!$N$84 | O31: =TAKVİM!$O$84 -> 7 | P31: =TAKVİM!$P$84 -> 14 | Q31: =TAKVİM!$Q$84 -> 21 | R31: =TAKVİM!$R$84 -> 28 | S31: =TAKVİM!$S$84 | T31: =TAKVİM!$T$84 | U31: =TAKVİM!$U$84 -> 5 | V31: =TAKVİM!$V$84 -> 12 | W31: =TAKVİM!$W$84 -> 19 | X31: =TAKVİM!$X$84 -> 26 | Y31: =TAKVİM!$Y$84 | Z31: =TAKVİM!$Z$84 -> 2 | AA31: =TAKVİM!$AA$84 -> 9 | AB31: =TAKVİM!$AB$84 -> 16 | AC31: =TAKVİM!$AC$84 -> 23 | AD31: =TAKVİM!$AD$84 -> 30 | AE31: =TAKVİM!$AE$84
A32: =TAKVİM!$A$85 -> Perşembe | B32: =TAKVİM!$B$85 -> 4 | C32: =TAKVİM!$C$85 -> 11 | D32: =TAKVİM!$D$85 -> 18 | E32: =TAKVİM!$E$85 -> 25 | F32: =TAKVİM!$F$85 | G32: =TAKVİM!$G$85 | H32: =TAKVİM!$H$85 -> 4 | I32: =TAKVİM!$I$85 -> 11 | J32: =TAKVİM!$J$85 -> 18 | K32: =TAKVİM!$K$85 -> 25 | L32: =TAKVİM!$L$85 | M32: =TAKVİM!$M$85 | N32: =TAKVİM!$N$85 -> 1 | O32: =TAKVİM!$O$85 -> 8 | P32: =TAKVİM!$P$85 -> 15 | Q32: =TAKVİM!$Q$85 -> 22 | R32: =TAKVİM!$R$85 -> 29 | S32: =TAKVİM!$S$85 | T32: =TAKVİM!$T$85 | U32: =TAKVİM!$U$85 -> 6 | V32: =TAKVİM!$V$85 -> 13 | W32: =TAKVİM!$W$85 -> 20 | X32: =TAKVİM!$X$85 -> 27 | Y32: =TAKVİM!$Y$85 | Z32: =TAKVİM!$Z$85 -> 3 | AA32: =TAKVİM!$AA$85 -> 10 | AB32: =TAKVİM!$AB$85 -> 17 | AC32: =TAKVİM!$AC$85 -> 24 | AD32: =TAKVİM!$AD$85 | AE32: =TAKVİM!$AE$85
A33: =TAKVİM!$A$86 -> Cuma | B33: =TAKVİM!$B$86 -> 5 | C33: =TAKVİM!$C$86 -> 12 | D33: =TAKVİM!$D$86 -> 19 | E33: =TAKVİM!$E$86 -> 26 | F33: =TAKVİM!$F$86 | G33: =TAKVİM!$G$86 | H33: =TAKVİM!$H$86 -> 5 | I33: =TAKVİM!$I$86 -> 12 | J33: =TAKVİM!$J$86 -> 19 | K33: =TAKVİM!$K$86 -> 26 | L33: =TAKVİM!$L$86 | M33: =TAKVİM!$M$86 | N33: =TAKVİM!$N$86 -> 2 | O33: =TAKVİM!$O$86 -> 9 | P33: =TAKVİM!$P$86 -> 16 | Q33: =TAKVİM!$Q$86 -> 23 | R33: =TAKVİM!$R$86 -> 30 | S33: =TAKVİM!$S$86 | T33: =TAKVİM!$T$86 | U33: =TAKVİM!$U$86 -> 7 | V33: =TAKVİM!$V$86 -> 14 | W33: =TAKVİM!$W$86 -> 21 | X33: =TAKVİM!$X$86 -> 28 | Y33: =TAKVİM!$Y$86 | Z33: =TAKVİM!$Z$86 -> 4 | AA33: =TAKVİM!$AA$86 -> 11 | AB33: =TAKVİM!$AB$86 -> 18 | AC33: =TAKVİM!$AC$86 -> 25 | AD33: =TAKVİM!$AD$86 | AE33: =TAKVİM!$AE$86
A34: =TAKVİM!$A$87 -> Cumartesi | B34: =TAKVİM!$B$87 -> 6 | C34: =TAKVİM!$C$87 -> 13 | D34: =TAKVİM!$D$87 -> 20 | E34: =TAKVİM!$E$87 -> 27 | F34: =TAKVİM!$F$87 | G34: =TAKVİM!$G$87 | H34: =TAKVİM!$H$87 -> 6 | I34: =TAKVİM!$I$87 -> 13 | J34: =TAKVİM!$J$87 -> 20 | K34: =TAKVİM!$K$87 -> 27 | L34: =TAKVİM!$L$87 | M34: =TAKVİM!$M$87 | N34: =TAKVİM!$N$87 -> 3 | O34: =TAKVİM!$O$87 -> 10 | P34: =TAKVİM!$P$87 -> 17 | Q34: =TAKVİM!$Q$87 -> 24 | R34: =TAKVİM!$R$87 | S34: =TAKVİM!$S$87 | T34: =TAKVİM!$T$87 -> 1 | U34: =TAKVİM!$U$87 -> 8 | V34: =TAKVİM!$V$87 -> 15 | W34: =TAKVİM!$W$87 -> 22 | X34: =TAKVİM!$X$87 -> 29 | Y34: =TAKVİM!$Y$87 | Z34: =TAKVİM!$Z$87 -> 5 | AA34: =TAKVİM!$AA$87 -> 12 | AB34: =TAKVİM!$AB$87 -> 19 | AC34: =TAKVİM!$AC$87 -> 26 | AD34: =TAKVİM!$AD$87 | AE34: =TAKVİM!$AE$87
A35: =TAKVİM!$A$88 -> Pazar | B35: =TAKVİM!$B$88 -> 7 | C35: =TAKVİM!$C$88 -> 14 | D35: =TAKVİM!$D$88 -> 21 | E35: =TAKVİM!$E$88 -> 28 | F35: =TAKVİM!$F$88 | G35: =TAKVİM!$G$88 | H35: =TAKVİM!$H$88 -> 7 | I35: =TAKVİM!$I$88 -> 14 | J35: =TAKVİM!$J$88 -> 21 | K35: =TAKVİM!$K$88 -> 28 | L35: =TAKVİM!$L$88 | M35: =TAKVİM!$M$88 | N35: =TAKVİM!$N$88 -> 4 | O35: =TAKVİM!$O$88 -> 11 | P35: =TAKVİM!$P$88 -> 18 | Q35: =TAKVİM!$Q$88 -> 25 | R35: =TAKVİM!$R$88 | S35: =TAKVİM!$S$88 | T35: =TAKVİM!$T$88 -> 2 | U35: =TAKVİM!$U$88 -> 9 | V35: =TAKVİM!$V$88 -> 16 | W35: =TAKVİM!$W$88 -> 23 | X35: =TAKVİM!$X$88 -> 30 | Y35: =TAKVİM!$Y$88 | Z35: =TAKVİM!$Z$88 -> 6 | AA35: =TAKVİM!$AA$88 -> 13 | AB35: =TAKVİM!$AB$88 -> 20 | AC35: =TAKVİM!$AC$88 -> 27 | AD35: =TAKVİM!$AD$88 | AE35: =TAKVİM!$AE$88
A37: TARİH | D37: KAZANIMLAR | L37: KONULAR | R37: ÖĞRENME-ÖĞRETME YÖNTEM VE TEKNİKLERİ | W37: KULLANILAN EĞİTİM TEKNOLOJİLERİ, ARAÇ VE GEREÇLER | AD37: DEĞERLENDİRME
A38: =TAKVİM!$B$29 -> 14-18 Eylül | D38: 1. Atölyede iş güvenliği tedbirlerini alır. • Atölyede uyması gereken kurallar açıklanır. • Tezgâhlardan meydana gelebilecek iş kazaları açıklanır. • Çalışma sırasında meydana gelebilecek iş kazalarına karşı tedbirleri açıklanır. • İş güvenliği ve emniyet kuralları açıklanır. | L38: EL İŞLEMLERİ 1. Atölyede İş Güvenliği Tedbirleri | R38: Gösteri, Soru-Cevap, Programlı Öğretim, Bireyselleştirilmiş Öğretim, Temrin Çalışmaları | W38: Temel İmalat Atölyesi, torna tezgahları, freze tezgahları, matkap tezgahları, kesici takımlar, akıllı tahta
A39: =TAKVİM!$B$30 -> 21-25 Eylül | D39: 1. Atölyede iş güvenliği tedbirlerini alır. • Atölye temizlik ve düzeni açıklanır. • Yapılan işe uygun iş elbiseleri ve kişisel koruyucu donanımları hazırlatılır. • Yanıcı ve parlayıcı malzemelerin güvenli bir şekilde tutulması sağlanır. | L39: 1. Atölyede İş Güvenliği Tedbirleri | R39: Gösteri, Soru-Cevap, Programlı Öğretim, Bireyselleştirilmiş Öğretim, Temrin Çalışmaları | W39: Temel İmalat Atölyesi, torna tezgahları, freze tezgahları, matkap tezgahları, kesici takımlar, akıllı tahta
A40: =TAKVİM!$B$31 -> 28 Eylül - 02 Ekim | D40: 2. Verilen resme uygun olarak düzlem yüzey eğeleme yapar. • Eğe çeşitleri sıralanır. • İşi parçasını bağlama yöntemleri açıklanır. • Düzlem yüzey kontrol aletleri sıralanır. • Öğrencilerin doğru pozisyonda olmaları sağlanır. | L40: 2. Düzlem Yüzey Eğeleme | R40: Gösteri, Soru-Cevap, Programlı Öğretim, Bireyselleştirilmiş Öğretim, Temrin Çalışmaları | W40: Temel İmalat Atölyesi, torna tezgahları, freze tezgahları, matkap tezgahları, kesici takımlar, akıllı tahta
A41: =TAKVİM!$B$32 -> 05-09 Ekim | D41: 2. Verilen resme uygun olarak düzlem yüzey eğeleme yapar. • Eğe çeşitleri sıralanır. • İşi parçasını bağlama yöntemleri açıklanır. • Düzlem yüzey kontrol aletleri sıralanır. • Öğrencilerin doğru pozisyonda olmaları sağlanır. | L41: 2. Düzlem Yüzey Eğeleme | R41: Gösteri, Soru-Cevap, Programlı Öğretim, Bireyselleştirilmiş Öğretim, Temrin Çalışmaları | W41: Temel İmalat Atölyesi, torna tezgahları, freze tezgahları, matkap tezgahları, kesici takımlar, akıllı tahta
A42: =TAKVİM!$B$33 -> 12-16 Ekim | D42: 3. Markalama ekipmanları ile verilen resme uygun olarak iş parçasını markalar. • Markalamanın amacı üzerinde durulur. • Markalama yöntemleri üzerinde durulur. | L42: 3. Markalama Yapma | R42: Gösteri, Soru-Cevap, Programlı Öğretim, Bireyselleştirilmiş Öğretim, Temrin Çalışmaları | W42: Temel İmalat Atölyesi, torna tezgahları, freze tezgahları, matkap tezgahları, kesici takımlar, akıllı tahta
A43: =TAKVİM!$B$34 -> 19-23 Ekim | D43: 4. Verilen resme uygun olarak profil yüzey eğeleme işlemleri yapar. • Profil yüzey eğeleme yöntemlerini açıklanır. • Yüzey kontrol aletleri tanımlanır. • İç ve dış yüzey eğeleme yaptırılır. • Delik ve kanal eğeleme yaptırılır. • Eğe ile pah kırma işlemi yaptırılır. | L43: 4. Profil Yüzey Eğeleme | R43: Gösteri, Soru-Cevap, Programlı Öğretim, Bireyselleştirilmiş Öğretim, Temrin Çalışmaları | W43: Temel İmalat Atölyesi, torna tezgahları, freze tezgahları, matkap tezgahları, kesici takımlar, akıllı tahta
A44: =TAKVİM!$B$35 -> 26-30 Ekim | D44: 4. Verilen resme uygun olarak profil yüzey eğeleme işlemleri yapar. • Profil yüzey eğeleme yöntemlerini açıklanır. • Yüzey kontrol aletleri tanımlanır. • İç ve dış yüzey eğeleme yaptırılır. • Delik ve kanal eğeleme yaptırılır. • Eğe ile pah kırma işlemi yaptırılır. 29 EKİM Cumhuriyet Bayramı | L44: 4. Profil Yüzey Eğeleme | R44: Gösteri, Soru-Cevap, Programlı Öğretim, Bireyselleştirilmiş Öğretim, Temrin Çalışmaları | W44: Temel İmalat Atölyesi, torna tezgahları, freze tezgahları, matkap tezgahları, kesici takımlar, akıllı tahta
A45: =TAKVİM!$B$36 -> 02-06 Kasım | D45: 5. Verilen resme uygun olarak kesme işlemlerini yapar. • Testere ile kesmeyi tarif edilir. • Testere ile kesme yaparken kazalardan korunma açıklanır. • Keski ile kesme açıklanır. • Keski çeşitleri sıralanır. • Keski ile kesmede dikkat edilecek hususlar açıklanır. | L45: 5. Kesme İşlemleri Yapma | R45: Gösteri, Soru-Cevap, Programlı Öğretim, Bireyselleştirilmiş Öğretim, Temrin Çalışmaları | W45: Temel İmalat Atölyesi, torna tezgahları, freze tezgahları, matkap tezgahları, kesici takımlar, akıllı tahta
...

Sheet MESLEKİ GELİŞİM AT AMP 9A
H1: YILLIK DERS PLANI
A3: EĞİTİM-ÖĞRETİM YILI | G3: =TAKVİM!$B$4 -> 2026-2027 Eğitim-Öğretim Yılı | P3: OKUL | U3: =TAKVİM!$B$3 -> Soma Mesleki ve Teknik Anadolu Lisesi
A4: DERS | G4: : MESLEKİ GELİŞİM ATÖLYESİ | P4: ALAN/DAL | U4: : Makine ve Tasarım Teknolojisi Alanı
A5: DERS SAATİ | G5: : 2 SAAT | P5: SINIF | U5: : AMP 9A
A7: 1.DÖNEM SINAV TARİHLERİ | P7: 2.DÖNEM SINAV TARİHLERİ
A8: 1.Dönem 1.Sınav Tarihi | G8: =TAKVİM!$B$7 -> 13.11.2026 | P8: 2.Dönem 1.Sınav Tarihi | U8: =TAKVİM!$B$9 -> 19.03.2027
A9: 1.Dönem 2.Sınav Tarihi | G9: =TAKVİM!$B$8 -> 08.01.2027 | P9: 2.Dönem 2.Sınav Tarihi | U9: =TAKVİM!$B$10 -> 14.05.2027
A11: 1.DÖNEM ÖNEMLİ GÜN VE HAFTALAR | P11: 2.DÖNEM ÖNEMLİ GÜN VE HAFTALAR
A12: 1.Yarıyıl Başlangıcı | G12: =TAKVİM!$B$13 -> 2026-09-14 00:00:00 | P12: 2.Yarıyıl Başlangıcı | U12: =TAKVİM!$B$14 -> 2027-02-08 00:00:00
A13: Cumhuriyet Bayramı | G13: =TAKVİM!$B$15 -> 29.10.2026 | P13: 2. Dönem Ara Tatil | U13: =TAKVİM!$B$19 -> 08-12 Mart
A14: Atatürk'ü Anma Günü ve Atatürk Haftası | G14: =TAKVİM!$B$17 -> 10.11.2026 | P14: 23 Nisan Ulusal Egemenlik ve Çocuk Bayramı | U14: =TAKVİM!$B$18 -> 23.04.2027
A15: 1. Dönem Ara Tatil | G15: =TAKVİM!$B$16 -> 16-20 Kasım | P15: 19 Mayıs Atatürk'ü Anma Gençlik ve Spor Bayramı | U15: =TAKVİM!$B$20 -> 19.05.2027
A16: Yılbaşı Tatili | G16: =TAKVİM!$B$21 -> 01.01.2027 | P16: Ramazan Bayramı | U16: =TAKVİM!$B$22 -> 20.03.2027
A17: Yarıyıl Tatili | G17: =TAKVİM!$B$23 -> 25 OCAK - 05 ŞUBAT 2027 | P17: Eğitim-Öğretim Yılının Sonu | U17: =TAKVİM!$B$24 -> 25.06.2027
A19: 2026-2027 EĞİTİM-ÖĞRETİM YILI İŞGÜNÜ TAKVİMİ
A20: =TAKVİM!$A$73 -> Günler | B20: =TAKVİM!$B$73 -> Eylül 2026 | H20: =TAKVİM!$H$73 -> Ekim 2026 | N20: =TAKVİM!$N$73 -> Kasım 2026 | T20: =TAKVİM!$T$73 -> Aralık 2026 | Z20: =TAKVİM!$Z$73 -> Ocak 2027
A21: =TAKVİM!$A$74 -> Pazartesi | B21: =TAKVİM!$B$74 | C21: =TAKVİM!$C$74 -> 7 | D21: =TAKVİM!$D$74 -> 14 | E21: =TAKVİM!$E$74 -> 21 | F21: =TAKVİM!$F$74 -> 28 | G21: =TAKVİM!$G$74 | H21: =TAKVİM!$H$74 | I21: =TAKVİM!$I$74 -> 5 | J21: =TAKVİM!$J$74 -> 12 | K21: =TAKVİM!$K$74 -> 19 | L21: =TAKVİM!$L$74 -> 26 | M21: =TAKVİM!$M$74 | N21: =TAKVİM!$N$74 | O21: =TAKVİM!$O$74 -> 2 | P21: =TAKVİM!$P$74 -> 9 | Q21: =TAKVİM!$Q$74 -> 16 | R21: =TAKVİM!$R$74 -> 23 | S21: =TAKVİM!$S$74 -> 30 | T21: =TAKVİM!$T$74 | U21: =TAKVİM!$U$74 -> 7 | V21: =TAKVİM!$V$74 -> 14 | W21: =TAKVİM!$W$74 -> 21 | X21: =TAKVİM!$X$74 -> 28 | Y21: =TAKVİM!$Y$74 | Z21: =TAKVİM!$Z$74 | AA21: =TAKVİM!$AA$74 -> 4 | AB21: =TAKVİM!$AB$74 -> 11 | AC21: =TAKVİM!$AC$74 -> 18 | AD21: =TAKVİM!$AD$74 -> 25 | AE21: =TAKVİM!$AE$74
A22: =TAKVİM!$A$75 -> Salı | B22: =TAKVİM!$B$75 -> 1 | C22: =TAKVİM!$C$75 -> 8 | D22: =TAKVİM!$D$75 -> 15 | E22: =TAKVİM!$E$75 -> 22 | F22: =TAKVİM!$F$75 -> 29 | G22: =TAKVİM!$G$75 | H22: =TAKVİM!$H$75 | I22: =TAKVİM!$I$75 -> 6 | J22: =TAKVİM!$J$75 -> 13 | K22: =TAKVİM!$K$75 -> 20 | L22: =TAKVİM!$L$75 -> 27 | M22: =TAKVİM!$M$75 | N22: =TAKVİM!$N$75 | O22: =TAKVİM!$O$75 -> 3 | P22: =TAKVİM!$P$75 -> 10 | Q22: =TAKVİM!$Q$75 -> 17 | R22: =TAKVİM!$R$75 -> 24 | S22: =TAKVİM!$S$75 | T22: =TAKVİM!$T$75 -> 1 | U22: =TAKVİM!$U$75 -> 8 | V22: =TAKVİM!$V$75 -> 15 | W22: =TAKVİM!$W$75 -> 22 | X22: =TAKVİM!$X$75 -> 29 | Y22: =TAKVİM!$Y$75 | Z22: =TAKVİM!$Z$75 | AA22: =TAKVİM!$AA$75 -> 5 | AB22: =TAKVİM!$AB$75 -> 12 | AC22: =TAKVİM!$AC$75 -> 19 | AD22: =TAKVİM!$AD$75 -> 26 | AE22: =TAKVİM!$AE$75
A23: =TAKVİM!$A$76 -> Çarşamba | B23: =TAKVİM!$B$76 -> 2 | C23: =TAKVİM!$C$76 -> 9 | D23: =TAKVİM!$D$76 -> 16 | E23: =TAKVİM!$E$76 -> 23 | F23: =TAKVİM!$F$76 -> 30 | G23: =TAKVİM!$G$76 | H23: =TAKVİM!$H$76 | I23: =TAKVİM!$I$76 -> 7 | J23: =TAKVİM!$J$76 -> 14 | K23: =TAKVİM!$K$76 -> 21 | L23: =TAKVİM!$L$76 -> 28 | M23: =TAKVİM!$M$76 | N23: =TAKVİM!$N$76 | O23: =TAKVİM!$O$76 -> 4 | P23: =TAKVİM!$P$76 -> 11 | Q23: =TAKVİM!$Q$76 -> 18 | R23: =TAKVİM!$R$76 -> 25 | S23: =TAKVİM!$S$76 | T23: =TAKVİM!$T$76 -> 2 | U23: =TAKVİM!$U$76 -> 9 | V23: =TAKVİM!$V$76 -> 16 | W23: =TAKVİM!$W$76 -> 23 | X23: =TAKVİM!$X$76 -> 30 | Y23: =TAKVİM!$Y$76 | Z23: =TAKVİM!$Z$76 | AA23: =TAKVİM!$AA$76 -> 6 | AB23: =TAKVİM!$AB$76 -> 13 | AC23: =TAKVİM!$AC$76 -> 20 | AD23: =TAKVİM!$AD$76 -> 27 | AE23: =TAKVİM!$AE$76
A24: =TAKVİM!$A$77 -> Perşembe | B24: =TAKVİM!$B$77 -> 3 | C24: =TAKVİM!$C$77 -> 10 | D24: =TAKVİM!$D$77 -> 17 | E24: =TAKVİM!$E$77 -> 24 | F24: =TAKVİM!$F$77 | G24: =TAKVİM!$G$77 | H24: =TAKVİM!$H$77 -> 1 | I24: =TAKVİM!$I$77 -> 8 | J24: =TAKVİM!$J$77 -> 15 | K24: =TAKVİM!$K$77 -> 22 | L24: =TAKVİM!$L$77 -> 29 | M24: =TAKVİM!$M$77 | N24: =TAKVİM!$N$77 | O24: =TAKVİM!$O$77 -> 5 | P24: =TAKVİM!$P$77 -> 12 | Q24: =TAKVİM!$Q$77 -> 19 | R24: =TAKVİM!$R$77 -> 26 | S24: =TAKVİM!$S$77 | T24: =TAKVİM!$T$77 -> 3 | U24: =TAKVİM!$U$77 -> 10 | V24: =TAKVİM!$V$77 -> 17 | W24: =TAKVİM!$W$77 -> 24 | X24: =TAKVİM!$X$77 -> 31 | Y24: =TAKVİM!$Y$77 | Z24: =TAKVİM!$Z$77 | AA24: =TAKVİM!$AA$77 -> 7 | AB24: =TAKVİM!$AB$77 -> 14 | AC24: =TAKVİM!$AC$77 -> 21 | AD24: =TAKVİM!$AD$77 -> 28 | AE24: =TAKVİM!$AE$77
A25: =TAKVİM!$A$78 -> Cuma | B25: =TAKVİM!$B$78 -> 4 | C25: =TAKVİM!$C$78 -> 11 | D25: =TAKVİM!$D$78 -> 18 | E25: =TAKVİM!$E$78 -> 25 | F25: =TAKVİM!$F$78 | G25: =TAKVİM!$G$78 | H25: =TAKVİM!$H$78 -> 2 | I25: =TAKVİM!$I$78 -> 9 | J25: =TAKVİM!$J$78 -> 16 | K25: =TAKVİM!$K$78 -> 23 | L25: =TAKVİM!$L$78 -> 30 | M25: =TAKVİM!$M$78 | N25: =TAKVİM!$N$78 | O25: =TAKVİM!$O$78 -> 6 | P25: =TAKVİM!$P$78 -> 13 | Q25: =TAKVİM!$Q$78 -> 20 | R25: =TAKVİM!$R$78 -> 27 | S25: =TAKVİM!$S$78 | T25: =TAKVİM!$T$78 -> 4 | U25: =TAKVİM!$U$78 -> 11 | V25: =TAKVİM!$V$78 -> 18 | W25: =TAKVİM!$W$78 -> 25 | X25: =TAKVİM!$X$78 | Y25: =TAKVİM!$Y$78 | Z25: =TAKVİM!$Z$78 -> 1 | AA25: =TAKVİM!$AA$78 -> 8 | AB25: =TAKVİM!$AB$78 -> 15 | AC25: =TAKVİM!$AC$78 -> 22 | AD25: =TAKVİM!$AD$78 -> 29 | AE25: =TAKVİM!$AE$78
A26: =TAKVİM!$A$79 -> Cumartesi | B26: =TAKVİM!$B$79 -> 5 | C26: =TAKVİM!$C$79 -> 12 | D26: =TAKVİM!$D$79 -> 19 | E26: =TAKVİM!$E$79 -> 26 | F26: =TAKVİM!$F$79 | G26: =TAKVİM!$G$79 | H26: =TAKVİM!$H$79 -> 3 | I26: =TAKVİM!$I$79 -> 10 | J26: =TAKVİM!$J$79 -> 17 | K26: =TAKVİM!$K$79 -> 24 | L26: =TAKVİM!$L$79 -> 31 | M26: =TAKVİM!$M$79 | N26: =TAKVİM!$N$79 | O26: =TAKVİM!$O$79 -> 7 | P26: =TAKVİM!$P$79 -> 14 | Q26: =TAKVİM!$Q$79 -> 21 | R26: =TAKVİM!$R$79 -> 28 | S26: =TAKVİM!$S$79 | T26: =TAKVİM!$T$79 -> 5 | U26: =TAKVİM!$U$79 -> 12 | V26: =TAKVİM!$V$79 -> 19 | W26: =TAKVİM!$W$79 -> 26 | X26: =TAKVİM!$X$79 | Y26: =TAKVİM!$Y$79 | Z26: =TAKVİM!$Z$79 -> 2 | AA26: =TAKVİM!$AA$79 -> 9 | AB26: =TAKVİM!$AB$79 -> 16 | AC26: =TAKVİM!$AC$79 -> 23 | AD26: =TAKVİM!$AD$79 -> 30 | AE26: =TAKVİM!$AE$79
A27: =TAKVİM!$A$80 -> Pazar | B27: =TAKVİM!$B$80 -> 6 | C27: =TAKVİM!$C$80 -> 13 | D27: =TAKVİM!$D$80 -> 20 | E27: =TAKVİM!$E$80 -> 27 | F27: =TAKVİM!$F$80 | G27: =TAKVİM!$G$80 | H27: =TAKVİM!$H$80 -> 4 | I27: =TAKVİM!$I$80 -> 11 | J27: =TAKVİM!$J$80 -> 18 | K27: =TAKVİM!$K$80 -> 25 | L27: =TAKVİM!$L$80 | M27: =TAKVİM!$M$80 | N27: =TAKVİM!$N$80 -> 1 | O27: =TAKVİM!$O$80 -> 8 | P27: =TAKVİM!$P$80 -> 15 | Q27: =TAKVİM!$Q$80 -> 22 | R27: =TAKVİM!$R$80 -> 29 | S27: =TAKVİM!$S$80 | T27: =TAKVİM!$T$80 -> 6 | U27: =TAKVİM!$U$80 -> 13 | V27: =TAKVİM!$V$80 -> 20 | W27: =TAKVİM!$W$80 -> 27 | X27: =TAKVİM!$X$80 | Y27: =TAKVİM!$Y$80 | Z27: =TAKVİM!$Z$80 -> 3 | AA27: =TAKVİM!$AA$80 -> 10 | AB27: =TAKVİM!$AB$80 -> 17 | AC27: =TAKVİM!$AC$80 -> 24 | AD27: =TAKVİM!$AD$80 -> 31 | AE27: =TAKVİM!$AE$80
A28: =TAKVİM!$A$81 -> Günler | B28: =TAKVİM!$B$81 -> Şubat 2027 | H28: =TAKVİM!$H$81 -> Mart 2027 | N28: =TAKVİM!$N$81 -> Nisan 2027 | T28: =TAKVİM!$T$81 -> Mayıs 2027 | Z28: =TAKVİM!$Z$81 -> Haziran 2027
A29: =TAKVİM!$A$82 -> Pazartesi | B29: =TAKVİM!$B$82 -> 1 | C29: =TAKVİM!$C$82 -> 8 | D29: =TAKVİM!$D$82 -> 15 | E29: =TAKVİM!$E$82 -> 22 | F29: =TAKVİM!$F$82 | G29: =TAKVİM!$G$82 | H29: =TAKVİM!$H$82 -> 1 | I29: =TAKVİM!$I$82 -> 8 | J29: =TAKVİM!$J$82 -> 15 | K29: =TAKVİM!$K$82 -> 22 | L29: =TAKVİM!$L$82 -> 29 | M29: =TAKVİM!$M$82 | N29: =TAKVİM!$N$82 | O29: =TAKVİM!$O$82 -> 5 | P29: =TAKVİM!$P$82 -> 12 | Q29: =TAKVİM!$Q$82 -> 19 | R29: =TAKVİM!$R$82 -> 26 | S29: =TAKVİM!$S$82 | T29: =TAKVİM!$T$82 | U29: =TAKVİM!$U$82 -> 3 | V29: =TAKVİM!$V$82 -> 10 | W29: =TAKVİM!$W$82 -> 17 | X29: =TAKVİM!$X$82 -> 24 | Y29: =TAKVİM!$Y$82 -> 31 | Z29: =TAKVİM!$Z$82 | AA29: =TAKVİM!$AA$82 -> 7 | AB29: =TAKVİM!$AB$82 -> 14 | AC29: =TAKVİM!$AC$82 -> 21 | AD29: =TAKVİM!$AD$82 -> 28 | AE29: =TAKVİM!$AE$82
A30: =TAKVİM!$A$83 -> Salı | B30: =TAKVİM!$B$83 -> 2 | C30: =TAKVİM!$C$83 -> 9 | D30: =TAKVİM!$D$83 -> 16 | E30: =TAKVİM!$E$83 -> 23 | F30: =TAKVİM!$F$83 | G30: =TAKVİM!$G$83 | H30: =TAKVİM!$H$83 -> 2 | I30: =TAKVİM!$I$83 -> 9 | J30: =TAKVİM!$J$83 -> 16 | K30: =TAKVİM!$K$83 -> 23 | L30: =TAKVİM!$L$83 -> 30 | M30: =TAKVİM!$M$83 | N30: =TAKVİM!$N$83 | O30: =TAKVİM!$O$83 -> 6 | P30: =TAKVİM!$P$83 -> 13 | Q30: =TAKVİM!$Q$83 -> 20 | R30: =TAKVİM!$R$83 -> 27 | S30: =TAKVİM!$S$83 | T30: =TAKVİM!$T$83 | U30: =TAKVİM!$U$83 -> 4 | V30: =TAKVİM!$V$83 -> 11 | W30: =TAKVİM!$W$83 -> 18 | X30: =TAKVİM!$X$83 -> 25 | Y30: =TAKVİM!$Y$83 | Z30: =TAKVİM!$Z$83 -> 1 | AA30: =TAKVİM!$AA$83 -> 8 | AB30: =TAKVİM!$AB$83 -> 15 | AC30: =TAKVİM!$AC$83 -> 22 | AD30: =TAKVİM!$AD$83 -> 29 | AE30: =TAKVİM!$AE$83
A31: =TAKVİM!$A$84 -> Çarşamba | B31: =TAKVİM!$B$84 -> 3 | C31: =TAKVİM!$C$84 -> 10 | D31: =TAKVİM!$D$84 -> 17 | E31: =TAKVİM!$E$84 -> 24 | F31: =TAKVİM!$F$84 | G31: =TAKVİM!$G$84 | H31: =TAKVİM!$H$84 -> 3 | I31: =TAKVİM!$I$84 -> 10 | J31: =TAKVİM!$J$84 -> 17 | K31: =TAKVİM!$K$84 -> 24 | L31: =TAKVİM!$L$84 -> 31 | M31: =TAKVİM!$M$84 | N31: =TAKVİM!$N$84 | O31: =TAKVİM!$O$84 -> 7 | P31: =TAKVİM!$P$84 -> 14 | Q31: =TAKVİM!$Q$84 -> 21 | R31: =TAKVİM!$R$84 -> 28 | S31: =TAKVİM!$S$84 | T31: =TAKVİM!$T$84 | U31: =TAKVİM!$U$84 -> 5 | V31: =TAKVİM!$V$84 -> 12 | W31: =TAKVİM!$W$84 -> 19 | X31: =TAKVİM!$X$84 -> 26 | Y31: =TAKVİM!$Y$84 | Z31: =TAKVİM!$Z$84 -> 2 | AA31: =TAKVİM!$AA$84 -> 9 | AB31: =TAKVİM!$AB$84 -> 16 | AC31: =TAKVİM!$AC$84 -> 23 | AD31: =TAKVİM!$AD$84 -> 30 | AE31: =TAKVİM!$AE$84
A32: =TAKVİM!$A$85 -> Perşembe | B32: =TAKVİM!$B$85 -> 4 | C32: =TAKVİM!$C$85 -> 11 | D32: =TAKVİM!$D$85 -> 18 | E32: =TAKVİM!$E$85 -> 25 | F32: =TAKVİM!$F$85 | G32: =TAKVİM!$G$85 | H32: =TAKVİM!$H$85 -> 4 | I32: =TAKVİM!$I$85 -> 11 | J32: =TAKVİM!$J$85 -> 18 | K32: =TAKVİM!$K$85 -> 25 | L32: =TAKVİM!$L$85 | M32: =TAKVİM!$M$85 | N32: =TAKVİM!$N$85 -> 1 | O32: =TAKVİM!$O$85 -> 8 | P32: =TAKVİM!$P$85 -> 15 | Q32: =TAKVİM!$Q$85 -> 22 | R32: =TAKVİM!$R$85 -> 29 | S32: =TAKVİM!$S$85 | T32: =TAKVİM!$T$85 | U32: =TAKVİM!$U$85 -> 6 | V32: =TAKVİM!$V$85 -> 13 | W32: =TAKVİM!$W$85 -> 20 | X32: =TAKVİM!$X$85 -> 27 | Y32: =TAKVİM!$Y$85 | Z32: =TAKVİM!$Z$85 -> 3 | AA32: =TAKVİM!$AA$85 -> 10 | AB32: =TAKVİM!$AB$85 -> 17 | AC32: =TAKVİM!$AC$85 -> 24 | AD32: =TAKVİM!$AD$85 | AE32: =TAKVİM!$AE$85
A33: =TAKVİM!$A$86 -> Cuma | B33: =TAKVİM!$B$86 -> 5 | C33: =TAKVİM!$C$86 -> 12 | D33: =TAKVİM!$D$86 -> 19 | E33: =TAKVİM!$E$86 -> 26 | F33: =TAKVİM!$F$86 | G33: =TAKVİM!$G$86 | H33: =TAKVİM!$H$86 -> 5 | I33: =TAKVİM!$I$86 -> 12 | J33: =TAKVİM!$J$86 -> 19 | K33: =TAKVİM!$K$86 -> 26 | L33: =TAKVİM!$L$86 | M33: =TAKVİM!$M$86 | N33: =TAKVİM!$N$86 -> 2 | O33: =TAKVİM!$O$86 -> 9 | P33: =TAKVİM!$P$86 -> 16 | Q33: =TAKVİM!$Q$86 -> 23 | R33: =TAKVİM!$R$86 -> 30 | S33: =TAKVİM!$S$86 | T33: =TAKVİM!$T$86 | U33: =TAKVİM!$U$86 -> 7 | V33: =TAKVİM!$V$86 -> 14 | W33: =TAKVİM!$W$86 -> 21 | X33: =TAKVİM!$X$86 -> 28 | Y33: =TAKVİM!$Y$86 | Z33: =TAKVİM!$Z$86 -> 4 | AA33: =TAKVİM!$AA$86 -> 11 | AB33: =TAKVİM!$AB$86 -> 18 | AC33: =TAKVİM!$AC$86 -> 25 | AD33: =TAKVİM!$AD$86 | AE33: =TAKVİM!$AE$86
A34: =TAKVİM!$A$87 -> Cumartesi | B34: =TAKVİM!$B$87 -> 6 | C34: =TAKVİM!$C$87 -> 13 | D34: =TAKVİM!$D$87 -> 20 | E34: =TAKVİM!$E$87 -> 27 | F34: =TAKVİM!$F$87 | G34: =TAKVİM!$G$87 | H34: =TAKVİM!$H$87 -> 6 | I34: =TAKVİM!$I$87 -> 13 | J34: =TAKVİM!$J$87 -> 20 | K34: =TAKVİM!$K$87 -> 27 | L34: =TAKVİM!$L$87 | M34: =TAKVİM!$M$87 | N34: =TAKVİM!$N$87 -> 3 | O34: =TAKVİM!$O$87 -> 10 | P34: =TAKVİM!$P$87 -> 17 | Q34: =TAKVİM!$Q$87 -> 24 | R34: =TAKVİM!$R$87 | S34: =TAKVİM!$S$87 | T34: =TAKVİM!$T$87 -> 1 | U34: =TAKVİM!$U$87 -> 8 | V34: =TAKVİM!$V$87 -> 15 | W34: =TAKVİM!$W$87 -> 22 | X34: =TAKVİM!$X$87 -> 29 | Y34: =TAKVİM!$Y$87 | Z34: =TAKVİM!$Z$87 -> 5 | AA34: =TAKVİM!$AA$87 -> 12 | AB34: =TAKVİM!$AB$87 -> 19 | AC34: =TAKVİM!$AC$87 -> 26 | AD34: =TAKVİM!$AD$87 | AE34: =TAKVİM!$AE$87
A35: =TAKVİM!$A$88 -> Pazar | B35: =TAKVİM!$B$88 -> 7 | C35: =TAKVİM!$C$88 -> 14 | D35: =TAKVİM!$D$88 -> 21 | E35: =TAKVİM!$E$88 -> 28 | F35: =TAKVİM!$F$88 | G35: =TAKVİM!$G$88 | H35: =TAKVİM!$H$88 -> 7 | I35: =TAKVİM!$I$88 -> 14 | J35: =TAKVİM!$J$88 -> 21 | K35: =TAKVİM!$K$88 -> 28 | L35: =TAKVİM!$L$88 | M35: =TAKVİM!$M$88 | N35: =TAKVİM!$N$88 -> 4 | O35: =TAKVİM!$O$88 -> 11 | P35: =TAKVİM!$P$88 -> 18 | Q35: =TAKVİM!$Q$88 -> 25 | R35: =TAKVİM!$R$88 | S35: =TAKVİM!$S$88 | T35: =TAKVİM!$T$88 -> 2 | U35: =TAKVİM!$U$88 -> 9 | V35: =TAKVİM!$V$88 -> 16 | W35: =TAKVİM!$W$88 -> 23 | X35: =TAKVİM!$X$88 -> 30 | Y35: =TAKVİM!$Y$88 | Z35: =TAKVİM!$Z$88 -> 6 | AA35: =TAKVİM!$AA$88 -> 13 | AB35: =TAKVİM!$AB$88 -> 20 | AC35: =TAKVİM!$AC$88 -> 27 | AD35: =TAKVİM!$AD$88 | AE35: =TAKVİM!$AE$88
A37: TARİH | D37: KAZANIMLAR | L37: KONULAR | R37: ÖĞRENME-ÖĞRETME YÖNTEM VE TEKNİKLERİ | W37: KULLANILAN EĞİTİM TEKNOLOJİLERİ, ARAÇ VE GEREÇLER | AD37: DEĞERLENDİRME
A38: =TAKVİM!$B$29 -> 14-18 Eylül | D38: 1. Kuralların gerekliliğini ve işlevini toplumsal fayda açısından tartışır. • Sınıf ortamında sunum yapmalarına yönelik bir etkinlik planlanarak öğrencilerin iletişim engellerini deneyimlemeleri sağlanır. • Öğrencilerin, etkili iletişim için sınıfta uyulması gereken kurallara arkadaşlarıyla birlikte karar vermeleri sağlanır. • Öğrencilerle birlikte oluşturulacak sınıf anlaşmasının görünür ve kalıcı olması için gerekli önlemler alınır. | L38: MESLEK ETİĞİ VE AHİLİK 1. Kurallar ve İşlevi | R38: Soru-Cevap, Grup Çalışması, Tartışma, Proje Tabanlı Öğrenme, Bireyselleştirilmiş Öğretim | W38: Etkileşimli tahta/projeksiyon, mesleki gelişim dersi tasarım odaklı çalışma defteri, internet, kütüphane
A39: =TAKVİM!$B$30 -> 21-25 Eylül | D39: 2. Meslek etiği ve ahilik ile ilgili temel kavramları ve ahilik ilkelerini açıklar. • Meslek etiği ve ahilik ile ilgili temel kavram ve ilkelerin görselleri sınıfta paylaşılarak bu kavramların hayatımızdaki yeri tartışılır. • Öğrencilerin, meslek etiği ve ahilik ile ilgili örnek hikâyelerden hareketle ahilik ve meslek etiği ilkelerini kavraması sağlanır. | L39: 2. Meslek Etiği ve Ahilik İle İlgili Temel Kavramlar | R39: Soru-Cevap, Grup Çalışması, Tartışma, Proje Tabanlı Öğrenme, Bireyselleştirilmiş Öğretim | W39: Etkileşimli tahta/projeksiyon, mesleki gelişim dersi tasarım odaklı çalışma defteri, internet, kütüphane
A40: =TAKVİM!$B$31 -> 28 Eylül - 02 Ekim | D40: 3. Geçmişten günümüze meslek kuruluşları ve ahiliğin tarihsel gelişimini açıklar. • Sınıfta ahilik teşkilatını anlatan örnek bir video izletilerek öğrencilerin ahiliğin temel ilke ve amaçlarını açıklaması sağlanır. • Öğrencilerden, ahiliğin tarihçesi hakkında araştırma yapmaları ve elde ettikleri bilgileri sınıfta sunmaları istenir. | L40: 3. Ahiliğin Tarihsel Gelişimi | R40: Soru-Cevap, Grup Çalışması, Tartışma, Proje Tabanlı Öğrenme, Bireyselleştirilmiş Öğretim | W40: Etkileşimli tahta/projeksiyon, mesleki gelişim dersi tasarım odaklı çalışma defteri, internet, kütüphane
A41: =TAKVİM!$B$32 -> 05-09 Ekim | D41: 1. Tasarım odaklı düşünme yaklaşımının ilkelerini ve basamaklarını kullanır. • Öğrencilerin, tasarım odaklı düşünmenin temel ilkelerini kavramaları sağlanır. • Öğrenciler, ders dışı zamanlarda da süreci takip etmeleri için teşvik edilir. | L41: İŞ SAĞLIĞI VE GÜVENLİĞİ 1. Tasarım Odaklı Düşünme | R41: Soru-Cevap, Grup Çalışması, Tartışma, Proje Tabanlı Öğrenme, Bireyselleştirilmiş Öğretim | W41: Etkileşimli tahta/projeksiyon, mesleki gelişim dersi tasarım odaklı çalışma defteri, internet, kütüphane
A42: =TAKVİM!$B$33 -> 12-16 Ekim | D42: 2. İş yerinde sağlık ve güvenliği tehdit eden unsurları ve giderici tedbirleri açıklar. • İş sağlığı ve güvenliği ile ilgili bir senaryo üzerinden işyerinde sağlık ve güvenliği tehdit eden unsurları analiz etmeleri sağlanır. • Öğrencilerden, iş sağlığı ve güvenliğine uygun şartlar için dikkate alınması gereken unsurları bir sunumla açıklamaları istenir. | L42: 2. İş Sağlığı ve Güvenliğini Tehdit Eden Unsurlar | R42: Soru-Cevap, Grup Çalışması, Tartışma, Proje Tabanlı Öğrenme, Bireyselleştirilmiş Öğretim | W42: Etkileşimli tahta/projeksiyon, mesleki gelişim dersi tasarım odaklı çalışma defteri, internet, kütüphane
A43: =TAKVİM!$B$34 -> 19-23 Ekim | D43: 3. İş yerinde ortaya çıkabilecek kaza, yaralanma ve yangınlara karşı alınması gereken tedbirleri açıklar. • Öğrencilerin, gözlem, görüşme gibi veri toplama yöntemleriyle iş yerlerinde veya atölyelerde alınan tedbirler hakkında bilgi sahibi olmaları sağlanır. | L43: 3. İş Yerinde Ortaya Çıkabilecek Kaza, Yaralanma ve Yangınlara Karşı Alınması Gereken Tedbirler | R43: Soru-Cevap, Grup Çalışması, Tartışma, Proje Tabanlı Öğrenme, Bireyselleştirilmiş Öğretim | W43: Etkileşimli tahta/projeksiyon, mesleki gelişim dersi tasarım odaklı çalışma defteri, internet, kütüphane
A44: =TAKVİM!$B$35 -> 26-30 Ekim | D44: 4. Meslek hastalıklarının sebeplerini, alınması gereken önlemleri açıklar. • Öğrencilerin, meslek hastalıkları ile ilgili bir senaryo aracılığıyla meslek hastalıkları ile güvenli atölye ortamı arasındaki ilişkiyi kavramaları sağlanır. 29 EKİM Cumhuriyet Bayramı | L44: 4. Meslek Hastalıkları ve Alınması Gereken Önlemler | R44: Soru-Cevap, Grup Çalışması, Tartışma, Proje Tabanlı Öğrenme, Bireyselleştirilmiş Öğretim | W44: Etkileşimli tahta/projeksiyon, mesleki gelişim dersi tasarım odaklı çalışma defteri, internet, kütüphane
A45: =TAKVİM!$B$36 -> 02-06 Kasım | D45: • Bireysel olarak İSG ile ilgili fikirlerini planlayarak kendi öğrenmesinin sorumluluğunu alır. • İSG ile ilgili önlem ve tedbirleri artırmak için bir senaryodan yola çıkarak kendi önerilerini geliştirmeleri ve süreçte sorumluluk almaları sağlanır. | L45: 5. Bireysel İSG Planlaması ile Öğrenme Sorumluluğu Alma | R45: Soru-Cevap, Grup Çalışması, Tartışma, Proje Tabanlı Öğrenme, Bireyselleştirilmiş Öğretim | W45: Etkileşimli tahta/projeksiyon, mesleki gelişim dersi tasarım odaklı çalışma defteri, internet, kütüphane
...

Sheet TEKNİK RESİM AMP 9A
H1: YILLIK DERS PLANI
A3: EĞİTİM-ÖĞRETİM YILI | G3: =TAKVİM!$B$4 -> 2026-2027 Eğitim-Öğretim Yılı | P3: OKUL | U3: =TAKVİM!$B$3 -> Soma Mesleki ve Teknik Anadolu Lisesi
A4: DERS | G4: : TEKNİK RESİM | P4: ALAN/DAL | U4: : Makine ve Tasarım Teknolojisi Alanı
A5: DERS SAATİ | G5: : 3 SAAT | P5: SINIF | U5: : AMP 9A
A7: 1.DÖNEM SINAV TARİHLERİ | P7: 2.DÖNEM SINAV TARİHLERİ
A8: 1.Dönem 1.Sınav Tarihi | G8: =TAKVİM!$B$7 -> 13.11.2026 | P8: 2.Dönem 1.Sınav Tarihi | U8: =TAKVİM!$B$9 -> 19.03.2027
A9: 1.Dönem 2.Sınav Tarihi | G9: =TAKVİM!$B$8 -> 08.01.2027 | P9: 2.Dönem 2.Sınav Tarihi | U9: =TAKVİM!$B$10 -> 14.05.2027
A11: 1.DÖNEM ÖNEMLİ GÜN VE HAFTALAR | P11: 2.DÖNEM ÖNEMLİ GÜN VE HAFTALAR
A12: 1.Yarıyıl Başlangıcı | G12: =TAKVİM!$B$13 -> 2026-09-14 00:00:00 | P12: 2.Yarıyıl Başlangıcı | U12: =TAKVİM!$B$14 -> 2027-02-08 00:00:00
A13: Cumhuriyet Bayramı | G13: =TAKVİM!$B$15 -> 29.10.2026 | P13: 2. Dönem Ara Tatil | U13: =TAKVİM!$B$19 -> 08-12 Mart
A14: Atatürk'ü Anma Günü ve Atatürk Haftası | G14: =TAKVİM!$B$17 -> 10.11.2026 | P14: 23 Nisan Ulusal Egemenlik ve Çocuk Bayramı | U14: =TAKVİM!$B$18 -> 23.04.2027
A15: 1. Dönem Ara Tatil | G15: =TAKVİM!$B$16 -> 16-20 Kasım | P15: 19 Mayıs Atatürk'ü Anma Gençlik ve Spor Bayramı | U15: =TAKVİM!$B$20 -> 19.05.2027
A16: Yılbaşı Tatili | G16: =TAKVİM!$B$21 -> 01.01.2027 | P16: Ramazan Bayramı | U16: =TAKVİM!$B$22 -> 20.03.2027
A17: Yarıyıl Tatili | G17: =TAKVİM!$B$23 -> 25 OCAK - 05 ŞUBAT 2027 | P17: Eğitim-Öğretim Yılının Sonu | U17: =TAKVİM!$B$24 -> 25.06.2027
A19: 2026-2027 EĞİTİM-ÖĞRETİM YILI İŞGÜNÜ TAKVİMİ
A20: =TAKVİM!$A$73 -> Günler | B20: =TAKVİM!$B$73 -> Eylül 2026 | H20: =TAKVİM!$H$73 -> Ekim 2026 | N20: =TAKVİM!$N$73 -> Kasım 2026 | T20: =TAKVİM!$T$73 -> Aralık 2026 | Z20: =TAKVİM!$Z$73 -> Ocak 2027
A21: =TAKVİM!$A$74 -> Pazartesi | B21: =TAKVİM!$B$74 | C21: =TAKVİM!$C$74 -> 7 | D21: =TAKVİM!$D$74 -> 14 | E21: =TAKVİM!$E$74 -> 21 | F21: =TAKVİM!$F$74 -> 28 | G21: =TAKVİM!$G$74 | H21: =TAKVİM!$H$74 | I21: =TAKVİM!$I$74 -> 5 | J21: =TAKVİM!$J$74 -> 12 | K21: =TAKVİM!$K$74 -> 19 | L21: =TAKVİM!$L$74 -> 26 | M21: =TAKVİM!$M$74 | N21: =TAKVİM!$N$74 | O21: =TAKVİM!$O$74 -> 2 | P21: =TAKVİM!$P$74 -> 9 | Q21: =TAKVİM!$Q$74 -> 16 | R21: =TAKVİM!$R$74 -> 23 | S21: =TAKVİM!$S$74 -> 30 | T21: =TAKVİM!$T$74 | U21: =TAKVİM!$U$74 -> 7 | V21: =TAKVİM!$V$74 -> 14 | W21: =TAKVİM!$W$74 -> 21 | X21: =TAKVİM!$X$74 -> 28 | Y21: =TAKVİM!$Y$74 | Z21: =TAKVİM!$Z$74 | AA21: =TAKVİM!$AA$74 -> 4 | AB21: =TAKVİM!$AB$74 -> 11 | AC21: =TAKVİM!$AC$74 -> 18 | AD21: =TAKVİM!$AD$74 -> 25 | AE21: =TAKVİM!$AE$74
A22: =TAKVİM!$A$75 -> Salı | B22: =TAKVİM!$B$75 -> 1 | C22: =TAKVİM!$C$75 -> 8 | D22: =TAKVİM!$D$75 -> 15 | E22: =TAKVİM!$E$75 -> 22 | F22: =TAKVİM!$F$75 -> 29 | G22: =TAKVİM!$G$75 | H22: =TAKVİM!$H$75 | I22: =TAKVİM!$I$75 -> 6 | J22: =TAKVİM!$J$75 -> 13 | K22: =TAKVİM!$K$75 -> 20 | L22: =TAKVİM!$L$75 -> 27 | M22: =TAKVİM!$M$75 | N22: =TAKVİM!$N$75 | O22: =TAKVİM!$O$75 -> 3 | P22: =TAKVİM!$P$75 -> 10 | Q22: =TAKVİM!$Q$75 -> 17 | R22: =TAKVİM!$R$75 -> 24 | S22: =TAKVİM!$S$75 | T22: =TAKVİM!$T$75 -> 1 | U22: =TAKVİM!$U$75 -> 8 | V22: =TAKVİM!$V$75 -> 15 | W22: =TAKVİM!$W$75 -> 22 | X22: =TAKVİM!$X$75 -> 29 | Y22: =TAKVİM!$Y$75 | Z22: =TAKVİM!$Z$75 | AA22: =TAKVİM!$AA$75 -> 5 | AB22: =TAKVİM!$AB$75 -> 12 | AC22: =TAKVİM!$AC$75 -> 19 | AD22: =TAKVİM!$AD$75 -> 26 | AE22: =TAKVİM!$AE$75
A23: =TAKVİM!$A$76 -> Çarşamba | B23: =TAKVİM!$B$76 -> 2 | C23: =TAKVİM!$C$76 -> 9 | D23: =TAKVİM!$D$76 -> 16 | E23: =TAKVİM!$E$76 -> 23 | F23: =TAKVİM!$F$76 -> 30 | G23: =TAKVİM!$G$76 | H23: =TAKVİM!$H$76 | I23: =TAKVİM!$I$76 -> 7 | J23: =TAKVİM!$J$76 -> 14 | K23: =TAKVİM!$K$76 -> 21 | L23: =TAKVİM!$L$76 -> 28 | M23: =TAKVİM!$M$76 | N23: =TAKVİM!$N$76 | O23: =TAKVİM!$O$76 -> 4 | P23: =TAKVİM!$P$76 -> 11 | Q23: =TAKVİM!$Q$76 -> 18 | R23: =TAKVİM!$R$76 -> 25 | S23: =TAKVİM!$S$76 | T23: =TAKVİM!$T$76 -> 2 | U23: =TAKVİM!$U$76 -> 9 | V23: =TAKVİM!$V$76 -> 16 | W23: =TAKVİM!$W$76 -> 23 | X23: =TAKVİM!$X$76 -> 30 | Y23: =TAKVİM!$Y$76 | Z23: =TAKVİM!$Z$76 | AA23: =TAKVİM!$AA$76 -> 6 | AB23: =TAKVİM!$AB$76 -> 13 | AC23: =TAKVİM!$AC$76 -> 20 | AD23: =TAKVİM!$AD$76 -> 27 | AE23: =TAKVİM!$AE$76
A24: =TAKVİM!$A$77 -> Perşembe | B24: =TAKVİM!$B$77 -> 3 | C24: =TAKVİM!$C$77 -> 10 | D24: =TAKVİM!$D$77 -> 17 | E24: =TAKVİM!$E$77 -> 24 | F24: =TAKVİM!$F$77 | G24: =TAKVİM!$G$77 | H24: =TAKVİM!$H$77 -> 1 | I24: =TAKVİM!$I$77 -> 8 | J24: =TAKVİM!$J$77 -> 15 | K24: =TAKVİM!$K$77 -> 22 | L24: =TAKVİM!$L$77 -> 29 | M24: =TAKVİM!$M$77 | N24: =TAKVİM!$N$77 | O24: =TAKVİM!$O$77 -> 5 | P24: =TAKVİM!$P$77 -> 12 | Q24: =TAKVİM!$Q$77 -> 19 | R24: =TAKVİM!$R$77 -> 26 | S24: =TAKVİM!$S$77 | T24: =TAKVİM!$T$77 -> 3 | U24: =TAKVİM!$U$77 -> 10 | V24: =TAKVİM!$V$77 -> 17 | W24: =TAKVİM!$W$77 -> 24 | X24: =TAKVİM!$X$77 -> 31 | Y24: =TAKVİM!$Y$77 | Z24: =TAKVİM!$Z$77 | AA24: =TAKVİM!$AA$77 -> 7 | AB24: =TAKVİM!$AB$77 -> 14 | AC24: =TAKVİM!$AC$77 -> 21 | AD24: =TAKVİM!$AD$77 -> 28 | AE24: =TAKVİM!$AE$77
A25: =TAKVİM!$A$78 -> Cuma | B25: =TAKVİM!$B$78 -> 4 | C25: =TAKVİM!$C$78 -> 11 | D25: =TAKVİM!$D$78 -> 18 | E25: =TAKVİM!$E$78 -> 25 | F25: =TAKVİM!$F$78 | G25: =TAKVİM!$G$78 | H25: =TAKVİM!$H$78 -> 2 | I25: =TAKVİM!$I$78 -> 9 | J25: =TAKVİM!$J$78 -> 16 | K25: =TAKVİM!$K$78 -> 23 | L25: =TAKVİM!$L$78 -> 30 | M25: =TAKVİM!$M$78 | N25: =TAKVİM!$N$78 | O25: =TAKVİM!$O$78 -> 6 | P25: =TAKVİM!$P$78 -> 13 | Q25: =TAKVİM!$Q$78 -> 20 | R25: =TAKVİM!$R$78 -> 27 | S25: =TAKVİM!$S$78 | T25: =TAKVİM!$T$78 -> 4 | U25: =TAKVİM!$U$78 -> 11 | V25: =TAKVİM!$V$78 -> 18 | W25: =TAKVİM!$W$78 -> 25 | X25: =TAKVİM!$X$78 | Y25: =TAKVİM!$Y$78 | Z25: =TAKVİM!$Z$78 -> 1 | AA25: =TAKVİM!$AA$78 -> 8 | AB25: =TAKVİM!$AB$78 -> 15 | AC25: =TAKVİM!$AC$78 -> 22 | AD25: =TAKVİM!$AD$78 -> 29 | AE25: =TAKVİM!$AE$78
A26: =TAKVİM!$A$79 -> Cumartesi | B26: =TAKVİM!$B$79 -> 5 | C26: =TAKVİM!$C$79 -> 12 | D26: =TAKVİM!$D$79 -> 19 | E26: =TAKVİM!$E$79 -> 26 | F26: =TAKVİM!$F$79 | G26: =TAKVİM!$G$79 | H26: =TAKVİM!$H$79 -> 3 | I26: =TAKVİM!$I$79 -> 10 | J26: =TAKVİM!$J$79 -> 17 | K26: =TAKVİM!$K$79 -> 24 | L26: =TAKVİM!$L$79 -> 31 | M26: =TAKVİM!$M$79 | N26: =TAKVİM!$N$79 | O26: =TAKVİM!$O$79 -> 7 | P26: =TAKVİM!$P$79 -> 14 | Q26: =TAKVİM!$Q$79 -> 21 | R26: =TAKVİM!$R$79 -> 28 | S26: =TAKVİM!$S$79 | T26: =TAKVİM!$T$79 -> 5 | U26: =TAKVİM!$U$79 -> 12 | V26: =TAKVİM!$V$79 -> 19 | W26: =TAKVİM!$W$79 -> 26 | X26: =TAKVİM!$X$79 | Y26: =TAKVİM!$Y$79 | Z26: =TAKVİM!$Z$79 -> 2 | AA26: =TAKVİM!$AA$79 -> 9 | AB26: =TAKVİM!$AB$79 -> 16 | AC26: =TAKVİM!$AC$79 -> 23 | AD26: =TAKVİM!$AD$79 -> 30 | AE26: =TAKVİM!$AE$79
A27: =TAKVİM!$A$80 -> Pazar | B27: =TAKVİM!$B$80 -> 6 | C27: =TAKVİM!$C$80 -> 13 | D27: =TAKVİM!$D$80 -> 20 | E27: =TAKVİM!$E$80 -> 27 | F27: =TAKVİM!$F$80 | G27: =TAKVİM!$G$80 | H27: =TAKVİM!$H$80 -> 4 | I27: =TAKVİM!$I$80 -> 11 | J27: =TAKVİM!$J$80 -> 18 | K27: =TAKVİM!$K$80 -> 25 | L27: =TAKVİM!$L$80 | M27: =TAKVİM!$M$80 | N27: =TAKVİM!$N$80 -> 1 | O27: =TAKVİM!$O$80 -> 8 | P27: =TAKVİM!$P$80 -> 15 | Q27: =TAKVİM!$Q$80 -> 22 | R27: =TAKVİM!$R$80 -> 29 | S27: =TAKVİM!$S$80 | T27: =TAKVİM!$T$80 -> 6 | U27: =TAKVİM!$U$80 -> 13 | V27: =TAKVİM!$V$80 -> 20 | W27: =TAKVİM!$W$80 -> 27 | X27: =TAKVİM!$X$80 | Y27: =TAKVİM!$Y$80 | Z27: =TAKVİM!$Z$80 -> 3 | AA27: =TAKVİM!$AA$80 -> 10 | AB27: =TAKVİM!$AB$80 -> 17 | AC27: =TAKVİM!$AC$80 -> 24 | AD27: =TAKVİM!$AD$80 -> 31 | AE27: =TAKVİM!$AE$80
A28: =TAKVİM!$A$81 -> Günler | B28: =TAKVİM!$B$81 -> Şubat 2027 | H28: =TAKVİM!$H$81 -> Mart 2027 | N28: =TAKVİM!$N$81 -> Nisan 2027 | T28: =TAKVİM!$T$81 -> Mayıs 2027 | Z28: =TAKVİM!$Z$81 -> Haziran 2027
A29: =TAKVİM!$A$82 -> Pazartesi | B29: =TAKVİM!$B$82 -> 1 | C29: =TAKVİM!$C$82 -> 8 | D29: =TAKVİM!$D$82 -> 15 | E29: =TAKVİM!$E$82 -> 22 | F29: =TAKVİM!$F$82 | G29: =TAKVİM!$G$82 | H29: =TAKVİM!$H$82 -> 1 | I29: =TAKVİM!$I$82 -> 8 | J29: =TAKVİM!$J$82 -> 15 | K29: =TAKVİM!$K$82 -> 22 | L29: =TAKVİM!$L$82 -> 29 | M29: =TAKVİM!$M$82 | N29: =TAKVİM!$N$82 | O29: =TAKVİM!$O$82 -> 5 | P29: =TAKVİM!$P$82 -> 12 | Q29: =TAKVİM!$Q$82 -> 19 | R29: =TAKVİM!$R$82 -> 26 | S29: =TAKVİM!$S$82 | T29: =TAKVİM!$T$82 | U29: =TAKVİM!$U$82 -> 3 | V29: =TAKVİM!$V$82 -> 10 | W29: =TAKVİM!$W$82 -> 17 | X29: =TAKVİM!$X$82 -> 24 | Y29: =TAKVİM!$Y$82 -> 31 | Z29: =TAKVİM!$Z$82 | AA29: =TAKVİM!$AA$82 -> 7 | AB29: =TAKVİM!$AB$82 -> 14 | AC29: =TAKVİM!$AC$82 -> 21 | AD29: =TAKVİM!$AD$82 -> 28 | AE29: =TAKVİM!$AE$82
A30: =TAKVİM!$A$83 -> Salı | B30: =TAKVİM!$B$83 -> 2 | C30: =TAKVİM!$C$83 -> 9 | D30: =TAKVİM!$D$83 -> 16 | E30: =TAKVİM!$E$83 -> 23 | F30: =TAKVİM!$F$83 | G30: =TAKVİM!$G$83 | H30: =TAKVİM!$H$83 -> 2 | I30: =TAKVİM!$I$83 -> 9 | J30: =TAKVİM!$J$83 -> 16 | K30: =TAKVİM!$K$83 -> 23 | L30: =TAKVİM!$L$83 -> 30 | M30: =TAKVİM!$M$83 | N30: =TAKVİM!$N$83 | O30: =TAKVİM!$O$83 -> 6 | P30: =TAKVİM!$P$83 -> 13 | Q30: =TAKVİM!$Q$83 -> 20 | R30: =TAKVİM!$R$83 -> 27 | S30: =TAKVİM!$S$83 | T30: =TAKVİM!$T$83 | U30: =TAKVİM!$U$83 -> 4 | V30: =TAKVİM!$V$83 -> 11 | W30: =TAKVİM!$W$83 -> 18 | X30: =TAKVİM!$X$83 -> 25 | Y30: =TAKVİM!$Y$83 | Z30: =TAKVİM!$Z$83 -> 1 | AA30: =TAKVİM!$AA$83 -> 8 | AB30: =TAKVİM!$AB$83 -> 15 | AC30: =TAKVİM!$AC$83 -> 22 | AD30: =TAKVİM!$AD$83 -> 29 | AE30: =TAKVİM!$AE$83
A31: =TAKVİM!$A$84 -> Çarşamba | B31: =TAKVİM!$B$84 -> 3 | C31: =TAKVİM!$C$84 -> 10 | D31: =TAKVİM!$D$84 -> 17 | E31: =TAKVİM!$E$84 -> 24 | F31: =TAKVİM!$F$84 | G31: =TAKVİM!$G$84 | H31: =TAKVİM!$H$84 -> 3 | I31: =TAKVİM!$I$84 -> 10 | J31: =TAKVİM!$J$84 -> 17 | K31: =TAKVİM!$K$84 -> 24 | L31: =TAKVİM!$L$84 -> 31 | M31: =TAKVİM!$M$84 | N31: =TAKVİM!$N$84 | O31: =TAKVİM!$O$84 -> 7 | P31: =TAKVİM!$P$84 -> 14 | Q31: =TAKVİM!$Q$84 -> 21 | R31: =TAKVİM!$R$84 -> 28 | S31: =TAKVİM!$S$84 | T31: =TAKVİM!$T$84 | U31: =TAKVİM!$U$84 -> 5 | V31: =TAKVİM!$V$84 -> 12 | W31: =TAKVİM!$W$84 -> 19 | X31: =TAKVİM!$X$84 -> 26 | Y31: =TAKVİM!$Y$84 | Z31: =TAKVİM!$Z$84 -> 2 | AA31: =TAKVİM!$AA$84 -> 9 | AB31: =TAKVİM!$AB$84 -> 16 | AC31: =TAKVİM!$AC$84 -> 23 | AD31: =TAKVİM!$AD$84 -> 30 | AE31: =TAKVİM!$AE$84
A32: =TAKVİM!$A$85 -> Perşembe | B32: =TAKVİM!$B$85 -> 4 | C32: =TAKVİM!$C$85 -> 11 | D32: =TAKVİM!$D$85 -> 18 | E32: =TAKVİM!$E$85 -> 25 | F32: =TAKVİM!$F$85 | G32: =TAKVİM!$G$85 | H32: =TAKVİM!$H$85 -> 4 | I32: =TAKVİM!$I$85 -> 11 | J32: =TAKVİM!$J$85 -> 18 | K32: =TAKVİM!$K$85 -> 25 | L32: =TAKVİM!$L$85 | M32: =TAKVİM!$M$85 | N32: =TAKVİM!$N$85 -> 1 | O32: =TAKVİM!$O$85 -> 8 | P32: =TAKVİM!$P$85 -> 15 | Q32: =TAKVİM!$Q$85 -> 22 | R32: =TAKVİM!$R$85 -> 29 | S32: =TAKVİM!$S$85 | T32: =TAKVİM!$T$85 | U32: =TAKVİM!$U$85 -> 6 | V32: =TAKVİM!$V$85 -> 13 | W32: =TAKVİM!$W$85 -> 20 | X32: =TAKVİM!$X$85 -> 27 | Y32: =TAKVİM!$Y$85 | Z32: =TAKVİM!$Z$85 -> 3 | AA32: =TAKVİM!$AA$85 -> 10 | AB32: =TAKVİM!$AB$85 -> 17 | AC32: =TAKVİM!$AC$85 -> 24 | AD32: =TAKVİM!$AD$85 | AE32: =TAKVİM!$AE$85
A33: =TAKVİM!$A$86 -> Cuma | B33: =TAKVİM!$B$86 -> 5 | C33: =TAKVİM!$C$86 -> 12 | D33: =TAKVİM!$D$86 -> 19 | E33: =TAKVİM!$E$86 -> 26 | F33: =TAKVİM!$F$86 | G33: =TAKVİM!$G$86 | H33: =TAKVİM!$H$86 -> 5 | I33: =TAKVİM!$I$86 -> 12 | J33: =TAKVİM!$J$86 -> 19 | K33: =TAKVİM!$K$86 -> 26 | L33: =TAKVİM!$L$86 | M33: =TAKVİM!$M$86 | N33: =TAKVİM!$N$86 -> 2 | O33: =TAKVİM!$O$86 -> 9 | P33: =TAKVİM!$P$86 -> 16 | Q33: =TAKVİM!$Q$86 -> 23 | R33: =TAKVİM!$R$86 -> 30 | S33: =TAKVİM!$S$86 | T33: =TAKVİM!$T$86 | U33: =TAKVİM!$U$86 -> 7 | V33: =TAKVİM!$V$86 -> 14 | W33: =TAKVİM!$W$86 -> 21 | X33: =TAKVİM!$X$86 -> 28 | Y33: =TAKVİM!$Y$86 | Z33: =TAKVİM!$Z$86 -> 4 | AA33: =TAKVİM!$AA$86 -> 11 | AB33: =TAKVİM!$AB$86 -> 18 | AC33: =TAKVİM!$AC$86 -> 25 | AD33: =TAKVİM!$AD$86 | AE33: =TAKVİM!$AE$86
A34: =TAKVİM!$A$87 -> Cumartesi | B34: =TAKVİM!$B$87 -> 6 | C34: =TAKVİM!$C$87 -> 13 | D34: =TAKVİM!$D$87 -> 20 | E34: =TAKVİM!$E$87 -> 27 | F34: =TAKVİM!$F$87 | G34: =TAKVİM!$G$87 | H34: =TAKVİM!$H$87 -> 6 | I34: =TAKVİM!$I$87 -> 13 | J34: =TAKVİM!$J$87 -> 20 | K34: =TAKVİM!$K$87 -> 27 | L34: =TAKVİM!$L$87 | M34: =TAKVİM!$M$87 | N34: =TAKVİM!$N$87 -> 3 | O34: =TAKVİM!$O$87 -> 10 | P34: =TAKVİM!$P$87 -> 17 | Q34: =TAKVİM!$Q$87 -> 24 | R34: =TAKVİM!$R$87 | S34: =TAKVİM!$S$87 | T34: =TAKVİM!$T$87 -> 1 | U34: =TAKVİM!$U$87 -> 8 | V34: =TAKVİM!$V$87 -> 15 | W34: =TAKVİM!$W$87 -> 22 | X34: =TAKVİM!$X$87 -> 29 | Y34: =TAKVİM!$Y$87 | Z34: =TAKVİM!$Z$87 -> 5 | AA34: =TAKVİM!$AA$87 -> 12 | AB34: =TAKVİM!$AB$87 -> 19 | AC34: =TAKVİM!$AC$87 -> 26 | AD34: =TAKVİM!$AD$87 | AE34: =TAKVİM!$AE$87
A35: =TAKVİM!$A$88 -> Pazar | B35: =TAKVİM!$B$88 -> 7 | C35: =TAKVİM!$C$88 -> 14 | D35: =TAKVİM!$D$88 -> 21 | E35: =TAKVİM!$E$88 -> 28 | F35: =TAKVİM!$F$88 | G35: =TAKVİM!$G$88 | H35: =TAKVİM!$H$88 -> 7 | I35: =TAKVİM!$I$88 -> 14 | J35: =TAKVİM!$J$88 -> 21 | K35: =TAKVİM!$K$88 -> 28 | L35: =TAKVİM!$L$88 | M35: =TAKVİM!$M$88 | N35: =TAKVİM!$N$88 -> 4 | O35: =TAKVİM!$O$88 -> 11 | P35: =TAKVİM!$P$88 -> 18 | Q35: =TAKVİM!$Q$88 -> 25 | R35: =TAKVİM!$R$88 | S35: =TAKVİM!$S$88 | T35: =TAKVİM!$T$88 -> 2 | U35: =TAKVİM!$U$88 -> 9 | V35: =TAKVİM!$V$88 -> 16 | W35: =TAKVİM!$W$88 -> 23 | X35: =TAKVİM!$X$88 -> 30 | Y35: =TAKVİM!$Y$88 | Z35: =TAKVİM!$Z$88 -> 6 | AA35: =TAKVİM!$AA$88 -> 13 | AB35: =TAKVİM!$AB$88 -> 20 | AC35: =TAKVİM!$AC$88 -> 27 | AD35: =TAKVİM!$AD$88 | AE35: =TAKVİM!$AE$88
A37: TARİH | D37: KAZANIMLAR | L37: KONULAR | R37: ÖĞRENME-ÖĞRETME YÖNTEM VE TEKNİKLERİ | W37: KULLANILAN EĞİTİM TEKNOLOJİLERİ, ARAÇ VE GEREÇLER | AD37: DEĞERLENDİRME
A38: =TAKVİM!$B$29 -> 14-18 Eylül | D38: 1. Teknik resim kurallarına (TS EN ISO standartlarına) uygun olarak eğik ve dik standart yazı yazar. • Teknik resmin endüstrideki önemi üzerinde durulur. • Teknik resim araç gereçleri ve çizim kâğıtları üzerinde durulur. | L38: GEOMETRİK ÇİZİMLER 1. Eğik ve Dik Standart Yazı | R38: Gösteri, Soru-Cevap, Bireyselleştirilmiş Öğretim, Temrin Çalışmaları | W38: Teknik Resim Atölyesi, çizim masası, gönye, T cetveli, daire şablonu, akıllı tahta
A39: =TAKVİM!$B$30 -> 21-25 Eylül | D39: 1. Teknik resim kurallarına (TS EN ISO standartlarına) uygun olarak eğik ve dik standart yazı yazar. • Standart yazı ve norm yazı örnekleri verilir. • Norm yazı temrinleri verilir. | L39: 1. Eğik ve Dik Standart Yazı | R39: Gösteri, Soru-Cevap, Bireyselleştirilmiş Öğretim, Temrin Çalışmaları | W39: Teknik Resim Atölyesi, çizim masası, gönye, T cetveli, daire şablonu, akıllı tahta
A40: =TAKVİM!$B$31 -> 28 Eylül - 02 Ekim | D40: 1. Teknik resim kurallarına (TS EN ISO standartlarına) uygun olarak eğik ve dik standart yazı yazar. • Standart yazı ve norm yazı örnekleri verilir. • Norm yazı temrinleri verilir. | L40: 1. Eğik ve Dik Standart Yazı | R40: Gösteri, Soru-Cevap, Bireyselleştirilmiş Öğretim, Temrin Çalışmaları | W40: Teknik Resim Atölyesi, çizim masası, gönye, T cetveli, daire şablonu, akıllı tahta
A41: =TAKVİM!$B$32 -> 05-09 Ekim | D41: 2. Teknik resim kurallarına uygun olarak serbest elle ve çizim takımlarıyla çizgi çalışmaları yapar. • Çizgi çeşitleri ve çizgi kalınlıkları üzerinde durulur. • Çizgi çeşitlerinin kullanım alanları ile ilgili örnekler verilir. • Çizgi çalışması temrinleri verilir. | L41: 2. Çizgi Çalışmaları | R41: Gösteri, Soru-Cevap, Bireyselleştirilmiş Öğretim, Temrin Çalışmaları | W41: Teknik Resim Atölyesi, çizim masası, gönye, T cetveli, daire şablonu, akıllı tahta
A42: =TAKVİM!$B$33 -> 12-16 Ekim | D42: 2. Teknik resim kurallarına uygun olarak serbest elle ve çizim takımlarıyla çizgi çalışmaları yapar. • Çizgi çeşitleri ve çizgi kalınlıkları üzerinde durulur. • Çizgi çeşitlerinin kullanım alanları ile ilgili örnekler verilir. • Çizgi çalışması temrinleri verilir. | L42: 2. Çizgi Çalışmaları | R42: Gösteri, Soru-Cevap, Bireyselleştirilmiş Öğretim, Temrin Çalışmaları | W42: Teknik Resim Atölyesi, çizim masası, gönye, T cetveli, daire şablonu, akıllı tahta
A43: =TAKVİM!$B$34 -> 19-23 Ekim | D43: 3. Teknik resim kurallarına uygun olarak geometrik şekiller çizer. • Teknik resimde açı, paralellik ve diklik kavramları üzerinde durulur. • Çember ve teğet doğrular üzerinde durulur. • Teğet çizim örnekleri verilir. | L43: 3. Geometrik Şekiller | R43: Gösteri, Soru-Cevap, Bireyselleştirilmiş Öğretim, Temrin Çalışmaları | W43: Teknik Resim Atölyesi, çizim masası, gönye, T cetveli, daire şablonu, akıllı tahta
A44: =TAKVİM!$B$35 -> 26-30 Ekim | D44: 3. Teknik resim kurallarına uygun olarak geometrik şekiller çizer. • Çokgen çizim yöntemleri üzerinde durulur. • Açılı çizimler, çember ve teğet çizimleri, çokgen çizim temrinleri verilir. 29 EKİM Cumhuriyet Bayramı | L44: 3. Geometrik Şekiller | R44: Gösteri, Soru-Cevap, Bireyselleştirilmiş Öğretim, Temrin Çalışmaları | W44: Teknik Resim Atölyesi, çizim masası, gönye, T cetveli, daire şablonu, akıllı tahta
A45: =TAKVİM!$B$36 -> 02-06 Kasım | D45: 3. Teknik resim kurallarına uygun olarak geometrik şekiller çizer. • Çokgen çizim örnekleri verilir. • Açılı çizimler, çember ve teğet çizimleri, çokgen çizim temrinleri verilir. | L45: 3. Geometrik Şekiller | R45: Gösteri, Soru-Cevap, Bireyselleştirilmiş Öğretim, Temrin Çalışmaları | W45: Teknik Resim Atölyesi, çizim masası, gönye, T cetveli, daire şablonu, akıllı tahta
...

Sheet ÖLÇME VE KONTROL AMP 10-A
H1: YILLIK DERS PLANI
A3: EĞİTİM-ÖĞRETİM YILI | G3: =TAKVİM!$B$4 -> 2026-2027 Eğitim-Öğretim Yılı | P3: OKUL | U3: =TAKVİM!$B$3 -> Soma Mesleki ve Teknik Anadolu Lisesi
A4: DERS | G4: : ÖLÇME VE KONTROL | P4: ALAN/DAL | U4: : Makine ve Tasarım Teknolojisi Alanı / Makine Bakım Onarım
A5: DERS SAATİ | G5: : 2 SAAT | P5: SINIF | U5: : AMP 10-A
A7: 1.DÖNEM SINAV TARİHLERİ | P7: 2.DÖNEM SINAV TARİHLERİ
A8: 1.Dönem 1.Sınav Tarihi | G8: =TAKVİM!$B$7 -> 13.11.2026 | P8: 2.Dönem 1.Sınav Tarihi | U8: =TAKVİM!$B$9 -> 19.03.2027
A9: 1.Dönem 2.Sınav Tarihi | G9: =TAKVİM!$B$8 -> 08.01.2027 | P9: 2.Dönem 2.Sınav Tarihi | U9: =TAKVİM!$B$10 -> 14.05.2027
A11: 1.DÖNEM ÖNEMLİ GÜN VE HAFTALAR | P11: 2.DÖNEM ÖNEMLİ GÜN VE HAFTALAR
A12: 1.Yarıyıl Başlangıcı | G12: =TAKVİM!$B$13 -> 2026-09-14 00:00:00 | P12: 2.Yarıyıl Başlangıcı | U12: =TAKVİM!$B$14 -> 2027-02-08 00:00:00
A13: Cumhuriyet Bayramı | G13: =TAKVİM!$B$15 -> 29.10.2026 | P13: 2. Dönem Ara Tatil | U13: =TAKVİM!$B$19 -> 08-12 Mart
A14: Atatürk'ü Anma Günü ve Atatürk Haftası | G14: =TAKVİM!$B$17 -> 10.11.2026 | P14: 23 Nisan Ulusal Egemenlik ve Çocuk Bayramı | U14: =TAKVİM!$B$18 -> 23.04.2027
A15: 1. Dönem Ara Tatil | G15: =TAKVİM!$B$16 -> 16-20 Kasım | P15: 19 Mayıs Atatürk'ü Anma Gençlik ve Spor Bayramı | U15: =TAKVİM!$B$20 -> 19.05.2027
A16: Yılbaşı Tatili | G16: =TAKVİM!$B$21 -> 01.01.2027 | P16: Ramazan Bayramı | U16: =TAKVİM!$B$22 -> 20.03.2027
A17: Yarıyıl Tatili | G17: =TAKVİM!$B$23 -> 25 OCAK - 05 ŞUBAT 2027 | P17: Eğitim-Öğretim Yılının Sonu | U17: =TAKVİM!$B$24 -> 25.06.2027
A19: 2026-2027 EĞİTİM-ÖĞRETİM YILI İŞGÜNÜ TAKVİMİ
A20: =TAKVİM!$A$73 -> Günler | B20: =TAKVİM!$B$73 -> Eylül 2026 | H20: =TAKVİM!$H$73 -> Ekim 2026 | N20: =TAKVİM!$N$73 -> Kasım 2026 | T20: =TAKVİM!$T$73 -> Aralık 2026 | Z20: =TAKVİM!$Z$73 -> Ocak 2027
A21: =TAKVİM!$A$74 -> Pazartesi | B21: =TAKVİM!$B$74 | C21: =TAKVİM!$C$74 -> 7 | D21: =TAKVİM!$D$74 -> 14 | E21: =TAKVİM!$E$74 -> 21 | F21: =TAKVİM!$F$74 -> 28 | G21: =TAKVİM!$G$74 | H21: =TAKVİM!$H$74 | I21: =TAKVİM!$I$74 -> 5 | J21: =TAKVİM!$J$74 -> 12 | K21: =TAKVİM!$K$74 -> 19 | L21: =TAKVİM!$L$74 -> 26 | M21: =TAKVİM!$M$74 | N21: =TAKVİM!$N$74 | O21: =TAKVİM!$O$74 -> 2 | P21: =TAKVİM!$P$74 -> 9 | Q21: =TAKVİM!$Q$74 -> 16 | R21: =TAKVİM!$R$74 -> 23 | S21: =TAKVİM!$S$74 -> 30 | T21: =TAKVİM!$T$74 | U21: =TAKVİM!$U$74 -> 7 | V21: =TAKVİM!$V$74 -> 14 | W21: =TAKVİM!$W$74 -> 21 | X21: =TAKVİM!$X$74 -> 28 | Y21: =TAKVİM!$Y$74 | Z21: =TAKVİM!$Z$74 | AA21: =TAKVİM!$AA$74 -> 4 | AB21: =TAKVİM!$AB$74 -> 11 | AC21: =TAKVİM!$AC$74 -> 18 | AD21: =TAKVİM!$AD$74 -> 25 | AE21: =TAKVİM!$AE$74
A22: =TAKVİM!$A$75 -> Salı | B22: =TAKVİM!$B$75 -> 1 | C22: =TAKVİM!$C$75 -> 8 | D22: =TAKVİM!$D$75 -> 15 | E22: =TAKVİM!$E$75 -> 22 | F22: =TAKVİM!$F$75 -> 29 | G22: =TAKVİM!$G$75 | H22: =TAKVİM!$H$75 | I22: =TAKVİM!$I$75 -> 6 | J22: =TAKVİM!$J$75 -> 13 | K22: =TAKVİM!$K$75 -> 20 | L22: =TAKVİM!$L$75 -> 27 | M22: =TAKVİM!$M$75 | N22: =TAKVİM!$N$75 | O22: =TAKVİM!$O$75 -> 3 | P22: =TAKVİM!$P$75 -> 10 | Q22: =TAKVİM!$Q$75 -> 17 | R22: =TAKVİM!$R$75 -> 24 | S22: =TAKVİM!$S$75 | T22: =TAKVİM!$T$75 -> 1 | U22: =TAKVİM!$U$75 -> 8 | V22: =TAKVİM!$V$75 -> 15 | W22: =TAKVİM!$W$75 -> 22 | X22: =TAKVİM!$X$75 -> 29 | Y22: =TAKVİM!$Y$75 | Z22: =TAKVİM!$Z$75 | AA22: =TAKVİM!$AA$75 -> 5 | AB22: =TAKVİM!$AB$75 -> 12 | AC22: =TAKVİM!$AC$75 -> 19 | AD22: =TAKVİM!$AD$75 -> 26 | AE22: =TAKVİM!$AE$75
A23: =TAKVİM!$A$76 -> Çarşamba | B23: =TAKVİM!$B$76 -> 2 | C23: =TAKVİM!$C$76 -> 9 | D23: =TAKVİM!$D$76 -> 16 | E23: =TAKVİM!$E$76 -> 23 | F23: =TAKVİM!$F$76 -> 30 | G23: =TAKVİM!$G$76 | H23: =TAKVİM!$H$76 | I23: =TAKVİM!$I$76 -> 7 | J23: =TAKVİM!$J$76 -> 14 | K23: =TAKVİM!$K$76 -> 21 | L23: =TAKVİM!$L$76 -> 28 | M23: =TAKVİM!$M$76 | N23: =TAKVİM!$N$76 | O23: =TAKVİM!$O$76 -> 4 | P23: =TAKVİM!$P$76 -> 11 | Q23: =TAKVİM!$Q$76 -> 18 | R23: =TAKVİM!$R$76 -> 25 | S23: =TAKVİM!$S$76 | T23: =TAKVİM!$T$76 -> 2 | U23: =TAKVİM!$U$76 -> 9 | V23: =TAKVİM!$V$76 -> 16 | W23: =TAKVİM!$W$76 -> 23 | X23: =TAKVİM!$X$76 -> 30 | Y23: =TAKVİM!$Y$76 | Z23: =TAKVİM!$Z$76 | AA23: =TAKVİM!$AA$76 -> 6 | AB23: =TAKVİM!$AB$76 -> 13 | AC23: =TAKVİM!$AC$76 -> 20 | AD23: =TAKVİM!$AD$76 -> 27 | AE23: =TAKVİM!$AE$76
A24: =TAKVİM!$A$77 -> Perşembe | B24: =TAKVİM!$B$77 -> 3 | C24: =TAKVİM!$C$77 -> 10 | D24: =TAKVİM!$D$77 -> 17 | E24: =TAKVİM!$E$77 -> 24 | F24: =TAKVİM!$F$77 | G24: =TAKVİM!$G$77 | H24: =TAKVİM!$H$77 -> 1 | I24: =TAKVİM!$I$77 -> 8 | J24: =TAKVİM!$J$77 -> 15 | K24: =TAKVİM!$K$77 -> 22 | L24: =TAKVİM!$L$77 -> 29 | M24: =TAKVİM!$M$77 | N24: =TAKVİM!$N$77 | O24: =TAKVİM!$O$77 -> 5 | P24: =TAKVİM!$P$77 -> 12 | Q24: =TAKVİM!$Q$77 -> 19 | R24: =TAKVİM!$R$77 -> 26 | S24: =TAKVİM!$S$77 | T24: =TAKVİM!$T$77 -> 3 | U24: =TAKVİM!$U$77 -> 10 | V24: =TAKVİM!$V$77 -> 17 | W24: =TAKVİM!$W$77 -> 24 | X24: =TAKVİM!$X$77 -> 31 | Y24: =TAKVİM!$Y$77 | Z24: =TAKVİM!$Z$77 | AA24: =TAKVİM!$AA$77 -> 7 | AB24: =TAKVİM!$AB$77 -> 14 | AC24: =TAKVİM!$AC$77 -> 21 | AD24: =TAKVİM!$AD$77 -> 28 | AE24: =TAKVİM!$AE$77
